[2024-07-09T20:48:44.638+0000] {local_task_job_runner.py:120} INFO - ::group::Pre task execution logs
[2024-07-09T20:48:44.688+0000] {taskinstance.py:2076} INFO - Dependencies all met for dep_context=non-requeueable deps ti=<TaskInstance: test_transformation.create_cluster manual__2024-07-09T20:47:17.512811+00:00 [queued]>
[2024-07-09T20:48:44.703+0000] {taskinstance.py:2076} INFO - Dependencies all met for dep_context=requeueable deps ti=<TaskInstance: test_transformation.create_cluster manual__2024-07-09T20:47:17.512811+00:00 [queued]>
[2024-07-09T20:48:44.704+0000] {taskinstance.py:2306} INFO - Starting attempt 2 of 2
[2024-07-09T20:48:44.740+0000] {taskinstance.py:2330} INFO - Executing <Task(DataprocCreateClusterOperator): create_cluster> on 2024-07-09 20:47:17.512811+00:00
[2024-07-09T20:48:44.752+0000] {standard_task_runner.py:63} INFO - Started process 155 to run task
[2024-07-09T20:48:44.767+0000] {standard_task_runner.py:90} INFO - Running: ['***', 'tasks', 'run', 'test_transformation', 'create_cluster', 'manual__2024-07-09T20:47:17.512811+00:00', '--job-id', '84', '--raw', '--subdir', 'DAGS_FOLDER/transformation_dag.py', '--cfg-path', '/tmp/tmppoizze5w']
[2024-07-09T20:48:44.774+0000] {standard_task_runner.py:91} INFO - Job 84: Subtask create_cluster
[2024-07-09T20:48:44.878+0000] {task_command.py:426} INFO - Running <TaskInstance: test_transformation.create_cluster manual__2024-07-09T20:47:17.512811+00:00 [running]> on host ea9610d9d6e7
[2024-07-09T20:48:45.057+0000] {taskinstance.py:2648} INFO - Exporting env vars: AIRFLOW_CTX_DAG_OWNER='***' AIRFLOW_CTX_DAG_ID='test_transformation' AIRFLOW_CTX_TASK_ID='create_cluster' AIRFLOW_CTX_EXECUTION_DATE='2024-07-09T20:47:17.512811+00:00' AIRFLOW_CTX_TRY_NUMBER='2' AIRFLOW_CTX_DAG_RUN_ID='manual__2024-07-09T20:47:17.512811+00:00'
[2024-07-09T20:48:45.061+0000] {taskinstance.py:430} INFO - ::endgroup::
[2024-07-09T20:48:45.062+0000] {dataproc.py:780} INFO - Creating cluster: de-zoomcamp-cluster
[2024-07-09T20:48:45.065+0000] {crypto.py:82} WARNING - empty cryptography key - values will not be stored encrypted.
[2024-07-09T20:48:45.066+0000] {connection.py:274} WARNING - Connection schemes (type: google_cloud_platform) shall not contain '_' according to RFC3986.
[2024-07-09T20:48:45.068+0000] {base.py:84} INFO - Using connection ID 'google_cloud_default' for task execution.
[2024-07-09T20:48:46.242+0000] {taskinstance.py:441} INFO - ::group::Post task execution logs
[2024-07-09T20:48:46.243+0000] {taskinstance.py:2905} ERROR - Task failed with exception
Traceback (most recent call last):
  File "/home/airflow/.local/lib/python3.11/site-packages/airflow/models/taskinstance.py", line 465, in _execute_task
    result = _execute_callable(context=context, **execute_callable_kwargs)
             ^^^^^^^^^^^^^^^^^^^^^^^^^^^^^^^^^^^^^^^^^^^^^^^^^^^^^^^^^^^^^
  File "/home/airflow/.local/lib/python3.11/site-packages/airflow/models/taskinstance.py", line 432, in _execute_callable
    return execute_callable(context=context, **execute_callable_kwargs)
           ^^^^^^^^^^^^^^^^^^^^^^^^^^^^^^^^^^^^^^^^^^^^^^^^^^^^^^^^^^^^
  File "/home/airflow/.local/lib/python3.11/site-packages/airflow/models/baseoperator.py", line 401, in wrapper
    return func(self, *args, **kwargs)
           ^^^^^^^^^^^^^^^^^^^^^^^^^^^
  File "/home/airflow/.local/lib/python3.11/site-packages/airflow/providers/google/cloud/operators/dataproc.py", line 796, in execute
    operation = self._create_cluster(hook)
                ^^^^^^^^^^^^^^^^^^^^^^^^^^
  File "/home/airflow/.local/lib/python3.11/site-packages/airflow/providers/google/cloud/operators/dataproc.py", line 696, in _create_cluster
    return hook.create_cluster(
           ^^^^^^^^^^^^^^^^^^^^
  File "/home/airflow/.local/lib/python3.11/site-packages/airflow/providers/google/common/hooks/base_google.py", line 528, in inner_wrapper
    return func(self, *args, **kwargs)
           ^^^^^^^^^^^^^^^^^^^^^^^^^^^
  File "/home/airflow/.local/lib/python3.11/site-packages/airflow/providers/google/cloud/hooks/dataproc.py", line 328, in create_cluster
    result = client.create_cluster(
             ^^^^^^^^^^^^^^^^^^^^^^
  File "/home/airflow/.local/lib/python3.11/site-packages/google/cloud/dataproc_v1/services/cluster_controller/client.py", line 857, in create_cluster
    response = rpc(
               ^^^^
  File "/home/airflow/.local/lib/python3.11/site-packages/google/api_core/gapic_v1/method.py", line 131, in __call__
    return wrapped_func(*args, **kwargs)
           ^^^^^^^^^^^^^^^^^^^^^^^^^^^^^
  File "/home/airflow/.local/lib/python3.11/site-packages/google/api_core/retry/retry_unary.py", line 293, in retry_wrapped_func
    return retry_target(
           ^^^^^^^^^^^^^
  File "/home/airflow/.local/lib/python3.11/site-packages/google/api_core/retry/retry_unary.py", line 153, in retry_target
    _retry_error_helper(
  File "/home/airflow/.local/lib/python3.11/site-packages/google/api_core/retry/retry_base.py", line 212, in _retry_error_helper
    raise final_exc from source_exc
  File "/home/airflow/.local/lib/python3.11/site-packages/google/api_core/retry/retry_unary.py", line 144, in retry_target
    result = target()
             ^^^^^^^^
  File "/home/airflow/.local/lib/python3.11/site-packages/google/api_core/timeout.py", line 120, in func_with_timeout
    return func(*args, **kwargs)
           ^^^^^^^^^^^^^^^^^^^^^
  File "/home/airflow/.local/lib/python3.11/site-packages/google/api_core/grpc_helpers.py", line 78, in error_remapped_callable
    raise exceptions.from_grpc_error(exc) from exc
google.api_core.exceptions.InvalidArgument: 400 User not authorized to act as service account '735867942533-compute@developer.gserviceaccount.com'. To act as a service account, user must have one of [Owner, Editor, Service Account Actor] roles. See https://cloud.google.com/iam/docs/understanding-service-accounts for additional details.
[2024-07-09T20:48:46.261+0000] {taskinstance.py:1206} INFO - Marking task as FAILED. dag_id=test_transformation, task_id=create_cluster, run_id=manual__2024-07-09T20:47:17.512811+00:00, execution_date=20240709T204717, start_date=20240709T204844, end_date=20240709T204846
[2024-07-09T20:48:46.282+0000] {standard_task_runner.py:110} ERROR - Failed to execute job 84 for task create_cluster (400 User not authorized to act as service account '735867942533-compute@developer.gserviceaccount.com'. To act as a service account, user must have one of [Owner, Editor, Service Account Actor] roles. See https://cloud.google.com/iam/docs/understanding-service-accounts for additional details.; 155)
[2024-07-09T20:48:46.339+0000] {local_task_job_runner.py:240} INFO - Task exited with return code 1
[2024-07-09T20:48:46.389+0000] {taskinstance.py:3503} INFO - 0 downstream tasks scheduled from follow-on schedule check
[2024-07-09T20:48:46.396+0000] {local_task_job_runner.py:222} INFO - ::endgroup::
