[2024-07-18T20:49:55.199+0000] {local_task_job_runner.py:120} INFO - ::group::Pre task execution logs
[2024-07-18T20:49:55.231+0000] {taskinstance.py:2076} INFO - Dependencies all met for dep_context=non-requeueable deps ti=<TaskInstance: rec_data_dag.upload_zip_task_fire scheduled__2024-01-01T08:00:00+00:00 [queued]>
[2024-07-18T20:49:55.241+0000] {taskinstance.py:2076} INFO - Dependencies all met for dep_context=requeueable deps ti=<TaskInstance: rec_data_dag.upload_zip_task_fire scheduled__2024-01-01T08:00:00+00:00 [queued]>
[2024-07-18T20:49:55.242+0000] {taskinstance.py:2306} INFO - Starting attempt 1 of 2
[2024-07-18T20:49:55.259+0000] {taskinstance.py:2330} INFO - Executing <Task(PythonOperator): upload_zip_task_fire> on 2024-01-01 08:00:00+00:00
[2024-07-18T20:49:55.269+0000] {standard_task_runner.py:63} INFO - Started process 267 to run task
[2024-07-18T20:49:55.274+0000] {standard_task_runner.py:90} INFO - Running: ['***', 'tasks', 'run', 'rec_data_dag', 'upload_zip_task_fire', 'scheduled__2024-01-01T08:00:00+00:00', '--job-id', '724', '--raw', '--subdir', 'DAGS_FOLDER/rec_data_dag.py', '--cfg-path', '/tmp/tmpuwrcyrmd']
[2024-07-18T20:49:55.276+0000] {standard_task_runner.py:91} INFO - Job 724: Subtask upload_zip_task_fire
[2024-07-18T20:49:55.352+0000] {task_command.py:426} INFO - Running <TaskInstance: rec_data_dag.upload_zip_task_fire scheduled__2024-01-01T08:00:00+00:00 [running]> on host e1216aff0b18
[2024-07-18T20:49:55.514+0000] {taskinstance.py:2648} INFO - Exporting env vars: AIRFLOW_CTX_DAG_OWNER='***' AIRFLOW_CTX_DAG_ID='rec_data_dag' AIRFLOW_CTX_TASK_ID='upload_zip_task_fire' AIRFLOW_CTX_EXECUTION_DATE='2024-01-01T08:00:00+00:00' AIRFLOW_CTX_TRY_NUMBER='1' AIRFLOW_CTX_DAG_RUN_ID='scheduled__2024-01-01T08:00:00+00:00'
[2024-07-18T20:49:55.517+0000] {taskinstance.py:430} INFO - ::endgroup::
[2024-07-18T20:49:55.667+0000] {logging_mixin.py:188} INFO - Uploading to storage bucket as <Blob: de-zoomcamp-cchow-bucket, recreation_lines.zip, None> from /opt/***/recreation_lines.zip...
[2024-07-18T20:49:55.674+0000] {logging_mixin.py:188} INFO - Error uploading file /opt/***/recreation_lines.zip to <Blob: de-zoomcamp-cchow-bucket, recreation_lines.zip, None>: [Errno 2] No such file or directory: '/opt/***/recreation_lines.zip'
[2024-07-18T20:49:55.674+0000] {taskinstance.py:441} INFO - ::group::Post task execution logs
[2024-07-18T20:49:55.693+0000] {taskinstance.py:2905} ERROR - Task failed with exception
Traceback (most recent call last):
  File "/opt/airflow/dags/rec_data_dag.py", line 51, in upload_to_gcs
    blob.upload_from_filename(source_path)
  File "/home/airflow/.local/lib/python3.11/site-packages/google/cloud/storage/blob.py", line 2947, in upload_from_filename
    self._handle_filename_and_upload(
  File "/home/airflow/.local/lib/python3.11/site-packages/google/cloud/storage/blob.py", line 2824, in _handle_filename_and_upload
    with open(filename, "rb") as file_obj:
         ^^^^^^^^^^^^^^^^^^^^
FileNotFoundError: [Errno 2] No such file or directory: '/opt/airflow/recreation_lines.zip'

During handling of the above exception, another exception occurred:

Traceback (most recent call last):
  File "/home/airflow/.local/lib/python3.11/site-packages/airflow/models/taskinstance.py", line 465, in _execute_task
    result = _execute_callable(context=context, **execute_callable_kwargs)
             ^^^^^^^^^^^^^^^^^^^^^^^^^^^^^^^^^^^^^^^^^^^^^^^^^^^^^^^^^^^^^
  File "/home/airflow/.local/lib/python3.11/site-packages/airflow/models/taskinstance.py", line 432, in _execute_callable
    return execute_callable(context=context, **execute_callable_kwargs)
           ^^^^^^^^^^^^^^^^^^^^^^^^^^^^^^^^^^^^^^^^^^^^^^^^^^^^^^^^^^^^
  File "/home/airflow/.local/lib/python3.11/site-packages/airflow/models/baseoperator.py", line 401, in wrapper
    return func(self, *args, **kwargs)
           ^^^^^^^^^^^^^^^^^^^^^^^^^^^
  File "/home/airflow/.local/lib/python3.11/site-packages/airflow/operators/python.py", line 235, in execute
    return_value = self.execute_callable()
                   ^^^^^^^^^^^^^^^^^^^^^^^
  File "/home/airflow/.local/lib/python3.11/site-packages/airflow/operators/python.py", line 252, in execute_callable
    return self.python_callable(*self.op_args, **self.op_kwargs)
           ^^^^^^^^^^^^^^^^^^^^^^^^^^^^^^^^^^^^^^^^^^^^^^^^^^^^^
  File "/opt/airflow/dags/rec_data_dag.py", line 55, in upload_to_gcs
    raise AirflowException("Task failed due to an exception")
airflow.exceptions.AirflowException: Task failed due to an exception
[2024-07-18T20:49:55.707+0000] {taskinstance.py:1206} INFO - Marking task as UP_FOR_RETRY. dag_id=rec_data_dag, task_id=upload_zip_task_fire, run_id=scheduled__2024-01-01T08:00:00+00:00, execution_date=20240101T080000, start_date=20240718T204955, end_date=20240718T204955
[2024-07-18T20:49:55.741+0000] {standard_task_runner.py:110} ERROR - Failed to execute job 724 for task upload_zip_task_fire (Task failed due to an exception; 267)
[2024-07-18T20:49:55.768+0000] {local_task_job_runner.py:240} INFO - Task exited with return code 1
[2024-07-18T20:49:55.856+0000] {taskinstance.py:3503} INFO - 0 downstream tasks scheduled from follow-on schedule check
[2024-07-18T20:49:55.859+0000] {local_task_job_runner.py:222} INFO - ::endgroup::
