[2024-07-17T22:44:38.526+0000] {local_task_job_runner.py:120} INFO - ::group::Pre task execution logs
[2024-07-17T22:44:38.550+0000] {taskinstance.py:2076} INFO - Dependencies all met for dep_context=non-requeueable deps ti=<TaskInstance: fire_data_dag.load_fire_bq_task manual__2024-07-17T22:43:59.987502+00:00 [queued]>
[2024-07-17T22:44:38.564+0000] {taskinstance.py:2076} INFO - Dependencies all met for dep_context=requeueable deps ti=<TaskInstance: fire_data_dag.load_fire_bq_task manual__2024-07-17T22:43:59.987502+00:00 [queued]>
[2024-07-17T22:44:38.565+0000] {taskinstance.py:2306} INFO - Starting attempt 1 of 2
[2024-07-17T22:44:38.583+0000] {taskinstance.py:2330} INFO - Executing <Task(PythonOperator): load_fire_bq_task> on 2024-07-17 22:43:59.987502+00:00
[2024-07-17T22:44:38.593+0000] {standard_task_runner.py:63} INFO - Started process 182 to run task
[2024-07-17T22:44:38.600+0000] {standard_task_runner.py:90} INFO - Running: ['***', 'tasks', 'run', 'fire_data_dag', 'load_fire_bq_task', 'manual__2024-07-17T22:43:59.987502+00:00', '--job-id', '605', '--raw', '--subdir', 'DAGS_FOLDER/fire_data_dag.py', '--cfg-path', '/tmp/tmpq22t1mep']
[2024-07-17T22:44:38.602+0000] {standard_task_runner.py:91} INFO - Job 605: Subtask load_fire_bq_task
[2024-07-17T22:44:38.672+0000] {task_command.py:426} INFO - Running <TaskInstance: fire_data_dag.load_fire_bq_task manual__2024-07-17T22:43:59.987502+00:00 [running]> on host b83e2bee00d2
[2024-07-17T22:44:38.791+0000] {taskinstance.py:2648} INFO - Exporting env vars: AIRFLOW_CTX_DAG_OWNER='***' AIRFLOW_CTX_DAG_ID='fire_data_dag' AIRFLOW_CTX_TASK_ID='load_fire_bq_task' AIRFLOW_CTX_EXECUTION_DATE='2024-07-17T22:43:59.987502+00:00' AIRFLOW_CTX_TRY_NUMBER='1' AIRFLOW_CTX_DAG_RUN_ID='manual__2024-07-17T22:43:59.987502+00:00'
[2024-07-17T22:44:38.793+0000] {taskinstance.py:430} INFO - ::endgroup::
[2024-07-17T22:44:40.276+0000] {taskinstance.py:441} INFO - ::group::Post task execution logs
[2024-07-17T22:44:40.277+0000] {taskinstance.py:2905} ERROR - Task failed with exception
Traceback (most recent call last):
  File "/home/airflow/.local/lib/python3.11/site-packages/airflow/models/taskinstance.py", line 465, in _execute_task
    result = _execute_callable(context=context, **execute_callable_kwargs)
             ^^^^^^^^^^^^^^^^^^^^^^^^^^^^^^^^^^^^^^^^^^^^^^^^^^^^^^^^^^^^^
  File "/home/airflow/.local/lib/python3.11/site-packages/airflow/models/taskinstance.py", line 432, in _execute_callable
    return execute_callable(context=context, **execute_callable_kwargs)
           ^^^^^^^^^^^^^^^^^^^^^^^^^^^^^^^^^^^^^^^^^^^^^^^^^^^^^^^^^^^^
  File "/home/airflow/.local/lib/python3.11/site-packages/airflow/models/baseoperator.py", line 401, in wrapper
    return func(self, *args, **kwargs)
           ^^^^^^^^^^^^^^^^^^^^^^^^^^^
  File "/home/airflow/.local/lib/python3.11/site-packages/airflow/operators/python.py", line 235, in execute
    return_value = self.execute_callable()
                   ^^^^^^^^^^^^^^^^^^^^^^^
  File "/home/airflow/.local/lib/python3.11/site-packages/airflow/operators/python.py", line 252, in execute_callable
    return self.python_callable(*self.op_args, **self.op_kwargs)
           ^^^^^^^^^^^^^^^^^^^^^^^^^^^^^^^^^^^^^^^^^^^^^^^^^^^^^
  File "/opt/airflow/dags/bq_load.py", line 47, in load_bq
    load_job.result()
  File "/home/airflow/.local/lib/python3.11/site-packages/google/cloud/bigquery/job/base.py", line 971, in result
    return super(_AsyncJob, self).result(timeout=timeout, **kwargs)
           ^^^^^^^^^^^^^^^^^^^^^^^^^^^^^^^^^^^^^^^^^^^^^^^^^^^^^^^^
  File "/home/airflow/.local/lib/python3.11/site-packages/google/api_core/future/polling.py", line 261, in result
    raise self._exception
google.api_core.exceptions.BadRequest: 400 Error while reading data, error message: JSON table encountered too many errors, giving up. Rows: 1; errors: 1. Please look into the errors[] collection for more details. File: gs://de-zoomcamp-cchow-bucket/wildfire_polygons_nl.geojsonl; reason: invalid, location: gs://de-zoomcamp-cchow-bucket/wildfire_polygons_nl.geojsonl, message: Error while reading data, error message: JSON table encountered too many errors, giving up. Rows: 1; errors: 1. Please look into the errors[] collection for more details. File: gs://de-zoomcamp-cchow-bucket/wildfire_polygons_nl.geojsonl; reason: invalid, message: Error while reading data, error message: JSON processing encountered too many errors, giving up. Rows: 1; errors: 1; max bad: 0; error percent: 0; reason: invalid, location: gs://de-zoomcamp-cchow-bucket/wildfire_polygons_nl.geojsonl, message: Error while reading data, error message: JSON parsing error in row starting at position 0: No such field: type. File: gs://de-zoomcamp-cchow-bucket/wildfire_polygons_nl.geojsonl
[2024-07-17T22:44:40.292+0000] {taskinstance.py:1206} INFO - Marking task as UP_FOR_RETRY. dag_id=fire_data_dag, task_id=load_fire_bq_task, run_id=manual__2024-07-17T22:43:59.987502+00:00, execution_date=20240717T224359, start_date=20240717T224438, end_date=20240717T224440
[2024-07-17T22:44:40.309+0000] {standard_task_runner.py:110} ERROR - Failed to execute job 605 for task load_fire_bq_task (400 Error while reading data, error message: JSON table encountered too many errors, giving up. Rows: 1; errors: 1. Please look into the errors[] collection for more details. File: gs://de-zoomcamp-cchow-bucket/wildfire_polygons_nl.geojsonl; reason: invalid, location: gs://de-zoomcamp-cchow-bucket/wildfire_polygons_nl.geojsonl, message: Error while reading data, error message: JSON table encountered too many errors, giving up. Rows: 1; errors: 1. Please look into the errors[] collection for more details. File: gs://de-zoomcamp-cchow-bucket/wildfire_polygons_nl.geojsonl; reason: invalid, message: Error while reading data, error message: JSON processing encountered too many errors, giving up. Rows: 1; errors: 1; max bad: 0; error percent: 0; reason: invalid, location: gs://de-zoomcamp-cchow-bucket/wildfire_polygons_nl.geojsonl, message: Error while reading data, error message: JSON parsing error in row starting at position 0: No such field: type. File: gs://de-zoomcamp-cchow-bucket/wildfire_polygons_nl.geojsonl; 182)
[2024-07-17T22:44:40.338+0000] {local_task_job_runner.py:240} INFO - Task exited with return code 1
[2024-07-17T22:44:40.363+0000] {taskinstance.py:3503} INFO - 0 downstream tasks scheduled from follow-on schedule check
[2024-07-17T22:44:40.365+0000] {local_task_job_runner.py:222} INFO - ::endgroup::
