[2024-06-27T23:10:17.190+0000] {processor.py:161} INFO - Started process (PID=3823) to work on /opt/airflow/dags/ingestion_dag.py
[2024-06-27T23:10:17.192+0000] {processor.py:830} INFO - Processing file /opt/airflow/dags/ingestion_dag.py for tasks to queue
[2024-06-27T23:10:17.196+0000] {logging_mixin.py:188} INFO - [2024-06-27T23:10:17.195+0000] {dagbag.py:545} INFO - Filling up the DagBag from /opt/airflow/dags/ingestion_dag.py
[2024-06-27T23:10:18.298+0000] {processor.py:842} WARNING - No viable dags retrieved from /opt/airflow/dags/ingestion_dag.py
[2024-06-27T23:10:18.317+0000] {processor.py:183} INFO - Processing /opt/airflow/dags/ingestion_dag.py took 1.139 seconds
[2024-06-27T23:10:48.998+0000] {processor.py:161} INFO - Started process (PID=3894) to work on /opt/airflow/dags/ingestion_dag.py
[2024-06-27T23:10:49.000+0000] {processor.py:830} INFO - Processing file /opt/airflow/dags/ingestion_dag.py for tasks to queue
[2024-06-27T23:10:49.003+0000] {logging_mixin.py:188} INFO - [2024-06-27T23:10:49.003+0000] {dagbag.py:545} INFO - Filling up the DagBag from /opt/airflow/dags/ingestion_dag.py
[2024-06-27T23:10:50.046+0000] {processor.py:842} WARNING - No viable dags retrieved from /opt/airflow/dags/ingestion_dag.py
[2024-06-27T23:10:50.065+0000] {processor.py:183} INFO - Processing /opt/airflow/dags/ingestion_dag.py took 1.080 seconds
[2024-06-27T23:11:20.558+0000] {processor.py:161} INFO - Started process (PID=3962) to work on /opt/airflow/dags/ingestion_dag.py
[2024-06-27T23:11:20.561+0000] {processor.py:830} INFO - Processing file /opt/airflow/dags/ingestion_dag.py for tasks to queue
[2024-06-27T23:11:20.564+0000] {logging_mixin.py:188} INFO - [2024-06-27T23:11:20.564+0000] {dagbag.py:545} INFO - Filling up the DagBag from /opt/airflow/dags/ingestion_dag.py
[2024-06-27T23:11:21.602+0000] {processor.py:842} WARNING - No viable dags retrieved from /opt/airflow/dags/ingestion_dag.py
[2024-06-27T23:11:21.621+0000] {processor.py:183} INFO - Processing /opt/airflow/dags/ingestion_dag.py took 1.081 seconds
[2024-06-27T23:11:52.459+0000] {processor.py:161} INFO - Started process (PID=4031) to work on /opt/airflow/dags/ingestion_dag.py
[2024-06-27T23:11:52.460+0000] {processor.py:830} INFO - Processing file /opt/airflow/dags/ingestion_dag.py for tasks to queue
[2024-06-27T23:11:52.465+0000] {logging_mixin.py:188} INFO - [2024-06-27T23:11:52.464+0000] {dagbag.py:545} INFO - Filling up the DagBag from /opt/airflow/dags/ingestion_dag.py
[2024-06-27T23:11:53.516+0000] {processor.py:842} WARNING - No viable dags retrieved from /opt/airflow/dags/ingestion_dag.py
[2024-06-27T23:11:53.541+0000] {processor.py:183} INFO - Processing /opt/airflow/dags/ingestion_dag.py took 1.096 seconds
[2024-06-27T23:11:58.580+0000] {processor.py:161} INFO - Started process (PID=4046) to work on /opt/airflow/dags/ingestion_dag.py
[2024-06-27T23:11:58.582+0000] {processor.py:830} INFO - Processing file /opt/airflow/dags/ingestion_dag.py for tasks to queue
[2024-06-27T23:11:58.585+0000] {logging_mixin.py:188} INFO - [2024-06-27T23:11:58.585+0000] {dagbag.py:545} INFO - Filling up the DagBag from /opt/airflow/dags/ingestion_dag.py
[2024-06-27T23:11:59.670+0000] {processor.py:840} INFO - DAG(s) 'exampleDag' retrieved from /opt/airflow/dags/ingestion_dag.py
[2024-06-27T23:11:59.812+0000] {logging_mixin.py:188} INFO - [2024-06-27T23:11:59.811+0000] {dag.py:3096} INFO - Sync 1 DAGs
[2024-06-27T23:11:59.838+0000] {logging_mixin.py:188} INFO - [2024-06-27T23:11:59.838+0000] {dag.py:3954} INFO - Setting next_dagrun for exampleDag to 2024-06-26 00:00:00+00:00, run_after=2024-06-27 00:00:00+00:00
[2024-06-27T23:11:59.868+0000] {processor.py:183} INFO - Processing /opt/airflow/dags/ingestion_dag.py took 1.302 seconds
[2024-06-27T23:12:30.439+0000] {processor.py:161} INFO - Started process (PID=4112) to work on /opt/airflow/dags/ingestion_dag.py
[2024-06-27T23:12:30.442+0000] {processor.py:830} INFO - Processing file /opt/airflow/dags/ingestion_dag.py for tasks to queue
[2024-06-27T23:12:30.446+0000] {logging_mixin.py:188} INFO - [2024-06-27T23:12:30.445+0000] {dagbag.py:545} INFO - Filling up the DagBag from /opt/airflow/dags/ingestion_dag.py
[2024-06-27T23:12:31.542+0000] {processor.py:840} INFO - DAG(s) 'exampleDag' retrieved from /opt/airflow/dags/ingestion_dag.py
[2024-06-27T23:12:31.578+0000] {logging_mixin.py:188} INFO - [2024-06-27T23:12:31.574+0000] {dag.py:3096} INFO - Sync 1 DAGs
[2024-06-27T23:12:31.620+0000] {logging_mixin.py:188} INFO - [2024-06-27T23:12:31.619+0000] {dag.py:3954} INFO - Setting next_dagrun for exampleDag to 2024-06-26 00:00:00+00:00, run_after=2024-06-27 00:00:00+00:00
[2024-06-27T23:12:31.652+0000] {processor.py:183} INFO - Processing /opt/airflow/dags/ingestion_dag.py took 1.226 seconds
[2024-06-27T23:13:02.108+0000] {processor.py:161} INFO - Started process (PID=4180) to work on /opt/airflow/dags/ingestion_dag.py
[2024-06-27T23:13:02.111+0000] {processor.py:830} INFO - Processing file /opt/airflow/dags/ingestion_dag.py for tasks to queue
[2024-06-27T23:13:02.114+0000] {logging_mixin.py:188} INFO - [2024-06-27T23:13:02.114+0000] {dagbag.py:545} INFO - Filling up the DagBag from /opt/airflow/dags/ingestion_dag.py
[2024-06-27T23:13:03.281+0000] {processor.py:840} INFO - DAG(s) 'exampleDag' retrieved from /opt/airflow/dags/ingestion_dag.py
[2024-06-27T23:13:03.297+0000] {logging_mixin.py:188} INFO - [2024-06-27T23:13:03.296+0000] {dag.py:3096} INFO - Sync 1 DAGs
[2024-06-27T23:13:03.330+0000] {logging_mixin.py:188} INFO - [2024-06-27T23:13:03.330+0000] {dag.py:3954} INFO - Setting next_dagrun for exampleDag to 2024-06-26 00:00:00+00:00, run_after=2024-06-27 00:00:00+00:00
[2024-06-27T23:13:03.355+0000] {processor.py:183} INFO - Processing /opt/airflow/dags/ingestion_dag.py took 1.259 seconds
[2024-06-27T23:13:33.363+0000] {processor.py:161} INFO - Started process (PID=4254) to work on /opt/airflow/dags/ingestion_dag.py
[2024-06-27T23:13:33.366+0000] {processor.py:830} INFO - Processing file /opt/airflow/dags/ingestion_dag.py for tasks to queue
[2024-06-27T23:13:33.371+0000] {logging_mixin.py:188} INFO - [2024-06-27T23:13:33.370+0000] {dagbag.py:545} INFO - Filling up the DagBag from /opt/airflow/dags/ingestion_dag.py
[2024-06-27T23:13:33.385+0000] {processor.py:840} INFO - DAG(s) 'exampleDag' retrieved from /opt/airflow/dags/ingestion_dag.py
[2024-06-27T23:13:33.925+0000] {logging_mixin.py:188} INFO - [2024-06-27T23:13:33.925+0000] {dag.py:3096} INFO - Sync 1 DAGs
[2024-06-27T23:13:33.954+0000] {logging_mixin.py:188} INFO - [2024-06-27T23:13:33.953+0000] {dag.py:3954} INFO - Setting next_dagrun for exampleDag to 2024-06-26 00:00:00+00:00, run_after=2024-06-27 00:00:00+00:00
[2024-06-27T23:13:33.980+0000] {processor.py:183} INFO - Processing /opt/airflow/dags/ingestion_dag.py took 0.634 seconds
[2024-06-27T23:14:04.656+0000] {processor.py:161} INFO - Started process (PID=4317) to work on /opt/airflow/dags/ingestion_dag.py
[2024-06-27T23:14:04.660+0000] {processor.py:830} INFO - Processing file /opt/airflow/dags/ingestion_dag.py for tasks to queue
[2024-06-27T23:14:04.665+0000] {logging_mixin.py:188} INFO - [2024-06-27T23:14:04.664+0000] {dagbag.py:545} INFO - Filling up the DagBag from /opt/airflow/dags/ingestion_dag.py
[2024-06-27T23:14:04.694+0000] {processor.py:840} INFO - DAG(s) 'exampleDag' retrieved from /opt/airflow/dags/ingestion_dag.py
[2024-06-27T23:14:04.817+0000] {logging_mixin.py:188} INFO - [2024-06-27T23:14:04.804+0000] {dag.py:3096} INFO - Sync 1 DAGs
[2024-06-27T23:14:04.929+0000] {logging_mixin.py:188} INFO - [2024-06-27T23:14:04.929+0000] {dag.py:3954} INFO - Setting next_dagrun for exampleDag to 2024-06-26 00:00:00+00:00, run_after=2024-06-27 00:00:00+00:00
[2024-06-27T23:14:05.007+0000] {processor.py:183} INFO - Processing /opt/airflow/dags/ingestion_dag.py took 0.372 seconds
[2024-06-27T23:14:35.314+0000] {processor.py:161} INFO - Started process (PID=4379) to work on /opt/airflow/dags/ingestion_dag.py
[2024-06-27T23:14:35.317+0000] {processor.py:830} INFO - Processing file /opt/airflow/dags/ingestion_dag.py for tasks to queue
[2024-06-27T23:14:35.321+0000] {logging_mixin.py:188} INFO - [2024-06-27T23:14:35.320+0000] {dagbag.py:545} INFO - Filling up the DagBag from /opt/airflow/dags/ingestion_dag.py
[2024-06-27T23:14:35.334+0000] {processor.py:840} INFO - DAG(s) 'exampleDag' retrieved from /opt/airflow/dags/ingestion_dag.py
[2024-06-27T23:14:35.360+0000] {logging_mixin.py:188} INFO - [2024-06-27T23:14:35.359+0000] {dag.py:3096} INFO - Sync 1 DAGs
[2024-06-27T23:14:35.402+0000] {logging_mixin.py:188} INFO - [2024-06-27T23:14:35.402+0000] {dag.py:3954} INFO - Setting next_dagrun for exampleDag to 2024-06-26 00:00:00+00:00, run_after=2024-06-27 00:00:00+00:00
[2024-06-27T23:14:35.436+0000] {processor.py:183} INFO - Processing /opt/airflow/dags/ingestion_dag.py took 0.135 seconds
[2024-06-27T23:15:05.848+0000] {processor.py:161} INFO - Started process (PID=4441) to work on /opt/airflow/dags/ingestion_dag.py
[2024-06-27T23:15:05.850+0000] {processor.py:830} INFO - Processing file /opt/airflow/dags/ingestion_dag.py for tasks to queue
[2024-06-27T23:15:05.855+0000] {logging_mixin.py:188} INFO - [2024-06-27T23:15:05.854+0000] {dagbag.py:545} INFO - Filling up the DagBag from /opt/airflow/dags/ingestion_dag.py
[2024-06-27T23:15:05.867+0000] {processor.py:840} INFO - DAG(s) 'exampleDag' retrieved from /opt/airflow/dags/ingestion_dag.py
[2024-06-27T23:15:06.050+0000] {logging_mixin.py:188} INFO - [2024-06-27T23:15:06.048+0000] {dag.py:3096} INFO - Sync 1 DAGs
[2024-06-27T23:15:06.084+0000] {logging_mixin.py:188} INFO - [2024-06-27T23:15:06.083+0000] {dag.py:3954} INFO - Setting next_dagrun for exampleDag to 2024-06-26 00:00:00+00:00, run_after=2024-06-27 00:00:00+00:00
[2024-06-27T23:15:06.130+0000] {processor.py:183} INFO - Processing /opt/airflow/dags/ingestion_dag.py took 0.296 seconds
[2024-06-27T23:15:36.215+0000] {processor.py:161} INFO - Started process (PID=4503) to work on /opt/airflow/dags/ingestion_dag.py
[2024-06-27T23:15:36.217+0000] {processor.py:830} INFO - Processing file /opt/airflow/dags/ingestion_dag.py for tasks to queue
[2024-06-27T23:15:36.221+0000] {logging_mixin.py:188} INFO - [2024-06-27T23:15:36.220+0000] {dagbag.py:545} INFO - Filling up the DagBag from /opt/airflow/dags/ingestion_dag.py
[2024-06-27T23:15:36.234+0000] {processor.py:840} INFO - DAG(s) 'exampleDag' retrieved from /opt/airflow/dags/ingestion_dag.py
[2024-06-27T23:15:36.273+0000] {logging_mixin.py:188} INFO - [2024-06-27T23:15:36.272+0000] {dag.py:3096} INFO - Sync 1 DAGs
[2024-06-27T23:15:36.312+0000] {logging_mixin.py:188} INFO - [2024-06-27T23:15:36.312+0000] {dag.py:3954} INFO - Setting next_dagrun for exampleDag to 2024-06-26 00:00:00+00:00, run_after=2024-06-27 00:00:00+00:00
[2024-06-27T23:15:36.347+0000] {processor.py:183} INFO - Processing /opt/airflow/dags/ingestion_dag.py took 0.145 seconds
[2024-06-27T23:16:06.620+0000] {processor.py:161} INFO - Started process (PID=4566) to work on /opt/airflow/dags/ingestion_dag.py
[2024-06-27T23:16:06.623+0000] {processor.py:830} INFO - Processing file /opt/airflow/dags/ingestion_dag.py for tasks to queue
[2024-06-27T23:16:06.628+0000] {logging_mixin.py:188} INFO - [2024-06-27T23:16:06.628+0000] {dagbag.py:545} INFO - Filling up the DagBag from /opt/airflow/dags/ingestion_dag.py
[2024-06-27T23:16:06.642+0000] {processor.py:840} INFO - DAG(s) 'exampleDag' retrieved from /opt/airflow/dags/ingestion_dag.py
[2024-06-27T23:16:06.668+0000] {logging_mixin.py:188} INFO - [2024-06-27T23:16:06.667+0000] {dag.py:3096} INFO - Sync 1 DAGs
[2024-06-27T23:16:06.710+0000] {logging_mixin.py:188} INFO - [2024-06-27T23:16:06.710+0000] {dag.py:3954} INFO - Setting next_dagrun for exampleDag to 2024-06-26 00:00:00+00:00, run_after=2024-06-27 00:00:00+00:00
[2024-06-27T23:16:06.743+0000] {processor.py:183} INFO - Processing /opt/airflow/dags/ingestion_dag.py took 0.136 seconds
[2024-06-27T23:16:23.306+0000] {processor.py:161} INFO - Started process (PID=4601) to work on /opt/airflow/dags/ingestion_dag.py
[2024-06-27T23:16:23.310+0000] {processor.py:830} INFO - Processing file /opt/airflow/dags/ingestion_dag.py for tasks to queue
[2024-06-27T23:16:23.315+0000] {logging_mixin.py:188} INFO - [2024-06-27T23:16:23.314+0000] {dagbag.py:545} INFO - Filling up the DagBag from /opt/airflow/dags/ingestion_dag.py
[2024-06-27T23:16:23.332+0000] {logging_mixin.py:188} INFO - [2024-06-27T23:16:23.328+0000] {dagbag.py:355} ERROR - Failed to import: /opt/airflow/dags/ingestion_dag.py
Traceback (most recent call last):
  File "/home/airflow/.local/lib/python3.11/site-packages/airflow/models/dagbag.py", line 351, in parse
    loader.exec_module(new_module)
  File "<frozen importlib._bootstrap_external>", line 940, in exec_module
  File "<frozen importlib._bootstrap>", line 241, in _call_with_frames_removed
  File "/opt/airflow/dags/ingestion_dag.py", line 20, in <module>
    SERVICE_ACCOUNT_CREDENTIALS = service_account.Credentials.from_service_account_file(
                                  ^^^^^^^^^^^^^^^^^^^^^^^^^^^^^^^^^^^^^^^^^^^^^^^^^^^^^^
  File "/home/airflow/.local/lib/python3.11/site-packages/google/oauth2/service_account.py", line 258, in from_service_account_file
    info, signer = _service_account_info.from_filename(
                   ^^^^^^^^^^^^^^^^^^^^^^^^^^^^^^^^^^^^
  File "/home/airflow/.local/lib/python3.11/site-packages/google/auth/_service_account_info.py", line 78, in from_filename
    with io.open(filename, "r", encoding="utf-8") as json_file:
         ^^^^^^^^^^^^^^^^^^^^^^^^^^^^^^^^^^^^^^^^
FileNotFoundError: [Errno 2] No such file or directory: '/.gc/my-creds.json'
[2024-06-27T23:16:23.334+0000] {processor.py:842} WARNING - No viable dags retrieved from /opt/airflow/dags/ingestion_dag.py
[2024-06-27T23:16:23.382+0000] {processor.py:183} INFO - Processing /opt/airflow/dags/ingestion_dag.py took 0.093 seconds
[2024-06-27T23:16:53.535+0000] {processor.py:161} INFO - Started process (PID=4663) to work on /opt/airflow/dags/ingestion_dag.py
[2024-06-27T23:16:53.538+0000] {processor.py:830} INFO - Processing file /opt/airflow/dags/ingestion_dag.py for tasks to queue
[2024-06-27T23:16:53.542+0000] {logging_mixin.py:188} INFO - [2024-06-27T23:16:53.542+0000] {dagbag.py:545} INFO - Filling up the DagBag from /opt/airflow/dags/ingestion_dag.py
[2024-06-27T23:16:53.549+0000] {logging_mixin.py:188} INFO - [2024-06-27T23:16:53.547+0000] {dagbag.py:355} ERROR - Failed to import: /opt/airflow/dags/ingestion_dag.py
Traceback (most recent call last):
  File "/home/airflow/.local/lib/python3.11/site-packages/airflow/models/dagbag.py", line 351, in parse
    loader.exec_module(new_module)
  File "<frozen importlib._bootstrap_external>", line 940, in exec_module
  File "<frozen importlib._bootstrap>", line 241, in _call_with_frames_removed
  File "/opt/airflow/dags/ingestion_dag.py", line 20, in <module>
    SERVICE_ACCOUNT_CREDENTIALS = service_account.Credentials.from_service_account_file(
                                  ^^^^^^^^^^^^^^^^^^^^^^^^^^^^^^^^^^^^^^^^^^^^^^^^^^^^^^
  File "/home/airflow/.local/lib/python3.11/site-packages/google/oauth2/service_account.py", line 258, in from_service_account_file
    info, signer = _service_account_info.from_filename(
                   ^^^^^^^^^^^^^^^^^^^^^^^^^^^^^^^^^^^^
  File "/home/airflow/.local/lib/python3.11/site-packages/google/auth/_service_account_info.py", line 78, in from_filename
    with io.open(filename, "r", encoding="utf-8") as json_file:
         ^^^^^^^^^^^^^^^^^^^^^^^^^^^^^^^^^^^^^^^^
FileNotFoundError: [Errno 2] No such file or directory: '/.gc/my-creds.json'
[2024-06-27T23:16:53.551+0000] {processor.py:842} WARNING - No viable dags retrieved from /opt/airflow/dags/ingestion_dag.py
[2024-06-27T23:16:53.587+0000] {processor.py:183} INFO - Processing /opt/airflow/dags/ingestion_dag.py took 0.065 seconds
[2024-06-27T23:17:24.365+0000] {processor.py:161} INFO - Started process (PID=4725) to work on /opt/airflow/dags/ingestion_dag.py
[2024-06-27T23:17:24.367+0000] {processor.py:830} INFO - Processing file /opt/airflow/dags/ingestion_dag.py for tasks to queue
[2024-06-27T23:17:24.372+0000] {logging_mixin.py:188} INFO - [2024-06-27T23:17:24.371+0000] {dagbag.py:545} INFO - Filling up the DagBag from /opt/airflow/dags/ingestion_dag.py
[2024-06-27T23:17:24.380+0000] {logging_mixin.py:188} INFO - [2024-06-27T23:17:24.376+0000] {dagbag.py:355} ERROR - Failed to import: /opt/airflow/dags/ingestion_dag.py
Traceback (most recent call last):
  File "/home/airflow/.local/lib/python3.11/site-packages/airflow/models/dagbag.py", line 351, in parse
    loader.exec_module(new_module)
  File "<frozen importlib._bootstrap_external>", line 940, in exec_module
  File "<frozen importlib._bootstrap>", line 241, in _call_with_frames_removed
  File "/opt/airflow/dags/ingestion_dag.py", line 20, in <module>
    SERVICE_ACCOUNT_CREDENTIALS = service_account.Credentials.from_service_account_file(
                                  ^^^^^^^^^^^^^^^^^^^^^^^^^^^^^^^^^^^^^^^^^^^^^^^^^^^^^^
  File "/home/airflow/.local/lib/python3.11/site-packages/google/oauth2/service_account.py", line 258, in from_service_account_file
    info, signer = _service_account_info.from_filename(
                   ^^^^^^^^^^^^^^^^^^^^^^^^^^^^^^^^^^^^
  File "/home/airflow/.local/lib/python3.11/site-packages/google/auth/_service_account_info.py", line 78, in from_filename
    with io.open(filename, "r", encoding="utf-8") as json_file:
         ^^^^^^^^^^^^^^^^^^^^^^^^^^^^^^^^^^^^^^^^
FileNotFoundError: [Errno 2] No such file or directory: '/.gc/my-creds.json'
[2024-06-27T23:17:24.381+0000] {processor.py:842} WARNING - No viable dags retrieved from /opt/airflow/dags/ingestion_dag.py
[2024-06-27T23:17:24.420+0000] {processor.py:183} INFO - Processing /opt/airflow/dags/ingestion_dag.py took 0.069 seconds
[2024-06-27T23:17:55.022+0000] {processor.py:161} INFO - Started process (PID=4787) to work on /opt/airflow/dags/ingestion_dag.py
[2024-06-27T23:17:55.025+0000] {processor.py:830} INFO - Processing file /opt/airflow/dags/ingestion_dag.py for tasks to queue
[2024-06-27T23:17:55.029+0000] {logging_mixin.py:188} INFO - [2024-06-27T23:17:55.028+0000] {dagbag.py:545} INFO - Filling up the DagBag from /opt/airflow/dags/ingestion_dag.py
[2024-06-27T23:17:55.037+0000] {logging_mixin.py:188} INFO - [2024-06-27T23:17:55.034+0000] {dagbag.py:355} ERROR - Failed to import: /opt/airflow/dags/ingestion_dag.py
Traceback (most recent call last):
  File "/home/airflow/.local/lib/python3.11/site-packages/airflow/models/dagbag.py", line 351, in parse
    loader.exec_module(new_module)
  File "<frozen importlib._bootstrap_external>", line 940, in exec_module
  File "<frozen importlib._bootstrap>", line 241, in _call_with_frames_removed
  File "/opt/airflow/dags/ingestion_dag.py", line 20, in <module>
    SERVICE_ACCOUNT_CREDENTIALS = service_account.Credentials.from_service_account_file(
                                  ^^^^^^^^^^^^^^^^^^^^^^^^^^^^^^^^^^^^^^^^^^^^^^^^^^^^^^
  File "/home/airflow/.local/lib/python3.11/site-packages/google/oauth2/service_account.py", line 258, in from_service_account_file
    info, signer = _service_account_info.from_filename(
                   ^^^^^^^^^^^^^^^^^^^^^^^^^^^^^^^^^^^^
  File "/home/airflow/.local/lib/python3.11/site-packages/google/auth/_service_account_info.py", line 78, in from_filename
    with io.open(filename, "r", encoding="utf-8") as json_file:
         ^^^^^^^^^^^^^^^^^^^^^^^^^^^^^^^^^^^^^^^^
FileNotFoundError: [Errno 2] No such file or directory: '/.gc/my-creds.json'
[2024-06-27T23:17:55.038+0000] {processor.py:842} WARNING - No viable dags retrieved from /opt/airflow/dags/ingestion_dag.py
[2024-06-27T23:17:55.076+0000] {processor.py:183} INFO - Processing /opt/airflow/dags/ingestion_dag.py took 0.067 seconds
[2024-06-27T23:18:25.601+0000] {processor.py:161} INFO - Started process (PID=4850) to work on /opt/airflow/dags/ingestion_dag.py
[2024-06-27T23:18:25.603+0000] {processor.py:830} INFO - Processing file /opt/airflow/dags/ingestion_dag.py for tasks to queue
[2024-06-27T23:18:25.607+0000] {logging_mixin.py:188} INFO - [2024-06-27T23:18:25.607+0000] {dagbag.py:545} INFO - Filling up the DagBag from /opt/airflow/dags/ingestion_dag.py
[2024-06-27T23:18:25.615+0000] {logging_mixin.py:188} INFO - [2024-06-27T23:18:25.612+0000] {dagbag.py:355} ERROR - Failed to import: /opt/airflow/dags/ingestion_dag.py
Traceback (most recent call last):
  File "/home/airflow/.local/lib/python3.11/site-packages/airflow/models/dagbag.py", line 351, in parse
    loader.exec_module(new_module)
  File "<frozen importlib._bootstrap_external>", line 940, in exec_module
  File "<frozen importlib._bootstrap>", line 241, in _call_with_frames_removed
  File "/opt/airflow/dags/ingestion_dag.py", line 20, in <module>
    SERVICE_ACCOUNT_CREDENTIALS = service_account.Credentials.from_service_account_file(
                                  ^^^^^^^^^^^^^^^^^^^^^^^^^^^^^^^^^^^^^^^^^^^^^^^^^^^^^^
  File "/home/airflow/.local/lib/python3.11/site-packages/google/oauth2/service_account.py", line 258, in from_service_account_file
    info, signer = _service_account_info.from_filename(
                   ^^^^^^^^^^^^^^^^^^^^^^^^^^^^^^^^^^^^
  File "/home/airflow/.local/lib/python3.11/site-packages/google/auth/_service_account_info.py", line 78, in from_filename
    with io.open(filename, "r", encoding="utf-8") as json_file:
         ^^^^^^^^^^^^^^^^^^^^^^^^^^^^^^^^^^^^^^^^
FileNotFoundError: [Errno 2] No such file or directory: '/.gc/my-creds.json'
[2024-06-27T23:18:25.616+0000] {processor.py:842} WARNING - No viable dags retrieved from /opt/airflow/dags/ingestion_dag.py
[2024-06-27T23:18:25.652+0000] {processor.py:183} INFO - Processing /opt/airflow/dags/ingestion_dag.py took 0.065 seconds
[2024-06-27T23:18:55.828+0000] {processor.py:161} INFO - Started process (PID=4912) to work on /opt/airflow/dags/ingestion_dag.py
[2024-06-27T23:18:55.831+0000] {processor.py:830} INFO - Processing file /opt/airflow/dags/ingestion_dag.py for tasks to queue
[2024-06-27T23:18:55.835+0000] {logging_mixin.py:188} INFO - [2024-06-27T23:18:55.834+0000] {dagbag.py:545} INFO - Filling up the DagBag from /opt/airflow/dags/ingestion_dag.py
[2024-06-27T23:18:55.842+0000] {logging_mixin.py:188} INFO - [2024-06-27T23:18:55.839+0000] {dagbag.py:355} ERROR - Failed to import: /opt/airflow/dags/ingestion_dag.py
Traceback (most recent call last):
  File "/home/airflow/.local/lib/python3.11/site-packages/airflow/models/dagbag.py", line 351, in parse
    loader.exec_module(new_module)
  File "<frozen importlib._bootstrap_external>", line 940, in exec_module
  File "<frozen importlib._bootstrap>", line 241, in _call_with_frames_removed
  File "/opt/airflow/dags/ingestion_dag.py", line 20, in <module>
    SERVICE_ACCOUNT_CREDENTIALS = service_account.Credentials.from_service_account_file(
                                  ^^^^^^^^^^^^^^^^^^^^^^^^^^^^^^^^^^^^^^^^^^^^^^^^^^^^^^
  File "/home/airflow/.local/lib/python3.11/site-packages/google/oauth2/service_account.py", line 258, in from_service_account_file
    info, signer = _service_account_info.from_filename(
                   ^^^^^^^^^^^^^^^^^^^^^^^^^^^^^^^^^^^^
  File "/home/airflow/.local/lib/python3.11/site-packages/google/auth/_service_account_info.py", line 78, in from_filename
    with io.open(filename, "r", encoding="utf-8") as json_file:
         ^^^^^^^^^^^^^^^^^^^^^^^^^^^^^^^^^^^^^^^^
FileNotFoundError: [Errno 2] No such file or directory: '/.gc/my-creds.json'
[2024-06-27T23:18:55.843+0000] {processor.py:842} WARNING - No viable dags retrieved from /opt/airflow/dags/ingestion_dag.py
[2024-06-27T23:18:55.882+0000] {processor.py:183} INFO - Processing /opt/airflow/dags/ingestion_dag.py took 0.068 seconds
[2024-06-27T23:19:26.611+0000] {processor.py:161} INFO - Started process (PID=4974) to work on /opt/airflow/dags/ingestion_dag.py
[2024-06-27T23:19:26.613+0000] {processor.py:830} INFO - Processing file /opt/airflow/dags/ingestion_dag.py for tasks to queue
[2024-06-27T23:19:26.617+0000] {logging_mixin.py:188} INFO - [2024-06-27T23:19:26.616+0000] {dagbag.py:545} INFO - Filling up the DagBag from /opt/airflow/dags/ingestion_dag.py
[2024-06-27T23:19:26.625+0000] {logging_mixin.py:188} INFO - [2024-06-27T23:19:26.622+0000] {dagbag.py:355} ERROR - Failed to import: /opt/airflow/dags/ingestion_dag.py
Traceback (most recent call last):
  File "/home/airflow/.local/lib/python3.11/site-packages/airflow/models/dagbag.py", line 351, in parse
    loader.exec_module(new_module)
  File "<frozen importlib._bootstrap_external>", line 940, in exec_module
  File "<frozen importlib._bootstrap>", line 241, in _call_with_frames_removed
  File "/opt/airflow/dags/ingestion_dag.py", line 20, in <module>
    SERVICE_ACCOUNT_CREDENTIALS = service_account.Credentials.from_service_account_file(
                                  ^^^^^^^^^^^^^^^^^^^^^^^^^^^^^^^^^^^^^^^^^^^^^^^^^^^^^^
  File "/home/airflow/.local/lib/python3.11/site-packages/google/oauth2/service_account.py", line 258, in from_service_account_file
    info, signer = _service_account_info.from_filename(
                   ^^^^^^^^^^^^^^^^^^^^^^^^^^^^^^^^^^^^
  File "/home/airflow/.local/lib/python3.11/site-packages/google/auth/_service_account_info.py", line 78, in from_filename
    with io.open(filename, "r", encoding="utf-8") as json_file:
         ^^^^^^^^^^^^^^^^^^^^^^^^^^^^^^^^^^^^^^^^
FileNotFoundError: [Errno 2] No such file or directory: '/.gc/my-creds.json'
[2024-06-27T23:19:26.626+0000] {processor.py:842} WARNING - No viable dags retrieved from /opt/airflow/dags/ingestion_dag.py
[2024-06-27T23:19:26.662+0000] {processor.py:183} INFO - Processing /opt/airflow/dags/ingestion_dag.py took 0.064 seconds
[2024-06-27T23:19:57.007+0000] {processor.py:161} INFO - Started process (PID=5036) to work on /opt/airflow/dags/ingestion_dag.py
[2024-06-27T23:19:57.010+0000] {processor.py:830} INFO - Processing file /opt/airflow/dags/ingestion_dag.py for tasks to queue
[2024-06-27T23:19:57.014+0000] {logging_mixin.py:188} INFO - [2024-06-27T23:19:57.013+0000] {dagbag.py:545} INFO - Filling up the DagBag from /opt/airflow/dags/ingestion_dag.py
[2024-06-27T23:19:57.021+0000] {logging_mixin.py:188} INFO - [2024-06-27T23:19:57.018+0000] {dagbag.py:355} ERROR - Failed to import: /opt/airflow/dags/ingestion_dag.py
Traceback (most recent call last):
  File "/home/airflow/.local/lib/python3.11/site-packages/airflow/models/dagbag.py", line 351, in parse
    loader.exec_module(new_module)
  File "<frozen importlib._bootstrap_external>", line 940, in exec_module
  File "<frozen importlib._bootstrap>", line 241, in _call_with_frames_removed
  File "/opt/airflow/dags/ingestion_dag.py", line 20, in <module>
    SERVICE_ACCOUNT_CREDENTIALS = service_account.Credentials.from_service_account_file(
                                  ^^^^^^^^^^^^^^^^^^^^^^^^^^^^^^^^^^^^^^^^^^^^^^^^^^^^^^
  File "/home/airflow/.local/lib/python3.11/site-packages/google/oauth2/service_account.py", line 258, in from_service_account_file
    info, signer = _service_account_info.from_filename(
                   ^^^^^^^^^^^^^^^^^^^^^^^^^^^^^^^^^^^^
  File "/home/airflow/.local/lib/python3.11/site-packages/google/auth/_service_account_info.py", line 78, in from_filename
    with io.open(filename, "r", encoding="utf-8") as json_file:
         ^^^^^^^^^^^^^^^^^^^^^^^^^^^^^^^^^^^^^^^^
FileNotFoundError: [Errno 2] No such file or directory: '/.gc/my-creds.json'
[2024-06-27T23:19:57.023+0000] {processor.py:842} WARNING - No viable dags retrieved from /opt/airflow/dags/ingestion_dag.py
[2024-06-27T23:19:57.059+0000] {processor.py:183} INFO - Processing /opt/airflow/dags/ingestion_dag.py took 0.066 seconds
[2024-06-27T23:20:27.227+0000] {processor.py:161} INFO - Started process (PID=5098) to work on /opt/airflow/dags/ingestion_dag.py
[2024-06-27T23:20:27.228+0000] {processor.py:830} INFO - Processing file /opt/airflow/dags/ingestion_dag.py for tasks to queue
[2024-06-27T23:20:27.233+0000] {logging_mixin.py:188} INFO - [2024-06-27T23:20:27.232+0000] {dagbag.py:545} INFO - Filling up the DagBag from /opt/airflow/dags/ingestion_dag.py
[2024-06-27T23:20:27.241+0000] {logging_mixin.py:188} INFO - [2024-06-27T23:20:27.238+0000] {dagbag.py:355} ERROR - Failed to import: /opt/airflow/dags/ingestion_dag.py
Traceback (most recent call last):
  File "/home/airflow/.local/lib/python3.11/site-packages/airflow/models/dagbag.py", line 351, in parse
    loader.exec_module(new_module)
  File "<frozen importlib._bootstrap_external>", line 940, in exec_module
  File "<frozen importlib._bootstrap>", line 241, in _call_with_frames_removed
  File "/opt/airflow/dags/ingestion_dag.py", line 20, in <module>
    SERVICE_ACCOUNT_CREDENTIALS = service_account.Credentials.from_service_account_file(
                                  ^^^^^^^^^^^^^^^^^^^^^^^^^^^^^^^^^^^^^^^^^^^^^^^^^^^^^^
  File "/home/airflow/.local/lib/python3.11/site-packages/google/oauth2/service_account.py", line 258, in from_service_account_file
    info, signer = _service_account_info.from_filename(
                   ^^^^^^^^^^^^^^^^^^^^^^^^^^^^^^^^^^^^
  File "/home/airflow/.local/lib/python3.11/site-packages/google/auth/_service_account_info.py", line 78, in from_filename
    with io.open(filename, "r", encoding="utf-8") as json_file:
         ^^^^^^^^^^^^^^^^^^^^^^^^^^^^^^^^^^^^^^^^
FileNotFoundError: [Errno 2] No such file or directory: '/.gc/my-creds.json'
[2024-06-27T23:20:27.243+0000] {processor.py:842} WARNING - No viable dags retrieved from /opt/airflow/dags/ingestion_dag.py
[2024-06-27T23:20:27.284+0000] {processor.py:183} INFO - Processing /opt/airflow/dags/ingestion_dag.py took 0.071 seconds
[2024-06-27T23:20:57.543+0000] {processor.py:161} INFO - Started process (PID=5160) to work on /opt/airflow/dags/ingestion_dag.py
[2024-06-27T23:20:57.546+0000] {processor.py:830} INFO - Processing file /opt/airflow/dags/ingestion_dag.py for tasks to queue
[2024-06-27T23:20:57.550+0000] {logging_mixin.py:188} INFO - [2024-06-27T23:20:57.549+0000] {dagbag.py:545} INFO - Filling up the DagBag from /opt/airflow/dags/ingestion_dag.py
[2024-06-27T23:20:57.557+0000] {logging_mixin.py:188} INFO - [2024-06-27T23:20:57.555+0000] {dagbag.py:355} ERROR - Failed to import: /opt/airflow/dags/ingestion_dag.py
Traceback (most recent call last):
  File "/home/airflow/.local/lib/python3.11/site-packages/airflow/models/dagbag.py", line 351, in parse
    loader.exec_module(new_module)
  File "<frozen importlib._bootstrap_external>", line 940, in exec_module
  File "<frozen importlib._bootstrap>", line 241, in _call_with_frames_removed
  File "/opt/airflow/dags/ingestion_dag.py", line 20, in <module>
    SERVICE_ACCOUNT_CREDENTIALS = service_account.Credentials.from_service_account_file(
                                  ^^^^^^^^^^^^^^^^^^^^^^^^^^^^^^^^^^^^^^^^^^^^^^^^^^^^^^
  File "/home/airflow/.local/lib/python3.11/site-packages/google/oauth2/service_account.py", line 258, in from_service_account_file
    info, signer = _service_account_info.from_filename(
                   ^^^^^^^^^^^^^^^^^^^^^^^^^^^^^^^^^^^^
  File "/home/airflow/.local/lib/python3.11/site-packages/google/auth/_service_account_info.py", line 78, in from_filename
    with io.open(filename, "r", encoding="utf-8") as json_file:
         ^^^^^^^^^^^^^^^^^^^^^^^^^^^^^^^^^^^^^^^^
FileNotFoundError: [Errno 2] No such file or directory: '/.gc/my-creds.json'
[2024-06-27T23:20:57.558+0000] {processor.py:842} WARNING - No viable dags retrieved from /opt/airflow/dags/ingestion_dag.py
[2024-06-27T23:20:57.598+0000] {processor.py:183} INFO - Processing /opt/airflow/dags/ingestion_dag.py took 0.070 seconds
[2024-06-27T23:21:27.829+0000] {processor.py:161} INFO - Started process (PID=5221) to work on /opt/airflow/dags/ingestion_dag.py
[2024-06-27T23:21:27.832+0000] {processor.py:830} INFO - Processing file /opt/airflow/dags/ingestion_dag.py for tasks to queue
[2024-06-27T23:21:27.837+0000] {logging_mixin.py:188} INFO - [2024-06-27T23:21:27.836+0000] {dagbag.py:545} INFO - Filling up the DagBag from /opt/airflow/dags/ingestion_dag.py
[2024-06-27T23:21:27.844+0000] {logging_mixin.py:188} INFO - [2024-06-27T23:21:27.841+0000] {dagbag.py:355} ERROR - Failed to import: /opt/airflow/dags/ingestion_dag.py
Traceback (most recent call last):
  File "/home/airflow/.local/lib/python3.11/site-packages/airflow/models/dagbag.py", line 351, in parse
    loader.exec_module(new_module)
  File "<frozen importlib._bootstrap_external>", line 940, in exec_module
  File "<frozen importlib._bootstrap>", line 241, in _call_with_frames_removed
  File "/opt/airflow/dags/ingestion_dag.py", line 20, in <module>
    SERVICE_ACCOUNT_CREDENTIALS = service_account.Credentials.from_service_account_file(
                                  ^^^^^^^^^^^^^^^^^^^^^^^^^^^^^^^^^^^^^^^^^^^^^^^^^^^^^^
  File "/home/airflow/.local/lib/python3.11/site-packages/google/oauth2/service_account.py", line 258, in from_service_account_file
    info, signer = _service_account_info.from_filename(
                   ^^^^^^^^^^^^^^^^^^^^^^^^^^^^^^^^^^^^
  File "/home/airflow/.local/lib/python3.11/site-packages/google/auth/_service_account_info.py", line 78, in from_filename
    with io.open(filename, "r", encoding="utf-8") as json_file:
         ^^^^^^^^^^^^^^^^^^^^^^^^^^^^^^^^^^^^^^^^
FileNotFoundError: [Errno 2] No such file or directory: '/.gc/my-creds.json'
[2024-06-27T23:21:27.845+0000] {processor.py:842} WARNING - No viable dags retrieved from /opt/airflow/dags/ingestion_dag.py
[2024-06-27T23:21:27.884+0000] {processor.py:183} INFO - Processing /opt/airflow/dags/ingestion_dag.py took 0.068 seconds
[2024-06-27T23:21:58.597+0000] {processor.py:161} INFO - Started process (PID=5283) to work on /opt/airflow/dags/ingestion_dag.py
[2024-06-27T23:21:58.600+0000] {processor.py:830} INFO - Processing file /opt/airflow/dags/ingestion_dag.py for tasks to queue
[2024-06-27T23:21:58.603+0000] {logging_mixin.py:188} INFO - [2024-06-27T23:21:58.603+0000] {dagbag.py:545} INFO - Filling up the DagBag from /opt/airflow/dags/ingestion_dag.py
[2024-06-27T23:21:58.610+0000] {logging_mixin.py:188} INFO - [2024-06-27T23:21:58.608+0000] {dagbag.py:355} ERROR - Failed to import: /opt/airflow/dags/ingestion_dag.py
Traceback (most recent call last):
  File "/home/airflow/.local/lib/python3.11/site-packages/airflow/models/dagbag.py", line 351, in parse
    loader.exec_module(new_module)
  File "<frozen importlib._bootstrap_external>", line 940, in exec_module
  File "<frozen importlib._bootstrap>", line 241, in _call_with_frames_removed
  File "/opt/airflow/dags/ingestion_dag.py", line 20, in <module>
    SERVICE_ACCOUNT_CREDENTIALS = service_account.Credentials.from_service_account_file(
                                  ^^^^^^^^^^^^^^^^^^^^^^^^^^^^^^^^^^^^^^^^^^^^^^^^^^^^^^
  File "/home/airflow/.local/lib/python3.11/site-packages/google/oauth2/service_account.py", line 258, in from_service_account_file
    info, signer = _service_account_info.from_filename(
                   ^^^^^^^^^^^^^^^^^^^^^^^^^^^^^^^^^^^^
  File "/home/airflow/.local/lib/python3.11/site-packages/google/auth/_service_account_info.py", line 78, in from_filename
    with io.open(filename, "r", encoding="utf-8") as json_file:
         ^^^^^^^^^^^^^^^^^^^^^^^^^^^^^^^^^^^^^^^^
FileNotFoundError: [Errno 2] No such file or directory: '/.gc/my-creds.json'
[2024-06-27T23:21:58.611+0000] {processor.py:842} WARNING - No viable dags retrieved from /opt/airflow/dags/ingestion_dag.py
[2024-06-27T23:21:58.644+0000] {processor.py:183} INFO - Processing /opt/airflow/dags/ingestion_dag.py took 0.060 seconds
[2024-06-27T23:22:29.289+0000] {processor.py:161} INFO - Started process (PID=5345) to work on /opt/airflow/dags/ingestion_dag.py
[2024-06-27T23:22:29.291+0000] {processor.py:830} INFO - Processing file /opt/airflow/dags/ingestion_dag.py for tasks to queue
[2024-06-27T23:22:29.295+0000] {logging_mixin.py:188} INFO - [2024-06-27T23:22:29.294+0000] {dagbag.py:545} INFO - Filling up the DagBag from /opt/airflow/dags/ingestion_dag.py
[2024-06-27T23:22:29.302+0000] {logging_mixin.py:188} INFO - [2024-06-27T23:22:29.299+0000] {dagbag.py:355} ERROR - Failed to import: /opt/airflow/dags/ingestion_dag.py
Traceback (most recent call last):
  File "/home/airflow/.local/lib/python3.11/site-packages/airflow/models/dagbag.py", line 351, in parse
    loader.exec_module(new_module)
  File "<frozen importlib._bootstrap_external>", line 940, in exec_module
  File "<frozen importlib._bootstrap>", line 241, in _call_with_frames_removed
  File "/opt/airflow/dags/ingestion_dag.py", line 20, in <module>
    SERVICE_ACCOUNT_CREDENTIALS = service_account.Credentials.from_service_account_file(
                                  ^^^^^^^^^^^^^^^^^^^^^^^^^^^^^^^^^^^^^^^^^^^^^^^^^^^^^^
  File "/home/airflow/.local/lib/python3.11/site-packages/google/oauth2/service_account.py", line 258, in from_service_account_file
    info, signer = _service_account_info.from_filename(
                   ^^^^^^^^^^^^^^^^^^^^^^^^^^^^^^^^^^^^
  File "/home/airflow/.local/lib/python3.11/site-packages/google/auth/_service_account_info.py", line 78, in from_filename
    with io.open(filename, "r", encoding="utf-8") as json_file:
         ^^^^^^^^^^^^^^^^^^^^^^^^^^^^^^^^^^^^^^^^
FileNotFoundError: [Errno 2] No such file or directory: '/.gc/my-creds.json'
[2024-06-27T23:22:29.303+0000] {processor.py:842} WARNING - No viable dags retrieved from /opt/airflow/dags/ingestion_dag.py
[2024-06-27T23:22:29.343+0000] {processor.py:183} INFO - Processing /opt/airflow/dags/ingestion_dag.py took 0.068 seconds
[2024-06-27T23:23:00.148+0000] {processor.py:161} INFO - Started process (PID=5406) to work on /opt/airflow/dags/ingestion_dag.py
[2024-06-27T23:23:00.150+0000] {processor.py:830} INFO - Processing file /opt/airflow/dags/ingestion_dag.py for tasks to queue
[2024-06-27T23:23:00.154+0000] {logging_mixin.py:188} INFO - [2024-06-27T23:23:00.154+0000] {dagbag.py:545} INFO - Filling up the DagBag from /opt/airflow/dags/ingestion_dag.py
[2024-06-27T23:23:00.162+0000] {logging_mixin.py:188} INFO - [2024-06-27T23:23:00.159+0000] {dagbag.py:355} ERROR - Failed to import: /opt/airflow/dags/ingestion_dag.py
Traceback (most recent call last):
  File "/home/airflow/.local/lib/python3.11/site-packages/airflow/models/dagbag.py", line 351, in parse
    loader.exec_module(new_module)
  File "<frozen importlib._bootstrap_external>", line 940, in exec_module
  File "<frozen importlib._bootstrap>", line 241, in _call_with_frames_removed
  File "/opt/airflow/dags/ingestion_dag.py", line 20, in <module>
    SERVICE_ACCOUNT_CREDENTIALS = service_account.Credentials.from_service_account_file(
                                  ^^^^^^^^^^^^^^^^^^^^^^^^^^^^^^^^^^^^^^^^^^^^^^^^^^^^^^
  File "/home/airflow/.local/lib/python3.11/site-packages/google/oauth2/service_account.py", line 258, in from_service_account_file
    info, signer = _service_account_info.from_filename(
                   ^^^^^^^^^^^^^^^^^^^^^^^^^^^^^^^^^^^^
  File "/home/airflow/.local/lib/python3.11/site-packages/google/auth/_service_account_info.py", line 78, in from_filename
    with io.open(filename, "r", encoding="utf-8") as json_file:
         ^^^^^^^^^^^^^^^^^^^^^^^^^^^^^^^^^^^^^^^^
FileNotFoundError: [Errno 2] No such file or directory: '/.gc/my-creds.json'
[2024-06-27T23:23:00.163+0000] {processor.py:842} WARNING - No viable dags retrieved from /opt/airflow/dags/ingestion_dag.py
[2024-06-27T23:23:00.202+0000] {processor.py:183} INFO - Processing /opt/airflow/dags/ingestion_dag.py took 0.067 seconds
[2024-06-27T23:23:30.526+0000] {processor.py:161} INFO - Started process (PID=5469) to work on /opt/airflow/dags/ingestion_dag.py
[2024-06-27T23:23:30.528+0000] {processor.py:830} INFO - Processing file /opt/airflow/dags/ingestion_dag.py for tasks to queue
[2024-06-27T23:23:30.532+0000] {logging_mixin.py:188} INFO - [2024-06-27T23:23:30.531+0000] {dagbag.py:545} INFO - Filling up the DagBag from /opt/airflow/dags/ingestion_dag.py
[2024-06-27T23:23:30.539+0000] {logging_mixin.py:188} INFO - [2024-06-27T23:23:30.536+0000] {dagbag.py:355} ERROR - Failed to import: /opt/airflow/dags/ingestion_dag.py
Traceback (most recent call last):
  File "/home/airflow/.local/lib/python3.11/site-packages/airflow/models/dagbag.py", line 351, in parse
    loader.exec_module(new_module)
  File "<frozen importlib._bootstrap_external>", line 940, in exec_module
  File "<frozen importlib._bootstrap>", line 241, in _call_with_frames_removed
  File "/opt/airflow/dags/ingestion_dag.py", line 20, in <module>
    SERVICE_ACCOUNT_CREDENTIALS = service_account.Credentials.from_service_account_file(
                                  ^^^^^^^^^^^^^^^^^^^^^^^^^^^^^^^^^^^^^^^^^^^^^^^^^^^^^^
  File "/home/airflow/.local/lib/python3.11/site-packages/google/oauth2/service_account.py", line 258, in from_service_account_file
    info, signer = _service_account_info.from_filename(
                   ^^^^^^^^^^^^^^^^^^^^^^^^^^^^^^^^^^^^
  File "/home/airflow/.local/lib/python3.11/site-packages/google/auth/_service_account_info.py", line 78, in from_filename
    with io.open(filename, "r", encoding="utf-8") as json_file:
         ^^^^^^^^^^^^^^^^^^^^^^^^^^^^^^^^^^^^^^^^
FileNotFoundError: [Errno 2] No such file or directory: '/.gc/my-creds.json'
[2024-06-27T23:23:30.540+0000] {processor.py:842} WARNING - No viable dags retrieved from /opt/airflow/dags/ingestion_dag.py
[2024-06-27T23:23:30.580+0000] {processor.py:183} INFO - Processing /opt/airflow/dags/ingestion_dag.py took 0.068 seconds
[2024-06-27T23:24:00.939+0000] {processor.py:161} INFO - Started process (PID=5531) to work on /opt/airflow/dags/ingestion_dag.py
[2024-06-27T23:24:00.942+0000] {processor.py:830} INFO - Processing file /opt/airflow/dags/ingestion_dag.py for tasks to queue
[2024-06-27T23:24:00.946+0000] {logging_mixin.py:188} INFO - [2024-06-27T23:24:00.946+0000] {dagbag.py:545} INFO - Filling up the DagBag from /opt/airflow/dags/ingestion_dag.py
[2024-06-27T23:24:00.953+0000] {logging_mixin.py:188} INFO - [2024-06-27T23:24:00.951+0000] {dagbag.py:355} ERROR - Failed to import: /opt/airflow/dags/ingestion_dag.py
Traceback (most recent call last):
  File "/home/airflow/.local/lib/python3.11/site-packages/airflow/models/dagbag.py", line 351, in parse
    loader.exec_module(new_module)
  File "<frozen importlib._bootstrap_external>", line 940, in exec_module
  File "<frozen importlib._bootstrap>", line 241, in _call_with_frames_removed
  File "/opt/airflow/dags/ingestion_dag.py", line 20, in <module>
    SERVICE_ACCOUNT_CREDENTIALS = service_account.Credentials.from_service_account_file(
                                  ^^^^^^^^^^^^^^^^^^^^^^^^^^^^^^^^^^^^^^^^^^^^^^^^^^^^^^
  File "/home/airflow/.local/lib/python3.11/site-packages/google/oauth2/service_account.py", line 258, in from_service_account_file
    info, signer = _service_account_info.from_filename(
                   ^^^^^^^^^^^^^^^^^^^^^^^^^^^^^^^^^^^^
  File "/home/airflow/.local/lib/python3.11/site-packages/google/auth/_service_account_info.py", line 78, in from_filename
    with io.open(filename, "r", encoding="utf-8") as json_file:
         ^^^^^^^^^^^^^^^^^^^^^^^^^^^^^^^^^^^^^^^^
FileNotFoundError: [Errno 2] No such file or directory: '/.gc/my-creds.json'
[2024-06-27T23:24:00.954+0000] {processor.py:842} WARNING - No viable dags retrieved from /opt/airflow/dags/ingestion_dag.py
[2024-06-27T23:24:00.995+0000] {processor.py:183} INFO - Processing /opt/airflow/dags/ingestion_dag.py took 0.069 seconds
[2024-06-27T23:24:31.172+0000] {processor.py:161} INFO - Started process (PID=5593) to work on /opt/airflow/dags/ingestion_dag.py
[2024-06-27T23:24:31.178+0000] {processor.py:830} INFO - Processing file /opt/airflow/dags/ingestion_dag.py for tasks to queue
[2024-06-27T23:24:31.193+0000] {logging_mixin.py:188} INFO - [2024-06-27T23:24:31.191+0000] {dagbag.py:545} INFO - Filling up the DagBag from /opt/airflow/dags/ingestion_dag.py
[2024-06-27T23:24:31.210+0000] {logging_mixin.py:188} INFO - [2024-06-27T23:24:31.205+0000] {dagbag.py:355} ERROR - Failed to import: /opt/airflow/dags/ingestion_dag.py
Traceback (most recent call last):
  File "/home/airflow/.local/lib/python3.11/site-packages/airflow/models/dagbag.py", line 351, in parse
    loader.exec_module(new_module)
  File "<frozen importlib._bootstrap_external>", line 940, in exec_module
  File "<frozen importlib._bootstrap>", line 241, in _call_with_frames_removed
  File "/opt/airflow/dags/ingestion_dag.py", line 20, in <module>
    SERVICE_ACCOUNT_CREDENTIALS = service_account.Credentials.from_service_account_file(
                                  ^^^^^^^^^^^^^^^^^^^^^^^^^^^^^^^^^^^^^^^^^^^^^^^^^^^^^^
  File "/home/airflow/.local/lib/python3.11/site-packages/google/oauth2/service_account.py", line 258, in from_service_account_file
    info, signer = _service_account_info.from_filename(
                   ^^^^^^^^^^^^^^^^^^^^^^^^^^^^^^^^^^^^
  File "/home/airflow/.local/lib/python3.11/site-packages/google/auth/_service_account_info.py", line 78, in from_filename
    with io.open(filename, "r", encoding="utf-8") as json_file:
         ^^^^^^^^^^^^^^^^^^^^^^^^^^^^^^^^^^^^^^^^
FileNotFoundError: [Errno 2] No such file or directory: '/.gc/my-creds.json'
[2024-06-27T23:24:31.215+0000] {processor.py:842} WARNING - No viable dags retrieved from /opt/airflow/dags/ingestion_dag.py
[2024-06-27T23:24:31.303+0000] {processor.py:183} INFO - Processing /opt/airflow/dags/ingestion_dag.py took 0.163 seconds
[2024-06-27T23:25:01.436+0000] {processor.py:161} INFO - Started process (PID=5654) to work on /opt/airflow/dags/ingestion_dag.py
[2024-06-27T23:25:01.440+0000] {processor.py:830} INFO - Processing file /opt/airflow/dags/ingestion_dag.py for tasks to queue
[2024-06-27T23:25:01.445+0000] {logging_mixin.py:188} INFO - [2024-06-27T23:25:01.444+0000] {dagbag.py:545} INFO - Filling up the DagBag from /opt/airflow/dags/ingestion_dag.py
[2024-06-27T23:25:01.453+0000] {logging_mixin.py:188} INFO - [2024-06-27T23:25:01.450+0000] {dagbag.py:355} ERROR - Failed to import: /opt/airflow/dags/ingestion_dag.py
Traceback (most recent call last):
  File "/home/airflow/.local/lib/python3.11/site-packages/airflow/models/dagbag.py", line 351, in parse
    loader.exec_module(new_module)
  File "<frozen importlib._bootstrap_external>", line 940, in exec_module
  File "<frozen importlib._bootstrap>", line 241, in _call_with_frames_removed
  File "/opt/airflow/dags/ingestion_dag.py", line 20, in <module>
    SERVICE_ACCOUNT_CREDENTIALS = service_account.Credentials.from_service_account_file(
                                  ^^^^^^^^^^^^^^^^^^^^^^^^^^^^^^^^^^^^^^^^^^^^^^^^^^^^^^
  File "/home/airflow/.local/lib/python3.11/site-packages/google/oauth2/service_account.py", line 258, in from_service_account_file
    info, signer = _service_account_info.from_filename(
                   ^^^^^^^^^^^^^^^^^^^^^^^^^^^^^^^^^^^^
  File "/home/airflow/.local/lib/python3.11/site-packages/google/auth/_service_account_info.py", line 78, in from_filename
    with io.open(filename, "r", encoding="utf-8") as json_file:
         ^^^^^^^^^^^^^^^^^^^^^^^^^^^^^^^^^^^^^^^^
FileNotFoundError: [Errno 2] No such file or directory: '/.gc/my-creds.json'
[2024-06-27T23:25:01.455+0000] {processor.py:842} WARNING - No viable dags retrieved from /opt/airflow/dags/ingestion_dag.py
[2024-06-27T23:25:01.495+0000] {processor.py:183} INFO - Processing /opt/airflow/dags/ingestion_dag.py took 0.077 seconds
[2024-06-27T23:25:31.673+0000] {processor.py:161} INFO - Started process (PID=5715) to work on /opt/airflow/dags/ingestion_dag.py
[2024-06-27T23:25:31.675+0000] {processor.py:830} INFO - Processing file /opt/airflow/dags/ingestion_dag.py for tasks to queue
[2024-06-27T23:25:31.681+0000] {logging_mixin.py:188} INFO - [2024-06-27T23:25:31.680+0000] {dagbag.py:545} INFO - Filling up the DagBag from /opt/airflow/dags/ingestion_dag.py
[2024-06-27T23:25:31.690+0000] {logging_mixin.py:188} INFO - [2024-06-27T23:25:31.687+0000] {dagbag.py:355} ERROR - Failed to import: /opt/airflow/dags/ingestion_dag.py
Traceback (most recent call last):
  File "/home/airflow/.local/lib/python3.11/site-packages/airflow/models/dagbag.py", line 351, in parse
    loader.exec_module(new_module)
  File "<frozen importlib._bootstrap_external>", line 940, in exec_module
  File "<frozen importlib._bootstrap>", line 241, in _call_with_frames_removed
  File "/opt/airflow/dags/ingestion_dag.py", line 20, in <module>
    SERVICE_ACCOUNT_CREDENTIALS = service_account.Credentials.from_service_account_file(
                                  ^^^^^^^^^^^^^^^^^^^^^^^^^^^^^^^^^^^^^^^^^^^^^^^^^^^^^^
  File "/home/airflow/.local/lib/python3.11/site-packages/google/oauth2/service_account.py", line 258, in from_service_account_file
    info, signer = _service_account_info.from_filename(
                   ^^^^^^^^^^^^^^^^^^^^^^^^^^^^^^^^^^^^
  File "/home/airflow/.local/lib/python3.11/site-packages/google/auth/_service_account_info.py", line 78, in from_filename
    with io.open(filename, "r", encoding="utf-8") as json_file:
         ^^^^^^^^^^^^^^^^^^^^^^^^^^^^^^^^^^^^^^^^
FileNotFoundError: [Errno 2] No such file or directory: '/.gc/my-creds.json'
[2024-06-27T23:25:31.691+0000] {processor.py:842} WARNING - No viable dags retrieved from /opt/airflow/dags/ingestion_dag.py
[2024-06-27T23:25:31.734+0000] {processor.py:183} INFO - Processing /opt/airflow/dags/ingestion_dag.py took 0.074 seconds
[2024-06-27T23:26:01.978+0000] {processor.py:161} INFO - Started process (PID=5777) to work on /opt/airflow/dags/ingestion_dag.py
[2024-06-27T23:26:01.980+0000] {processor.py:830} INFO - Processing file /opt/airflow/dags/ingestion_dag.py for tasks to queue
[2024-06-27T23:26:01.985+0000] {logging_mixin.py:188} INFO - [2024-06-27T23:26:01.985+0000] {dagbag.py:545} INFO - Filling up the DagBag from /opt/airflow/dags/ingestion_dag.py
[2024-06-27T23:26:01.992+0000] {logging_mixin.py:188} INFO - [2024-06-27T23:26:01.990+0000] {dagbag.py:355} ERROR - Failed to import: /opt/airflow/dags/ingestion_dag.py
Traceback (most recent call last):
  File "/home/airflow/.local/lib/python3.11/site-packages/airflow/models/dagbag.py", line 351, in parse
    loader.exec_module(new_module)
  File "<frozen importlib._bootstrap_external>", line 940, in exec_module
  File "<frozen importlib._bootstrap>", line 241, in _call_with_frames_removed
  File "/opt/airflow/dags/ingestion_dag.py", line 20, in <module>
    SERVICE_ACCOUNT_CREDENTIALS = service_account.Credentials.from_service_account_file(
                                  ^^^^^^^^^^^^^^^^^^^^^^^^^^^^^^^^^^^^^^^^^^^^^^^^^^^^^^
  File "/home/airflow/.local/lib/python3.11/site-packages/google/oauth2/service_account.py", line 258, in from_service_account_file
    info, signer = _service_account_info.from_filename(
                   ^^^^^^^^^^^^^^^^^^^^^^^^^^^^^^^^^^^^
  File "/home/airflow/.local/lib/python3.11/site-packages/google/auth/_service_account_info.py", line 78, in from_filename
    with io.open(filename, "r", encoding="utf-8") as json_file:
         ^^^^^^^^^^^^^^^^^^^^^^^^^^^^^^^^^^^^^^^^
FileNotFoundError: [Errno 2] No such file or directory: '/.gc/my-creds.json'
[2024-06-27T23:26:01.993+0000] {processor.py:842} WARNING - No viable dags retrieved from /opt/airflow/dags/ingestion_dag.py
[2024-06-27T23:26:02.040+0000] {processor.py:183} INFO - Processing /opt/airflow/dags/ingestion_dag.py took 0.076 seconds
[2024-06-27T23:26:32.274+0000] {processor.py:161} INFO - Started process (PID=5838) to work on /opt/airflow/dags/ingestion_dag.py
[2024-06-27T23:26:32.278+0000] {processor.py:830} INFO - Processing file /opt/airflow/dags/ingestion_dag.py for tasks to queue
[2024-06-27T23:26:32.285+0000] {logging_mixin.py:188} INFO - [2024-06-27T23:26:32.284+0000] {dagbag.py:545} INFO - Filling up the DagBag from /opt/airflow/dags/ingestion_dag.py
[2024-06-27T23:26:32.292+0000] {logging_mixin.py:188} INFO - [2024-06-27T23:26:32.290+0000] {dagbag.py:355} ERROR - Failed to import: /opt/airflow/dags/ingestion_dag.py
Traceback (most recent call last):
  File "/home/airflow/.local/lib/python3.11/site-packages/airflow/models/dagbag.py", line 351, in parse
    loader.exec_module(new_module)
  File "<frozen importlib._bootstrap_external>", line 940, in exec_module
  File "<frozen importlib._bootstrap>", line 241, in _call_with_frames_removed
  File "/opt/airflow/dags/ingestion_dag.py", line 20, in <module>
    SERVICE_ACCOUNT_CREDENTIALS = service_account.Credentials.from_service_account_file(
                                  ^^^^^^^^^^^^^^^^^^^^^^^^^^^^^^^^^^^^^^^^^^^^^^^^^^^^^^
  File "/home/airflow/.local/lib/python3.11/site-packages/google/oauth2/service_account.py", line 258, in from_service_account_file
    info, signer = _service_account_info.from_filename(
                   ^^^^^^^^^^^^^^^^^^^^^^^^^^^^^^^^^^^^
  File "/home/airflow/.local/lib/python3.11/site-packages/google/auth/_service_account_info.py", line 78, in from_filename
    with io.open(filename, "r", encoding="utf-8") as json_file:
         ^^^^^^^^^^^^^^^^^^^^^^^^^^^^^^^^^^^^^^^^
FileNotFoundError: [Errno 2] No such file or directory: '/.gc/my-creds.json'
[2024-06-27T23:26:32.294+0000] {processor.py:842} WARNING - No viable dags retrieved from /opt/airflow/dags/ingestion_dag.py
[2024-06-27T23:26:32.342+0000] {processor.py:183} INFO - Processing /opt/airflow/dags/ingestion_dag.py took 0.086 seconds
[2024-06-27T23:27:03.008+0000] {processor.py:161} INFO - Started process (PID=5901) to work on /opt/airflow/dags/ingestion_dag.py
[2024-06-27T23:27:03.012+0000] {processor.py:830} INFO - Processing file /opt/airflow/dags/ingestion_dag.py for tasks to queue
[2024-06-27T23:27:03.018+0000] {logging_mixin.py:188} INFO - [2024-06-27T23:27:03.018+0000] {dagbag.py:545} INFO - Filling up the DagBag from /opt/airflow/dags/ingestion_dag.py
[2024-06-27T23:27:03.026+0000] {logging_mixin.py:188} INFO - [2024-06-27T23:27:03.023+0000] {dagbag.py:355} ERROR - Failed to import: /opt/airflow/dags/ingestion_dag.py
Traceback (most recent call last):
  File "/home/airflow/.local/lib/python3.11/site-packages/airflow/models/dagbag.py", line 351, in parse
    loader.exec_module(new_module)
  File "<frozen importlib._bootstrap_external>", line 940, in exec_module
  File "<frozen importlib._bootstrap>", line 241, in _call_with_frames_removed
  File "/opt/airflow/dags/ingestion_dag.py", line 20, in <module>
    SERVICE_ACCOUNT_CREDENTIALS = service_account.Credentials.from_service_account_file(
                                  ^^^^^^^^^^^^^^^^^^^^^^^^^^^^^^^^^^^^^^^^^^^^^^^^^^^^^^
  File "/home/airflow/.local/lib/python3.11/site-packages/google/oauth2/service_account.py", line 258, in from_service_account_file
    info, signer = _service_account_info.from_filename(
                   ^^^^^^^^^^^^^^^^^^^^^^^^^^^^^^^^^^^^
  File "/home/airflow/.local/lib/python3.11/site-packages/google/auth/_service_account_info.py", line 78, in from_filename
    with io.open(filename, "r", encoding="utf-8") as json_file:
         ^^^^^^^^^^^^^^^^^^^^^^^^^^^^^^^^^^^^^^^^
FileNotFoundError: [Errno 2] No such file or directory: '/.gc/my-creds.json'
[2024-06-27T23:27:03.027+0000] {processor.py:842} WARNING - No viable dags retrieved from /opt/airflow/dags/ingestion_dag.py
[2024-06-27T23:27:03.071+0000] {processor.py:183} INFO - Processing /opt/airflow/dags/ingestion_dag.py took 0.076 seconds
[2024-06-27T23:27:33.757+0000] {processor.py:161} INFO - Started process (PID=5963) to work on /opt/airflow/dags/ingestion_dag.py
[2024-06-27T23:27:33.761+0000] {processor.py:830} INFO - Processing file /opt/airflow/dags/ingestion_dag.py for tasks to queue
[2024-06-27T23:27:33.766+0000] {logging_mixin.py:188} INFO - [2024-06-27T23:27:33.766+0000] {dagbag.py:545} INFO - Filling up the DagBag from /opt/airflow/dags/ingestion_dag.py
[2024-06-27T23:27:33.773+0000] {logging_mixin.py:188} INFO - [2024-06-27T23:27:33.771+0000] {dagbag.py:355} ERROR - Failed to import: /opt/airflow/dags/ingestion_dag.py
Traceback (most recent call last):
  File "/home/airflow/.local/lib/python3.11/site-packages/airflow/models/dagbag.py", line 351, in parse
    loader.exec_module(new_module)
  File "<frozen importlib._bootstrap_external>", line 940, in exec_module
  File "<frozen importlib._bootstrap>", line 241, in _call_with_frames_removed
  File "/opt/airflow/dags/ingestion_dag.py", line 20, in <module>
    SERVICE_ACCOUNT_CREDENTIALS = service_account.Credentials.from_service_account_file(
                                  ^^^^^^^^^^^^^^^^^^^^^^^^^^^^^^^^^^^^^^^^^^^^^^^^^^^^^^
  File "/home/airflow/.local/lib/python3.11/site-packages/google/oauth2/service_account.py", line 258, in from_service_account_file
    info, signer = _service_account_info.from_filename(
                   ^^^^^^^^^^^^^^^^^^^^^^^^^^^^^^^^^^^^
  File "/home/airflow/.local/lib/python3.11/site-packages/google/auth/_service_account_info.py", line 78, in from_filename
    with io.open(filename, "r", encoding="utf-8") as json_file:
         ^^^^^^^^^^^^^^^^^^^^^^^^^^^^^^^^^^^^^^^^
FileNotFoundError: [Errno 2] No such file or directory: '/.gc/my-creds.json'
[2024-06-27T23:27:33.775+0000] {processor.py:842} WARNING - No viable dags retrieved from /opt/airflow/dags/ingestion_dag.py
[2024-06-27T23:27:33.813+0000] {processor.py:183} INFO - Processing /opt/airflow/dags/ingestion_dag.py took 0.070 seconds
[2024-06-27T23:28:04.070+0000] {processor.py:161} INFO - Started process (PID=6024) to work on /opt/airflow/dags/ingestion_dag.py
[2024-06-27T23:28:04.074+0000] {processor.py:830} INFO - Processing file /opt/airflow/dags/ingestion_dag.py for tasks to queue
[2024-06-27T23:28:04.080+0000] {logging_mixin.py:188} INFO - [2024-06-27T23:28:04.080+0000] {dagbag.py:545} INFO - Filling up the DagBag from /opt/airflow/dags/ingestion_dag.py
[2024-06-27T23:28:04.089+0000] {logging_mixin.py:188} INFO - [2024-06-27T23:28:04.086+0000] {dagbag.py:355} ERROR - Failed to import: /opt/airflow/dags/ingestion_dag.py
Traceback (most recent call last):
  File "/home/airflow/.local/lib/python3.11/site-packages/airflow/models/dagbag.py", line 351, in parse
    loader.exec_module(new_module)
  File "<frozen importlib._bootstrap_external>", line 940, in exec_module
  File "<frozen importlib._bootstrap>", line 241, in _call_with_frames_removed
  File "/opt/airflow/dags/ingestion_dag.py", line 20, in <module>
    SERVICE_ACCOUNT_CREDENTIALS = service_account.Credentials.from_service_account_file(
                                  ^^^^^^^^^^^^^^^^^^^^^^^^^^^^^^^^^^^^^^^^^^^^^^^^^^^^^^
  File "/home/airflow/.local/lib/python3.11/site-packages/google/oauth2/service_account.py", line 258, in from_service_account_file
    info, signer = _service_account_info.from_filename(
                   ^^^^^^^^^^^^^^^^^^^^^^^^^^^^^^^^^^^^
  File "/home/airflow/.local/lib/python3.11/site-packages/google/auth/_service_account_info.py", line 78, in from_filename
    with io.open(filename, "r", encoding="utf-8") as json_file:
         ^^^^^^^^^^^^^^^^^^^^^^^^^^^^^^^^^^^^^^^^
FileNotFoundError: [Errno 2] No such file or directory: '/.gc/my-creds.json'
[2024-06-27T23:28:04.090+0000] {processor.py:842} WARNING - No viable dags retrieved from /opt/airflow/dags/ingestion_dag.py
[2024-06-27T23:28:04.130+0000] {processor.py:183} INFO - Processing /opt/airflow/dags/ingestion_dag.py took 0.079 seconds
[2024-06-27T23:28:34.804+0000] {processor.py:161} INFO - Started process (PID=6086) to work on /opt/airflow/dags/ingestion_dag.py
[2024-06-27T23:28:34.806+0000] {processor.py:830} INFO - Processing file /opt/airflow/dags/ingestion_dag.py for tasks to queue
[2024-06-27T23:28:34.812+0000] {logging_mixin.py:188} INFO - [2024-06-27T23:28:34.812+0000] {dagbag.py:545} INFO - Filling up the DagBag from /opt/airflow/dags/ingestion_dag.py
[2024-06-27T23:28:34.819+0000] {logging_mixin.py:188} INFO - [2024-06-27T23:28:34.817+0000] {dagbag.py:355} ERROR - Failed to import: /opt/airflow/dags/ingestion_dag.py
Traceback (most recent call last):
  File "/home/airflow/.local/lib/python3.11/site-packages/airflow/models/dagbag.py", line 351, in parse
    loader.exec_module(new_module)
  File "<frozen importlib._bootstrap_external>", line 940, in exec_module
  File "<frozen importlib._bootstrap>", line 241, in _call_with_frames_removed
  File "/opt/airflow/dags/ingestion_dag.py", line 20, in <module>
    SERVICE_ACCOUNT_CREDENTIALS = service_account.Credentials.from_service_account_file(
                                  ^^^^^^^^^^^^^^^^^^^^^^^^^^^^^^^^^^^^^^^^^^^^^^^^^^^^^^
  File "/home/airflow/.local/lib/python3.11/site-packages/google/oauth2/service_account.py", line 258, in from_service_account_file
    info, signer = _service_account_info.from_filename(
                   ^^^^^^^^^^^^^^^^^^^^^^^^^^^^^^^^^^^^
  File "/home/airflow/.local/lib/python3.11/site-packages/google/auth/_service_account_info.py", line 78, in from_filename
    with io.open(filename, "r", encoding="utf-8") as json_file:
         ^^^^^^^^^^^^^^^^^^^^^^^^^^^^^^^^^^^^^^^^
FileNotFoundError: [Errno 2] No such file or directory: '/.gc/my-creds.json'
[2024-06-27T23:28:34.820+0000] {processor.py:842} WARNING - No viable dags retrieved from /opt/airflow/dags/ingestion_dag.py
[2024-06-27T23:28:34.861+0000] {processor.py:183} INFO - Processing /opt/airflow/dags/ingestion_dag.py took 0.071 seconds
[2024-06-27T23:29:05.225+0000] {processor.py:161} INFO - Started process (PID=6148) to work on /opt/airflow/dags/ingestion_dag.py
[2024-06-27T23:29:05.227+0000] {processor.py:830} INFO - Processing file /opt/airflow/dags/ingestion_dag.py for tasks to queue
[2024-06-27T23:29:05.234+0000] {logging_mixin.py:188} INFO - [2024-06-27T23:29:05.233+0000] {dagbag.py:545} INFO - Filling up the DagBag from /opt/airflow/dags/ingestion_dag.py
[2024-06-27T23:29:05.241+0000] {logging_mixin.py:188} INFO - [2024-06-27T23:29:05.239+0000] {dagbag.py:355} ERROR - Failed to import: /opt/airflow/dags/ingestion_dag.py
Traceback (most recent call last):
  File "/home/airflow/.local/lib/python3.11/site-packages/airflow/models/dagbag.py", line 351, in parse
    loader.exec_module(new_module)
  File "<frozen importlib._bootstrap_external>", line 940, in exec_module
  File "<frozen importlib._bootstrap>", line 241, in _call_with_frames_removed
  File "/opt/airflow/dags/ingestion_dag.py", line 20, in <module>
    SERVICE_ACCOUNT_CREDENTIALS = service_account.Credentials.from_service_account_file(
                                  ^^^^^^^^^^^^^^^^^^^^^^^^^^^^^^^^^^^^^^^^^^^^^^^^^^^^^^
  File "/home/airflow/.local/lib/python3.11/site-packages/google/oauth2/service_account.py", line 258, in from_service_account_file
    info, signer = _service_account_info.from_filename(
                   ^^^^^^^^^^^^^^^^^^^^^^^^^^^^^^^^^^^^
  File "/home/airflow/.local/lib/python3.11/site-packages/google/auth/_service_account_info.py", line 78, in from_filename
    with io.open(filename, "r", encoding="utf-8") as json_file:
         ^^^^^^^^^^^^^^^^^^^^^^^^^^^^^^^^^^^^^^^^
FileNotFoundError: [Errno 2] No such file or directory: '/.gc/my-creds.json'
[2024-06-27T23:29:05.243+0000] {processor.py:842} WARNING - No viable dags retrieved from /opt/airflow/dags/ingestion_dag.py
[2024-06-27T23:29:05.298+0000] {processor.py:183} INFO - Processing /opt/airflow/dags/ingestion_dag.py took 0.087 seconds
[2024-06-27T23:29:35.590+0000] {processor.py:161} INFO - Started process (PID=6210) to work on /opt/airflow/dags/ingestion_dag.py
[2024-06-27T23:29:35.593+0000] {processor.py:830} INFO - Processing file /opt/airflow/dags/ingestion_dag.py for tasks to queue
[2024-06-27T23:29:35.599+0000] {logging_mixin.py:188} INFO - [2024-06-27T23:29:35.598+0000] {dagbag.py:545} INFO - Filling up the DagBag from /opt/airflow/dags/ingestion_dag.py
[2024-06-27T23:29:35.607+0000] {logging_mixin.py:188} INFO - [2024-06-27T23:29:35.604+0000] {dagbag.py:355} ERROR - Failed to import: /opt/airflow/dags/ingestion_dag.py
Traceback (most recent call last):
  File "/home/airflow/.local/lib/python3.11/site-packages/airflow/models/dagbag.py", line 351, in parse
    loader.exec_module(new_module)
  File "<frozen importlib._bootstrap_external>", line 940, in exec_module
  File "<frozen importlib._bootstrap>", line 241, in _call_with_frames_removed
  File "/opt/airflow/dags/ingestion_dag.py", line 20, in <module>
    SERVICE_ACCOUNT_CREDENTIALS = service_account.Credentials.from_service_account_file(
                                  ^^^^^^^^^^^^^^^^^^^^^^^^^^^^^^^^^^^^^^^^^^^^^^^^^^^^^^
  File "/home/airflow/.local/lib/python3.11/site-packages/google/oauth2/service_account.py", line 258, in from_service_account_file
    info, signer = _service_account_info.from_filename(
                   ^^^^^^^^^^^^^^^^^^^^^^^^^^^^^^^^^^^^
  File "/home/airflow/.local/lib/python3.11/site-packages/google/auth/_service_account_info.py", line 78, in from_filename
    with io.open(filename, "r", encoding="utf-8") as json_file:
         ^^^^^^^^^^^^^^^^^^^^^^^^^^^^^^^^^^^^^^^^
FileNotFoundError: [Errno 2] No such file or directory: '/.gc/my-creds.json'
[2024-06-27T23:29:35.608+0000] {processor.py:842} WARNING - No viable dags retrieved from /opt/airflow/dags/ingestion_dag.py
[2024-06-27T23:29:35.655+0000] {processor.py:183} INFO - Processing /opt/airflow/dags/ingestion_dag.py took 0.080 seconds
[2024-06-27T23:30:06.172+0000] {processor.py:161} INFO - Started process (PID=6278) to work on /opt/airflow/dags/ingestion_dag.py
[2024-06-27T23:30:06.176+0000] {processor.py:830} INFO - Processing file /opt/airflow/dags/ingestion_dag.py for tasks to queue
[2024-06-27T23:30:06.182+0000] {logging_mixin.py:188} INFO - [2024-06-27T23:30:06.181+0000] {dagbag.py:545} INFO - Filling up the DagBag from /opt/airflow/dags/ingestion_dag.py
[2024-06-27T23:30:06.196+0000] {logging_mixin.py:188} INFO - [2024-06-27T23:30:06.192+0000] {dagbag.py:355} ERROR - Failed to import: /opt/airflow/dags/ingestion_dag.py
Traceback (most recent call last):
  File "/home/airflow/.local/lib/python3.11/site-packages/airflow/models/dagbag.py", line 351, in parse
    loader.exec_module(new_module)
  File "<frozen importlib._bootstrap_external>", line 940, in exec_module
  File "<frozen importlib._bootstrap>", line 241, in _call_with_frames_removed
  File "/opt/airflow/dags/ingestion_dag.py", line 20, in <module>
    SERVICE_ACCOUNT_CREDENTIALS = service_account.Credentials.from_service_account_file(
                                  ^^^^^^^^^^^^^^^^^^^^^^^^^^^^^^^^^^^^^^^^^^^^^^^^^^^^^^
  File "/home/airflow/.local/lib/python3.11/site-packages/google/oauth2/service_account.py", line 258, in from_service_account_file
    info, signer = _service_account_info.from_filename(
                   ^^^^^^^^^^^^^^^^^^^^^^^^^^^^^^^^^^^^
  File "/home/airflow/.local/lib/python3.11/site-packages/google/auth/_service_account_info.py", line 78, in from_filename
    with io.open(filename, "r", encoding="utf-8") as json_file:
         ^^^^^^^^^^^^^^^^^^^^^^^^^^^^^^^^^^^^^^^^
FileNotFoundError: [Errno 2] No such file or directory: '/.gc/my-creds.json'
[2024-06-27T23:30:06.199+0000] {processor.py:842} WARNING - No viable dags retrieved from /opt/airflow/dags/ingestion_dag.py
[2024-06-27T23:30:06.246+0000] {processor.py:183} INFO - Processing /opt/airflow/dags/ingestion_dag.py took 0.093 seconds
[2024-06-27T23:30:36.694+0000] {processor.py:161} INFO - Started process (PID=6340) to work on /opt/airflow/dags/ingestion_dag.py
[2024-06-27T23:30:36.698+0000] {processor.py:830} INFO - Processing file /opt/airflow/dags/ingestion_dag.py for tasks to queue
[2024-06-27T23:30:36.706+0000] {logging_mixin.py:188} INFO - [2024-06-27T23:30:36.705+0000] {dagbag.py:545} INFO - Filling up the DagBag from /opt/airflow/dags/ingestion_dag.py
[2024-06-27T23:30:36.715+0000] {logging_mixin.py:188} INFO - [2024-06-27T23:30:36.712+0000] {dagbag.py:355} ERROR - Failed to import: /opt/airflow/dags/ingestion_dag.py
Traceback (most recent call last):
  File "/home/airflow/.local/lib/python3.11/site-packages/airflow/models/dagbag.py", line 351, in parse
    loader.exec_module(new_module)
  File "<frozen importlib._bootstrap_external>", line 940, in exec_module
  File "<frozen importlib._bootstrap>", line 241, in _call_with_frames_removed
  File "/opt/airflow/dags/ingestion_dag.py", line 20, in <module>
    SERVICE_ACCOUNT_CREDENTIALS = service_account.Credentials.from_service_account_file(
                                  ^^^^^^^^^^^^^^^^^^^^^^^^^^^^^^^^^^^^^^^^^^^^^^^^^^^^^^
  File "/home/airflow/.local/lib/python3.11/site-packages/google/oauth2/service_account.py", line 258, in from_service_account_file
    info, signer = _service_account_info.from_filename(
                   ^^^^^^^^^^^^^^^^^^^^^^^^^^^^^^^^^^^^
  File "/home/airflow/.local/lib/python3.11/site-packages/google/auth/_service_account_info.py", line 78, in from_filename
    with io.open(filename, "r", encoding="utf-8") as json_file:
         ^^^^^^^^^^^^^^^^^^^^^^^^^^^^^^^^^^^^^^^^
FileNotFoundError: [Errno 2] No such file or directory: '/.gc/my-creds.json'
[2024-06-27T23:30:36.716+0000] {processor.py:842} WARNING - No viable dags retrieved from /opt/airflow/dags/ingestion_dag.py
[2024-06-27T23:30:36.757+0000] {processor.py:183} INFO - Processing /opt/airflow/dags/ingestion_dag.py took 0.078 seconds
[2024-06-27T23:31:07.184+0000] {processor.py:161} INFO - Started process (PID=6402) to work on /opt/airflow/dags/ingestion_dag.py
[2024-06-27T23:31:07.188+0000] {processor.py:830} INFO - Processing file /opt/airflow/dags/ingestion_dag.py for tasks to queue
[2024-06-27T23:31:07.194+0000] {logging_mixin.py:188} INFO - [2024-06-27T23:31:07.193+0000] {dagbag.py:545} INFO - Filling up the DagBag from /opt/airflow/dags/ingestion_dag.py
[2024-06-27T23:31:07.202+0000] {logging_mixin.py:188} INFO - [2024-06-27T23:31:07.199+0000] {dagbag.py:355} ERROR - Failed to import: /opt/airflow/dags/ingestion_dag.py
Traceback (most recent call last):
  File "/home/airflow/.local/lib/python3.11/site-packages/airflow/models/dagbag.py", line 351, in parse
    loader.exec_module(new_module)
  File "<frozen importlib._bootstrap_external>", line 940, in exec_module
  File "<frozen importlib._bootstrap>", line 241, in _call_with_frames_removed
  File "/opt/airflow/dags/ingestion_dag.py", line 20, in <module>
    SERVICE_ACCOUNT_CREDENTIALS = service_account.Credentials.from_service_account_file(
                                  ^^^^^^^^^^^^^^^^^^^^^^^^^^^^^^^^^^^^^^^^^^^^^^^^^^^^^^
  File "/home/airflow/.local/lib/python3.11/site-packages/google/oauth2/service_account.py", line 258, in from_service_account_file
    info, signer = _service_account_info.from_filename(
                   ^^^^^^^^^^^^^^^^^^^^^^^^^^^^^^^^^^^^
  File "/home/airflow/.local/lib/python3.11/site-packages/google/auth/_service_account_info.py", line 78, in from_filename
    with io.open(filename, "r", encoding="utf-8") as json_file:
         ^^^^^^^^^^^^^^^^^^^^^^^^^^^^^^^^^^^^^^^^
FileNotFoundError: [Errno 2] No such file or directory: '/.gc/my-creds.json'
[2024-06-27T23:31:07.203+0000] {processor.py:842} WARNING - No viable dags retrieved from /opt/airflow/dags/ingestion_dag.py
[2024-06-27T23:31:07.245+0000] {processor.py:183} INFO - Processing /opt/airflow/dags/ingestion_dag.py took 0.076 seconds
[2024-06-27T23:31:37.919+0000] {processor.py:161} INFO - Started process (PID=6463) to work on /opt/airflow/dags/ingestion_dag.py
[2024-06-27T23:31:37.923+0000] {processor.py:830} INFO - Processing file /opt/airflow/dags/ingestion_dag.py for tasks to queue
[2024-06-27T23:31:37.929+0000] {logging_mixin.py:188} INFO - [2024-06-27T23:31:37.929+0000] {dagbag.py:545} INFO - Filling up the DagBag from /opt/airflow/dags/ingestion_dag.py
[2024-06-27T23:31:37.937+0000] {logging_mixin.py:188} INFO - [2024-06-27T23:31:37.934+0000] {dagbag.py:355} ERROR - Failed to import: /opt/airflow/dags/ingestion_dag.py
Traceback (most recent call last):
  File "/home/airflow/.local/lib/python3.11/site-packages/airflow/models/dagbag.py", line 351, in parse
    loader.exec_module(new_module)
  File "<frozen importlib._bootstrap_external>", line 940, in exec_module
  File "<frozen importlib._bootstrap>", line 241, in _call_with_frames_removed
  File "/opt/airflow/dags/ingestion_dag.py", line 20, in <module>
    SERVICE_ACCOUNT_CREDENTIALS = service_account.Credentials.from_service_account_file(
                                  ^^^^^^^^^^^^^^^^^^^^^^^^^^^^^^^^^^^^^^^^^^^^^^^^^^^^^^
  File "/home/airflow/.local/lib/python3.11/site-packages/google/oauth2/service_account.py", line 258, in from_service_account_file
    info, signer = _service_account_info.from_filename(
                   ^^^^^^^^^^^^^^^^^^^^^^^^^^^^^^^^^^^^
  File "/home/airflow/.local/lib/python3.11/site-packages/google/auth/_service_account_info.py", line 78, in from_filename
    with io.open(filename, "r", encoding="utf-8") as json_file:
         ^^^^^^^^^^^^^^^^^^^^^^^^^^^^^^^^^^^^^^^^
FileNotFoundError: [Errno 2] No such file or directory: '/.gc/my-creds.json'
[2024-06-27T23:31:37.938+0000] {processor.py:842} WARNING - No viable dags retrieved from /opt/airflow/dags/ingestion_dag.py
[2024-06-27T23:31:37.977+0000] {processor.py:183} INFO - Processing /opt/airflow/dags/ingestion_dag.py took 0.078 seconds
[2024-06-27T23:32:08.381+0000] {processor.py:161} INFO - Started process (PID=6526) to work on /opt/airflow/dags/ingestion_dag.py
[2024-06-27T23:32:08.385+0000] {processor.py:830} INFO - Processing file /opt/airflow/dags/ingestion_dag.py for tasks to queue
[2024-06-27T23:32:08.391+0000] {logging_mixin.py:188} INFO - [2024-06-27T23:32:08.391+0000] {dagbag.py:545} INFO - Filling up the DagBag from /opt/airflow/dags/ingestion_dag.py
[2024-06-27T23:32:08.399+0000] {logging_mixin.py:188} INFO - [2024-06-27T23:32:08.396+0000] {dagbag.py:355} ERROR - Failed to import: /opt/airflow/dags/ingestion_dag.py
Traceback (most recent call last):
  File "/home/airflow/.local/lib/python3.11/site-packages/airflow/models/dagbag.py", line 351, in parse
    loader.exec_module(new_module)
  File "<frozen importlib._bootstrap_external>", line 940, in exec_module
  File "<frozen importlib._bootstrap>", line 241, in _call_with_frames_removed
  File "/opt/airflow/dags/ingestion_dag.py", line 20, in <module>
    SERVICE_ACCOUNT_CREDENTIALS = service_account.Credentials.from_service_account_file(
                                  ^^^^^^^^^^^^^^^^^^^^^^^^^^^^^^^^^^^^^^^^^^^^^^^^^^^^^^
  File "/home/airflow/.local/lib/python3.11/site-packages/google/oauth2/service_account.py", line 258, in from_service_account_file
    info, signer = _service_account_info.from_filename(
                   ^^^^^^^^^^^^^^^^^^^^^^^^^^^^^^^^^^^^
  File "/home/airflow/.local/lib/python3.11/site-packages/google/auth/_service_account_info.py", line 78, in from_filename
    with io.open(filename, "r", encoding="utf-8") as json_file:
         ^^^^^^^^^^^^^^^^^^^^^^^^^^^^^^^^^^^^^^^^
FileNotFoundError: [Errno 2] No such file or directory: '/.gc/my-creds.json'
[2024-06-27T23:32:08.400+0000] {processor.py:842} WARNING - No viable dags retrieved from /opt/airflow/dags/ingestion_dag.py
[2024-06-27T23:32:08.440+0000] {processor.py:183} INFO - Processing /opt/airflow/dags/ingestion_dag.py took 0.077 seconds
[2024-06-27T23:32:38.969+0000] {processor.py:161} INFO - Started process (PID=6588) to work on /opt/airflow/dags/ingestion_dag.py
[2024-06-27T23:32:38.970+0000] {processor.py:830} INFO - Processing file /opt/airflow/dags/ingestion_dag.py for tasks to queue
[2024-06-27T23:32:38.977+0000] {logging_mixin.py:188} INFO - [2024-06-27T23:32:38.976+0000] {dagbag.py:545} INFO - Filling up the DagBag from /opt/airflow/dags/ingestion_dag.py
[2024-06-27T23:32:38.984+0000] {logging_mixin.py:188} INFO - [2024-06-27T23:32:38.981+0000] {dagbag.py:355} ERROR - Failed to import: /opt/airflow/dags/ingestion_dag.py
Traceback (most recent call last):
  File "/home/airflow/.local/lib/python3.11/site-packages/airflow/models/dagbag.py", line 351, in parse
    loader.exec_module(new_module)
  File "<frozen importlib._bootstrap_external>", line 940, in exec_module
  File "<frozen importlib._bootstrap>", line 241, in _call_with_frames_removed
  File "/opt/airflow/dags/ingestion_dag.py", line 20, in <module>
    SERVICE_ACCOUNT_CREDENTIALS = service_account.Credentials.from_service_account_file(
                                  ^^^^^^^^^^^^^^^^^^^^^^^^^^^^^^^^^^^^^^^^^^^^^^^^^^^^^^
  File "/home/airflow/.local/lib/python3.11/site-packages/google/oauth2/service_account.py", line 258, in from_service_account_file
    info, signer = _service_account_info.from_filename(
                   ^^^^^^^^^^^^^^^^^^^^^^^^^^^^^^^^^^^^
  File "/home/airflow/.local/lib/python3.11/site-packages/google/auth/_service_account_info.py", line 78, in from_filename
    with io.open(filename, "r", encoding="utf-8") as json_file:
         ^^^^^^^^^^^^^^^^^^^^^^^^^^^^^^^^^^^^^^^^
FileNotFoundError: [Errno 2] No such file or directory: '/.gc/my-creds.json'
[2024-06-27T23:32:38.985+0000] {processor.py:842} WARNING - No viable dags retrieved from /opt/airflow/dags/ingestion_dag.py
[2024-06-27T23:32:39.026+0000] {processor.py:183} INFO - Processing /opt/airflow/dags/ingestion_dag.py took 0.072 seconds
[2024-06-27T23:33:09.364+0000] {processor.py:161} INFO - Started process (PID=6649) to work on /opt/airflow/dags/ingestion_dag.py
[2024-06-27T23:33:09.367+0000] {processor.py:830} INFO - Processing file /opt/airflow/dags/ingestion_dag.py for tasks to queue
[2024-06-27T23:33:09.374+0000] {logging_mixin.py:188} INFO - [2024-06-27T23:33:09.373+0000] {dagbag.py:545} INFO - Filling up the DagBag from /opt/airflow/dags/ingestion_dag.py
[2024-06-27T23:33:09.381+0000] {logging_mixin.py:188} INFO - [2024-06-27T23:33:09.378+0000] {dagbag.py:355} ERROR - Failed to import: /opt/airflow/dags/ingestion_dag.py
Traceback (most recent call last):
  File "/home/airflow/.local/lib/python3.11/site-packages/airflow/models/dagbag.py", line 351, in parse
    loader.exec_module(new_module)
  File "<frozen importlib._bootstrap_external>", line 940, in exec_module
  File "<frozen importlib._bootstrap>", line 241, in _call_with_frames_removed
  File "/opt/airflow/dags/ingestion_dag.py", line 20, in <module>
    SERVICE_ACCOUNT_CREDENTIALS = service_account.Credentials.from_service_account_file(
                                  ^^^^^^^^^^^^^^^^^^^^^^^^^^^^^^^^^^^^^^^^^^^^^^^^^^^^^^
  File "/home/airflow/.local/lib/python3.11/site-packages/google/oauth2/service_account.py", line 258, in from_service_account_file
    info, signer = _service_account_info.from_filename(
                   ^^^^^^^^^^^^^^^^^^^^^^^^^^^^^^^^^^^^
  File "/home/airflow/.local/lib/python3.11/site-packages/google/auth/_service_account_info.py", line 78, in from_filename
    with io.open(filename, "r", encoding="utf-8") as json_file:
         ^^^^^^^^^^^^^^^^^^^^^^^^^^^^^^^^^^^^^^^^
FileNotFoundError: [Errno 2] No such file or directory: '/.gc/my-creds.json'
[2024-06-27T23:33:09.382+0000] {processor.py:842} WARNING - No viable dags retrieved from /opt/airflow/dags/ingestion_dag.py
[2024-06-27T23:33:09.426+0000] {processor.py:183} INFO - Processing /opt/airflow/dags/ingestion_dag.py took 0.078 seconds
[2024-06-27T23:33:39.734+0000] {processor.py:161} INFO - Started process (PID=6711) to work on /opt/airflow/dags/ingestion_dag.py
[2024-06-27T23:33:39.736+0000] {processor.py:830} INFO - Processing file /opt/airflow/dags/ingestion_dag.py for tasks to queue
[2024-06-27T23:33:39.741+0000] {logging_mixin.py:188} INFO - [2024-06-27T23:33:39.740+0000] {dagbag.py:545} INFO - Filling up the DagBag from /opt/airflow/dags/ingestion_dag.py
[2024-06-27T23:33:39.747+0000] {logging_mixin.py:188} INFO - [2024-06-27T23:33:39.745+0000] {dagbag.py:355} ERROR - Failed to import: /opt/airflow/dags/ingestion_dag.py
Traceback (most recent call last):
  File "/home/airflow/.local/lib/python3.11/site-packages/airflow/models/dagbag.py", line 351, in parse
    loader.exec_module(new_module)
  File "<frozen importlib._bootstrap_external>", line 940, in exec_module
  File "<frozen importlib._bootstrap>", line 241, in _call_with_frames_removed
  File "/opt/airflow/dags/ingestion_dag.py", line 20, in <module>
    SERVICE_ACCOUNT_CREDENTIALS = service_account.Credentials.from_service_account_file(
                                  ^^^^^^^^^^^^^^^^^^^^^^^^^^^^^^^^^^^^^^^^^^^^^^^^^^^^^^
  File "/home/airflow/.local/lib/python3.11/site-packages/google/oauth2/service_account.py", line 258, in from_service_account_file
    info, signer = _service_account_info.from_filename(
                   ^^^^^^^^^^^^^^^^^^^^^^^^^^^^^^^^^^^^
  File "/home/airflow/.local/lib/python3.11/site-packages/google/auth/_service_account_info.py", line 78, in from_filename
    with io.open(filename, "r", encoding="utf-8") as json_file:
         ^^^^^^^^^^^^^^^^^^^^^^^^^^^^^^^^^^^^^^^^
FileNotFoundError: [Errno 2] No such file or directory: '/.gc/my-creds.json'
[2024-06-27T23:33:39.749+0000] {processor.py:842} WARNING - No viable dags retrieved from /opt/airflow/dags/ingestion_dag.py
[2024-06-27T23:33:39.787+0000] {processor.py:183} INFO - Processing /opt/airflow/dags/ingestion_dag.py took 0.071 seconds
[2024-06-27T23:34:10.104+0000] {processor.py:161} INFO - Started process (PID=6773) to work on /opt/airflow/dags/ingestion_dag.py
[2024-06-27T23:34:10.107+0000] {processor.py:830} INFO - Processing file /opt/airflow/dags/ingestion_dag.py for tasks to queue
[2024-06-27T23:34:10.112+0000] {logging_mixin.py:188} INFO - [2024-06-27T23:34:10.111+0000] {dagbag.py:545} INFO - Filling up the DagBag from /opt/airflow/dags/ingestion_dag.py
[2024-06-27T23:34:10.119+0000] {logging_mixin.py:188} INFO - [2024-06-27T23:34:10.116+0000] {dagbag.py:355} ERROR - Failed to import: /opt/airflow/dags/ingestion_dag.py
Traceback (most recent call last):
  File "/home/airflow/.local/lib/python3.11/site-packages/airflow/models/dagbag.py", line 351, in parse
    loader.exec_module(new_module)
  File "<frozen importlib._bootstrap_external>", line 940, in exec_module
  File "<frozen importlib._bootstrap>", line 241, in _call_with_frames_removed
  File "/opt/airflow/dags/ingestion_dag.py", line 20, in <module>
    SERVICE_ACCOUNT_CREDENTIALS = service_account.Credentials.from_service_account_file(
                                  ^^^^^^^^^^^^^^^^^^^^^^^^^^^^^^^^^^^^^^^^^^^^^^^^^^^^^^
  File "/home/airflow/.local/lib/python3.11/site-packages/google/oauth2/service_account.py", line 258, in from_service_account_file
    info, signer = _service_account_info.from_filename(
                   ^^^^^^^^^^^^^^^^^^^^^^^^^^^^^^^^^^^^
  File "/home/airflow/.local/lib/python3.11/site-packages/google/auth/_service_account_info.py", line 78, in from_filename
    with io.open(filename, "r", encoding="utf-8") as json_file:
         ^^^^^^^^^^^^^^^^^^^^^^^^^^^^^^^^^^^^^^^^
FileNotFoundError: [Errno 2] No such file or directory: '/.gc/my-creds.json'
[2024-06-27T23:34:10.120+0000] {processor.py:842} WARNING - No viable dags retrieved from /opt/airflow/dags/ingestion_dag.py
[2024-06-27T23:34:10.159+0000] {processor.py:183} INFO - Processing /opt/airflow/dags/ingestion_dag.py took 0.069 seconds
[2024-06-27T23:34:40.419+0000] {processor.py:161} INFO - Started process (PID=6835) to work on /opt/airflow/dags/ingestion_dag.py
[2024-06-27T23:34:40.422+0000] {processor.py:830} INFO - Processing file /opt/airflow/dags/ingestion_dag.py for tasks to queue
[2024-06-27T23:34:40.426+0000] {logging_mixin.py:188} INFO - [2024-06-27T23:34:40.425+0000] {dagbag.py:545} INFO - Filling up the DagBag from /opt/airflow/dags/ingestion_dag.py
[2024-06-27T23:34:40.433+0000] {logging_mixin.py:188} INFO - [2024-06-27T23:34:40.430+0000] {dagbag.py:355} ERROR - Failed to import: /opt/airflow/dags/ingestion_dag.py
Traceback (most recent call last):
  File "/home/airflow/.local/lib/python3.11/site-packages/airflow/models/dagbag.py", line 351, in parse
    loader.exec_module(new_module)
  File "<frozen importlib._bootstrap_external>", line 940, in exec_module
  File "<frozen importlib._bootstrap>", line 241, in _call_with_frames_removed
  File "/opt/airflow/dags/ingestion_dag.py", line 20, in <module>
    SERVICE_ACCOUNT_CREDENTIALS = service_account.Credentials.from_service_account_file(
                                  ^^^^^^^^^^^^^^^^^^^^^^^^^^^^^^^^^^^^^^^^^^^^^^^^^^^^^^
  File "/home/airflow/.local/lib/python3.11/site-packages/google/oauth2/service_account.py", line 258, in from_service_account_file
    info, signer = _service_account_info.from_filename(
                   ^^^^^^^^^^^^^^^^^^^^^^^^^^^^^^^^^^^^
  File "/home/airflow/.local/lib/python3.11/site-packages/google/auth/_service_account_info.py", line 78, in from_filename
    with io.open(filename, "r", encoding="utf-8") as json_file:
         ^^^^^^^^^^^^^^^^^^^^^^^^^^^^^^^^^^^^^^^^
FileNotFoundError: [Errno 2] No such file or directory: '/.gc/my-creds.json'
[2024-06-27T23:34:40.434+0000] {processor.py:842} WARNING - No viable dags retrieved from /opt/airflow/dags/ingestion_dag.py
[2024-06-27T23:34:40.474+0000] {processor.py:183} INFO - Processing /opt/airflow/dags/ingestion_dag.py took 0.069 seconds
[2024-06-27T23:35:11.088+0000] {processor.py:161} INFO - Started process (PID=6897) to work on /opt/airflow/dags/ingestion_dag.py
[2024-06-27T23:35:11.093+0000] {processor.py:830} INFO - Processing file /opt/airflow/dags/ingestion_dag.py for tasks to queue
[2024-06-27T23:35:11.100+0000] {logging_mixin.py:188} INFO - [2024-06-27T23:35:11.099+0000] {dagbag.py:545} INFO - Filling up the DagBag from /opt/airflow/dags/ingestion_dag.py
[2024-06-27T23:35:11.110+0000] {logging_mixin.py:188} INFO - [2024-06-27T23:35:11.107+0000] {dagbag.py:355} ERROR - Failed to import: /opt/airflow/dags/ingestion_dag.py
Traceback (most recent call last):
  File "/home/airflow/.local/lib/python3.11/site-packages/airflow/models/dagbag.py", line 351, in parse
    loader.exec_module(new_module)
  File "<frozen importlib._bootstrap_external>", line 940, in exec_module
  File "<frozen importlib._bootstrap>", line 241, in _call_with_frames_removed
  File "/opt/airflow/dags/ingestion_dag.py", line 20, in <module>
    SERVICE_ACCOUNT_CREDENTIALS = service_account.Credentials.from_service_account_file(
                                  ^^^^^^^^^^^^^^^^^^^^^^^^^^^^^^^^^^^^^^^^^^^^^^^^^^^^^^
  File "/home/airflow/.local/lib/python3.11/site-packages/google/oauth2/service_account.py", line 258, in from_service_account_file
    info, signer = _service_account_info.from_filename(
                   ^^^^^^^^^^^^^^^^^^^^^^^^^^^^^^^^^^^^
  File "/home/airflow/.local/lib/python3.11/site-packages/google/auth/_service_account_info.py", line 78, in from_filename
    with io.open(filename, "r", encoding="utf-8") as json_file:
         ^^^^^^^^^^^^^^^^^^^^^^^^^^^^^^^^^^^^^^^^
FileNotFoundError: [Errno 2] No such file or directory: '/.gc/my-creds.json'
[2024-06-27T23:35:11.111+0000] {processor.py:842} WARNING - No viable dags retrieved from /opt/airflow/dags/ingestion_dag.py
[2024-06-27T23:35:11.155+0000] {processor.py:183} INFO - Processing /opt/airflow/dags/ingestion_dag.py took 0.083 seconds
[2024-06-27T23:35:41.720+0000] {processor.py:161} INFO - Started process (PID=6959) to work on /opt/airflow/dags/ingestion_dag.py
[2024-06-27T23:35:41.723+0000] {processor.py:830} INFO - Processing file /opt/airflow/dags/ingestion_dag.py for tasks to queue
[2024-06-27T23:35:41.729+0000] {logging_mixin.py:188} INFO - [2024-06-27T23:35:41.728+0000] {dagbag.py:545} INFO - Filling up the DagBag from /opt/airflow/dags/ingestion_dag.py
[2024-06-27T23:35:41.737+0000] {logging_mixin.py:188} INFO - [2024-06-27T23:35:41.735+0000] {dagbag.py:355} ERROR - Failed to import: /opt/airflow/dags/ingestion_dag.py
Traceback (most recent call last):
  File "/home/airflow/.local/lib/python3.11/site-packages/airflow/models/dagbag.py", line 351, in parse
    loader.exec_module(new_module)
  File "<frozen importlib._bootstrap_external>", line 940, in exec_module
  File "<frozen importlib._bootstrap>", line 241, in _call_with_frames_removed
  File "/opt/airflow/dags/ingestion_dag.py", line 20, in <module>
    SERVICE_ACCOUNT_CREDENTIALS = service_account.Credentials.from_service_account_file(
                                  ^^^^^^^^^^^^^^^^^^^^^^^^^^^^^^^^^^^^^^^^^^^^^^^^^^^^^^
  File "/home/airflow/.local/lib/python3.11/site-packages/google/oauth2/service_account.py", line 258, in from_service_account_file
    info, signer = _service_account_info.from_filename(
                   ^^^^^^^^^^^^^^^^^^^^^^^^^^^^^^^^^^^^
  File "/home/airflow/.local/lib/python3.11/site-packages/google/auth/_service_account_info.py", line 78, in from_filename
    with io.open(filename, "r", encoding="utf-8") as json_file:
         ^^^^^^^^^^^^^^^^^^^^^^^^^^^^^^^^^^^^^^^^
FileNotFoundError: [Errno 2] No such file or directory: '/.gc/my-creds.json'
[2024-06-27T23:35:41.739+0000] {processor.py:842} WARNING - No viable dags retrieved from /opt/airflow/dags/ingestion_dag.py
[2024-06-27T23:35:41.782+0000] {processor.py:183} INFO - Processing /opt/airflow/dags/ingestion_dag.py took 0.078 seconds
[2024-06-27T23:36:12.167+0000] {processor.py:161} INFO - Started process (PID=7021) to work on /opt/airflow/dags/ingestion_dag.py
[2024-06-27T23:36:12.171+0000] {processor.py:830} INFO - Processing file /opt/airflow/dags/ingestion_dag.py for tasks to queue
[2024-06-27T23:36:12.176+0000] {logging_mixin.py:188} INFO - [2024-06-27T23:36:12.175+0000] {dagbag.py:545} INFO - Filling up the DagBag from /opt/airflow/dags/ingestion_dag.py
[2024-06-27T23:36:12.183+0000] {logging_mixin.py:188} INFO - [2024-06-27T23:36:12.180+0000] {dagbag.py:355} ERROR - Failed to import: /opt/airflow/dags/ingestion_dag.py
Traceback (most recent call last):
  File "/home/airflow/.local/lib/python3.11/site-packages/airflow/models/dagbag.py", line 351, in parse
    loader.exec_module(new_module)
  File "<frozen importlib._bootstrap_external>", line 940, in exec_module
  File "<frozen importlib._bootstrap>", line 241, in _call_with_frames_removed
  File "/opt/airflow/dags/ingestion_dag.py", line 20, in <module>
    SERVICE_ACCOUNT_CREDENTIALS = service_account.Credentials.from_service_account_file(
                                  ^^^^^^^^^^^^^^^^^^^^^^^^^^^^^^^^^^^^^^^^^^^^^^^^^^^^^^
  File "/home/airflow/.local/lib/python3.11/site-packages/google/oauth2/service_account.py", line 258, in from_service_account_file
    info, signer = _service_account_info.from_filename(
                   ^^^^^^^^^^^^^^^^^^^^^^^^^^^^^^^^^^^^
  File "/home/airflow/.local/lib/python3.11/site-packages/google/auth/_service_account_info.py", line 78, in from_filename
    with io.open(filename, "r", encoding="utf-8") as json_file:
         ^^^^^^^^^^^^^^^^^^^^^^^^^^^^^^^^^^^^^^^^
FileNotFoundError: [Errno 2] No such file or directory: '/.gc/my-creds.json'
[2024-06-27T23:36:12.185+0000] {processor.py:842} WARNING - No viable dags retrieved from /opt/airflow/dags/ingestion_dag.py
[2024-06-27T23:36:12.224+0000] {processor.py:183} INFO - Processing /opt/airflow/dags/ingestion_dag.py took 0.075 seconds
[2024-06-27T23:36:42.694+0000] {processor.py:161} INFO - Started process (PID=7083) to work on /opt/airflow/dags/ingestion_dag.py
[2024-06-27T23:36:42.696+0000] {processor.py:830} INFO - Processing file /opt/airflow/dags/ingestion_dag.py for tasks to queue
[2024-06-27T23:36:42.702+0000] {logging_mixin.py:188} INFO - [2024-06-27T23:36:42.701+0000] {dagbag.py:545} INFO - Filling up the DagBag from /opt/airflow/dags/ingestion_dag.py
[2024-06-27T23:36:42.712+0000] {logging_mixin.py:188} INFO - [2024-06-27T23:36:42.709+0000] {dagbag.py:355} ERROR - Failed to import: /opt/airflow/dags/ingestion_dag.py
Traceback (most recent call last):
  File "/home/airflow/.local/lib/python3.11/site-packages/airflow/models/dagbag.py", line 351, in parse
    loader.exec_module(new_module)
  File "<frozen importlib._bootstrap_external>", line 940, in exec_module
  File "<frozen importlib._bootstrap>", line 241, in _call_with_frames_removed
  File "/opt/airflow/dags/ingestion_dag.py", line 20, in <module>
    SERVICE_ACCOUNT_CREDENTIALS = service_account.Credentials.from_service_account_file(
                                  ^^^^^^^^^^^^^^^^^^^^^^^^^^^^^^^^^^^^^^^^^^^^^^^^^^^^^^
  File "/home/airflow/.local/lib/python3.11/site-packages/google/oauth2/service_account.py", line 258, in from_service_account_file
    info, signer = _service_account_info.from_filename(
                   ^^^^^^^^^^^^^^^^^^^^^^^^^^^^^^^^^^^^
  File "/home/airflow/.local/lib/python3.11/site-packages/google/auth/_service_account_info.py", line 78, in from_filename
    with io.open(filename, "r", encoding="utf-8") as json_file:
         ^^^^^^^^^^^^^^^^^^^^^^^^^^^^^^^^^^^^^^^^
FileNotFoundError: [Errno 2] No such file or directory: '/.gc/my-creds.json'
[2024-06-27T23:36:42.714+0000] {processor.py:842} WARNING - No viable dags retrieved from /opt/airflow/dags/ingestion_dag.py
[2024-06-27T23:36:42.754+0000] {processor.py:183} INFO - Processing /opt/airflow/dags/ingestion_dag.py took 0.076 seconds
[2024-06-27T23:37:13.096+0000] {processor.py:161} INFO - Started process (PID=7145) to work on /opt/airflow/dags/ingestion_dag.py
[2024-06-27T23:37:13.101+0000] {processor.py:830} INFO - Processing file /opt/airflow/dags/ingestion_dag.py for tasks to queue
[2024-06-27T23:37:13.107+0000] {logging_mixin.py:188} INFO - [2024-06-27T23:37:13.106+0000] {dagbag.py:545} INFO - Filling up the DagBag from /opt/airflow/dags/ingestion_dag.py
[2024-06-27T23:37:13.118+0000] {logging_mixin.py:188} INFO - [2024-06-27T23:37:13.114+0000] {dagbag.py:355} ERROR - Failed to import: /opt/airflow/dags/ingestion_dag.py
Traceback (most recent call last):
  File "/home/airflow/.local/lib/python3.11/site-packages/airflow/models/dagbag.py", line 351, in parse
    loader.exec_module(new_module)
  File "<frozen importlib._bootstrap_external>", line 940, in exec_module
  File "<frozen importlib._bootstrap>", line 241, in _call_with_frames_removed
  File "/opt/airflow/dags/ingestion_dag.py", line 20, in <module>
    SERVICE_ACCOUNT_CREDENTIALS = service_account.Credentials.from_service_account_file(
                                  ^^^^^^^^^^^^^^^^^^^^^^^^^^^^^^^^^^^^^^^^^^^^^^^^^^^^^^
  File "/home/airflow/.local/lib/python3.11/site-packages/google/oauth2/service_account.py", line 258, in from_service_account_file
    info, signer = _service_account_info.from_filename(
                   ^^^^^^^^^^^^^^^^^^^^^^^^^^^^^^^^^^^^
  File "/home/airflow/.local/lib/python3.11/site-packages/google/auth/_service_account_info.py", line 78, in from_filename
    with io.open(filename, "r", encoding="utf-8") as json_file:
         ^^^^^^^^^^^^^^^^^^^^^^^^^^^^^^^^^^^^^^^^
FileNotFoundError: [Errno 2] No such file or directory: '/.gc/my-creds.json'
[2024-06-27T23:37:13.120+0000] {processor.py:842} WARNING - No viable dags retrieved from /opt/airflow/dags/ingestion_dag.py
[2024-06-27T23:37:13.170+0000] {processor.py:183} INFO - Processing /opt/airflow/dags/ingestion_dag.py took 0.092 seconds
[2024-06-27T23:37:43.416+0000] {processor.py:161} INFO - Started process (PID=7207) to work on /opt/airflow/dags/ingestion_dag.py
[2024-06-27T23:37:43.418+0000] {processor.py:830} INFO - Processing file /opt/airflow/dags/ingestion_dag.py for tasks to queue
[2024-06-27T23:37:43.423+0000] {logging_mixin.py:188} INFO - [2024-06-27T23:37:43.422+0000] {dagbag.py:545} INFO - Filling up the DagBag from /opt/airflow/dags/ingestion_dag.py
[2024-06-27T23:37:43.430+0000] {logging_mixin.py:188} INFO - [2024-06-27T23:37:43.427+0000] {dagbag.py:355} ERROR - Failed to import: /opt/airflow/dags/ingestion_dag.py
Traceback (most recent call last):
  File "/home/airflow/.local/lib/python3.11/site-packages/airflow/models/dagbag.py", line 351, in parse
    loader.exec_module(new_module)
  File "<frozen importlib._bootstrap_external>", line 940, in exec_module
  File "<frozen importlib._bootstrap>", line 241, in _call_with_frames_removed
  File "/opt/airflow/dags/ingestion_dag.py", line 20, in <module>
    SERVICE_ACCOUNT_CREDENTIALS = service_account.Credentials.from_service_account_file(
                                  ^^^^^^^^^^^^^^^^^^^^^^^^^^^^^^^^^^^^^^^^^^^^^^^^^^^^^^
  File "/home/airflow/.local/lib/python3.11/site-packages/google/oauth2/service_account.py", line 258, in from_service_account_file
    info, signer = _service_account_info.from_filename(
                   ^^^^^^^^^^^^^^^^^^^^^^^^^^^^^^^^^^^^
  File "/home/airflow/.local/lib/python3.11/site-packages/google/auth/_service_account_info.py", line 78, in from_filename
    with io.open(filename, "r", encoding="utf-8") as json_file:
         ^^^^^^^^^^^^^^^^^^^^^^^^^^^^^^^^^^^^^^^^
FileNotFoundError: [Errno 2] No such file or directory: '/.gc/my-creds.json'
[2024-06-27T23:37:43.431+0000] {processor.py:842} WARNING - No viable dags retrieved from /opt/airflow/dags/ingestion_dag.py
[2024-06-27T23:37:43.473+0000] {processor.py:183} INFO - Processing /opt/airflow/dags/ingestion_dag.py took 0.070 seconds
[2024-06-27T23:38:13.915+0000] {processor.py:161} INFO - Started process (PID=7269) to work on /opt/airflow/dags/ingestion_dag.py
[2024-06-27T23:38:13.918+0000] {processor.py:830} INFO - Processing file /opt/airflow/dags/ingestion_dag.py for tasks to queue
[2024-06-27T23:38:13.922+0000] {logging_mixin.py:188} INFO - [2024-06-27T23:38:13.921+0000] {dagbag.py:545} INFO - Filling up the DagBag from /opt/airflow/dags/ingestion_dag.py
[2024-06-27T23:38:13.929+0000] {logging_mixin.py:188} INFO - [2024-06-27T23:38:13.927+0000] {dagbag.py:355} ERROR - Failed to import: /opt/airflow/dags/ingestion_dag.py
Traceback (most recent call last):
  File "/home/airflow/.local/lib/python3.11/site-packages/airflow/models/dagbag.py", line 351, in parse
    loader.exec_module(new_module)
  File "<frozen importlib._bootstrap_external>", line 940, in exec_module
  File "<frozen importlib._bootstrap>", line 241, in _call_with_frames_removed
  File "/opt/airflow/dags/ingestion_dag.py", line 20, in <module>
    SERVICE_ACCOUNT_CREDENTIALS = service_account.Credentials.from_service_account_file(
                                  ^^^^^^^^^^^^^^^^^^^^^^^^^^^^^^^^^^^^^^^^^^^^^^^^^^^^^^
  File "/home/airflow/.local/lib/python3.11/site-packages/google/oauth2/service_account.py", line 258, in from_service_account_file
    info, signer = _service_account_info.from_filename(
                   ^^^^^^^^^^^^^^^^^^^^^^^^^^^^^^^^^^^^
  File "/home/airflow/.local/lib/python3.11/site-packages/google/auth/_service_account_info.py", line 78, in from_filename
    with io.open(filename, "r", encoding="utf-8") as json_file:
         ^^^^^^^^^^^^^^^^^^^^^^^^^^^^^^^^^^^^^^^^
FileNotFoundError: [Errno 2] No such file or directory: '/.gc/my-creds.json'
[2024-06-27T23:38:13.931+0000] {processor.py:842} WARNING - No viable dags retrieved from /opt/airflow/dags/ingestion_dag.py
[2024-06-27T23:38:13.973+0000] {processor.py:183} INFO - Processing /opt/airflow/dags/ingestion_dag.py took 0.072 seconds
[2024-06-27T23:38:44.326+0000] {processor.py:161} INFO - Started process (PID=7331) to work on /opt/airflow/dags/ingestion_dag.py
[2024-06-27T23:38:44.328+0000] {processor.py:830} INFO - Processing file /opt/airflow/dags/ingestion_dag.py for tasks to queue
[2024-06-27T23:38:44.333+0000] {logging_mixin.py:188} INFO - [2024-06-27T23:38:44.332+0000] {dagbag.py:545} INFO - Filling up the DagBag from /opt/airflow/dags/ingestion_dag.py
[2024-06-27T23:38:44.340+0000] {logging_mixin.py:188} INFO - [2024-06-27T23:38:44.337+0000] {dagbag.py:355} ERROR - Failed to import: /opt/airflow/dags/ingestion_dag.py
Traceback (most recent call last):
  File "/home/airflow/.local/lib/python3.11/site-packages/airflow/models/dagbag.py", line 351, in parse
    loader.exec_module(new_module)
  File "<frozen importlib._bootstrap_external>", line 940, in exec_module
  File "<frozen importlib._bootstrap>", line 241, in _call_with_frames_removed
  File "/opt/airflow/dags/ingestion_dag.py", line 20, in <module>
    SERVICE_ACCOUNT_CREDENTIALS = service_account.Credentials.from_service_account_file(
                                  ^^^^^^^^^^^^^^^^^^^^^^^^^^^^^^^^^^^^^^^^^^^^^^^^^^^^^^
  File "/home/airflow/.local/lib/python3.11/site-packages/google/oauth2/service_account.py", line 258, in from_service_account_file
    info, signer = _service_account_info.from_filename(
                   ^^^^^^^^^^^^^^^^^^^^^^^^^^^^^^^^^^^^
  File "/home/airflow/.local/lib/python3.11/site-packages/google/auth/_service_account_info.py", line 78, in from_filename
    with io.open(filename, "r", encoding="utf-8") as json_file:
         ^^^^^^^^^^^^^^^^^^^^^^^^^^^^^^^^^^^^^^^^
FileNotFoundError: [Errno 2] No such file or directory: '/.gc/my-creds.json'
[2024-06-27T23:38:44.341+0000] {processor.py:842} WARNING - No viable dags retrieved from /opt/airflow/dags/ingestion_dag.py
[2024-06-27T23:38:44.389+0000] {processor.py:183} INFO - Processing /opt/airflow/dags/ingestion_dag.py took 0.076 seconds
[2024-06-27T23:39:15.034+0000] {processor.py:161} INFO - Started process (PID=7393) to work on /opt/airflow/dags/ingestion_dag.py
[2024-06-27T23:39:15.038+0000] {processor.py:830} INFO - Processing file /opt/airflow/dags/ingestion_dag.py for tasks to queue
[2024-06-27T23:39:15.043+0000] {logging_mixin.py:188} INFO - [2024-06-27T23:39:15.042+0000] {dagbag.py:545} INFO - Filling up the DagBag from /opt/airflow/dags/ingestion_dag.py
[2024-06-27T23:39:15.052+0000] {logging_mixin.py:188} INFO - [2024-06-27T23:39:15.049+0000] {dagbag.py:355} ERROR - Failed to import: /opt/airflow/dags/ingestion_dag.py
Traceback (most recent call last):
  File "/home/airflow/.local/lib/python3.11/site-packages/airflow/models/dagbag.py", line 351, in parse
    loader.exec_module(new_module)
  File "<frozen importlib._bootstrap_external>", line 940, in exec_module
  File "<frozen importlib._bootstrap>", line 241, in _call_with_frames_removed
  File "/opt/airflow/dags/ingestion_dag.py", line 20, in <module>
    SERVICE_ACCOUNT_CREDENTIALS = service_account.Credentials.from_service_account_file(
                                  ^^^^^^^^^^^^^^^^^^^^^^^^^^^^^^^^^^^^^^^^^^^^^^^^^^^^^^
  File "/home/airflow/.local/lib/python3.11/site-packages/google/oauth2/service_account.py", line 258, in from_service_account_file
    info, signer = _service_account_info.from_filename(
                   ^^^^^^^^^^^^^^^^^^^^^^^^^^^^^^^^^^^^
  File "/home/airflow/.local/lib/python3.11/site-packages/google/auth/_service_account_info.py", line 78, in from_filename
    with io.open(filename, "r", encoding="utf-8") as json_file:
         ^^^^^^^^^^^^^^^^^^^^^^^^^^^^^^^^^^^^^^^^
FileNotFoundError: [Errno 2] No such file or directory: '/.gc/my-creds.json'
[2024-06-27T23:39:15.054+0000] {processor.py:842} WARNING - No viable dags retrieved from /opt/airflow/dags/ingestion_dag.py
[2024-06-27T23:39:15.096+0000] {processor.py:183} INFO - Processing /opt/airflow/dags/ingestion_dag.py took 0.076 seconds
[2024-06-27T23:39:45.484+0000] {processor.py:161} INFO - Started process (PID=7455) to work on /opt/airflow/dags/ingestion_dag.py
[2024-06-27T23:39:45.487+0000] {processor.py:830} INFO - Processing file /opt/airflow/dags/ingestion_dag.py for tasks to queue
[2024-06-27T23:39:45.491+0000] {logging_mixin.py:188} INFO - [2024-06-27T23:39:45.491+0000] {dagbag.py:545} INFO - Filling up the DagBag from /opt/airflow/dags/ingestion_dag.py
[2024-06-27T23:39:45.498+0000] {logging_mixin.py:188} INFO - [2024-06-27T23:39:45.496+0000] {dagbag.py:355} ERROR - Failed to import: /opt/airflow/dags/ingestion_dag.py
Traceback (most recent call last):
  File "/home/airflow/.local/lib/python3.11/site-packages/airflow/models/dagbag.py", line 351, in parse
    loader.exec_module(new_module)
  File "<frozen importlib._bootstrap_external>", line 940, in exec_module
  File "<frozen importlib._bootstrap>", line 241, in _call_with_frames_removed
  File "/opt/airflow/dags/ingestion_dag.py", line 20, in <module>
    SERVICE_ACCOUNT_CREDENTIALS = service_account.Credentials.from_service_account_file(
                                  ^^^^^^^^^^^^^^^^^^^^^^^^^^^^^^^^^^^^^^^^^^^^^^^^^^^^^^
  File "/home/airflow/.local/lib/python3.11/site-packages/google/oauth2/service_account.py", line 258, in from_service_account_file
    info, signer = _service_account_info.from_filename(
                   ^^^^^^^^^^^^^^^^^^^^^^^^^^^^^^^^^^^^
  File "/home/airflow/.local/lib/python3.11/site-packages/google/auth/_service_account_info.py", line 78, in from_filename
    with io.open(filename, "r", encoding="utf-8") as json_file:
         ^^^^^^^^^^^^^^^^^^^^^^^^^^^^^^^^^^^^^^^^
FileNotFoundError: [Errno 2] No such file or directory: '/.gc/my-creds.json'
[2024-06-27T23:39:45.499+0000] {processor.py:842} WARNING - No viable dags retrieved from /opt/airflow/dags/ingestion_dag.py
[2024-06-27T23:39:45.539+0000] {processor.py:183} INFO - Processing /opt/airflow/dags/ingestion_dag.py took 0.068 seconds
[2024-06-27T23:40:16.194+0000] {processor.py:161} INFO - Started process (PID=7517) to work on /opt/airflow/dags/ingestion_dag.py
[2024-06-27T23:40:16.198+0000] {processor.py:830} INFO - Processing file /opt/airflow/dags/ingestion_dag.py for tasks to queue
[2024-06-27T23:40:16.207+0000] {logging_mixin.py:188} INFO - [2024-06-27T23:40:16.205+0000] {dagbag.py:545} INFO - Filling up the DagBag from /opt/airflow/dags/ingestion_dag.py
[2024-06-27T23:40:16.216+0000] {logging_mixin.py:188} INFO - [2024-06-27T23:40:16.213+0000] {dagbag.py:355} ERROR - Failed to import: /opt/airflow/dags/ingestion_dag.py
Traceback (most recent call last):
  File "/home/airflow/.local/lib/python3.11/site-packages/airflow/models/dagbag.py", line 351, in parse
    loader.exec_module(new_module)
  File "<frozen importlib._bootstrap_external>", line 940, in exec_module
  File "<frozen importlib._bootstrap>", line 241, in _call_with_frames_removed
  File "/opt/airflow/dags/ingestion_dag.py", line 20, in <module>
    SERVICE_ACCOUNT_CREDENTIALS = service_account.Credentials.from_service_account_file(
                                  ^^^^^^^^^^^^^^^^^^^^^^^^^^^^^^^^^^^^^^^^^^^^^^^^^^^^^^
  File "/home/airflow/.local/lib/python3.11/site-packages/google/oauth2/service_account.py", line 258, in from_service_account_file
    info, signer = _service_account_info.from_filename(
                   ^^^^^^^^^^^^^^^^^^^^^^^^^^^^^^^^^^^^
  File "/home/airflow/.local/lib/python3.11/site-packages/google/auth/_service_account_info.py", line 78, in from_filename
    with io.open(filename, "r", encoding="utf-8") as json_file:
         ^^^^^^^^^^^^^^^^^^^^^^^^^^^^^^^^^^^^^^^^
FileNotFoundError: [Errno 2] No such file or directory: '/.gc/my-creds.json'
[2024-06-27T23:40:16.218+0000] {processor.py:842} WARNING - No viable dags retrieved from /opt/airflow/dags/ingestion_dag.py
[2024-06-27T23:40:16.269+0000] {processor.py:183} INFO - Processing /opt/airflow/dags/ingestion_dag.py took 0.092 seconds
[2024-06-27T23:40:46.760+0000] {processor.py:161} INFO - Started process (PID=7578) to work on /opt/airflow/dags/ingestion_dag.py
[2024-06-27T23:40:46.763+0000] {processor.py:830} INFO - Processing file /opt/airflow/dags/ingestion_dag.py for tasks to queue
[2024-06-27T23:40:46.767+0000] {logging_mixin.py:188} INFO - [2024-06-27T23:40:46.767+0000] {dagbag.py:545} INFO - Filling up the DagBag from /opt/airflow/dags/ingestion_dag.py
[2024-06-27T23:40:46.774+0000] {logging_mixin.py:188} INFO - [2024-06-27T23:40:46.772+0000] {dagbag.py:355} ERROR - Failed to import: /opt/airflow/dags/ingestion_dag.py
Traceback (most recent call last):
  File "/home/airflow/.local/lib/python3.11/site-packages/airflow/models/dagbag.py", line 351, in parse
    loader.exec_module(new_module)
  File "<frozen importlib._bootstrap_external>", line 940, in exec_module
  File "<frozen importlib._bootstrap>", line 241, in _call_with_frames_removed
  File "/opt/airflow/dags/ingestion_dag.py", line 20, in <module>
    SERVICE_ACCOUNT_CREDENTIALS = service_account.Credentials.from_service_account_file(
                                  ^^^^^^^^^^^^^^^^^^^^^^^^^^^^^^^^^^^^^^^^^^^^^^^^^^^^^^
  File "/home/airflow/.local/lib/python3.11/site-packages/google/oauth2/service_account.py", line 258, in from_service_account_file
    info, signer = _service_account_info.from_filename(
                   ^^^^^^^^^^^^^^^^^^^^^^^^^^^^^^^^^^^^
  File "/home/airflow/.local/lib/python3.11/site-packages/google/auth/_service_account_info.py", line 78, in from_filename
    with io.open(filename, "r", encoding="utf-8") as json_file:
         ^^^^^^^^^^^^^^^^^^^^^^^^^^^^^^^^^^^^^^^^
FileNotFoundError: [Errno 2] No such file or directory: '/.gc/my-creds.json'
[2024-06-27T23:40:46.776+0000] {processor.py:842} WARNING - No viable dags retrieved from /opt/airflow/dags/ingestion_dag.py
[2024-06-27T23:40:46.813+0000] {processor.py:183} INFO - Processing /opt/airflow/dags/ingestion_dag.py took 0.071 seconds
[2024-06-27T23:41:17.406+0000] {processor.py:161} INFO - Started process (PID=7640) to work on /opt/airflow/dags/ingestion_dag.py
[2024-06-27T23:41:17.410+0000] {processor.py:830} INFO - Processing file /opt/airflow/dags/ingestion_dag.py for tasks to queue
[2024-06-27T23:41:17.417+0000] {logging_mixin.py:188} INFO - [2024-06-27T23:41:17.415+0000] {dagbag.py:545} INFO - Filling up the DagBag from /opt/airflow/dags/ingestion_dag.py
[2024-06-27T23:41:17.427+0000] {logging_mixin.py:188} INFO - [2024-06-27T23:41:17.423+0000] {dagbag.py:355} ERROR - Failed to import: /opt/airflow/dags/ingestion_dag.py
Traceback (most recent call last):
  File "/home/airflow/.local/lib/python3.11/site-packages/airflow/models/dagbag.py", line 351, in parse
    loader.exec_module(new_module)
  File "<frozen importlib._bootstrap_external>", line 940, in exec_module
  File "<frozen importlib._bootstrap>", line 241, in _call_with_frames_removed
  File "/opt/airflow/dags/ingestion_dag.py", line 20, in <module>
    SERVICE_ACCOUNT_CREDENTIALS = service_account.Credentials.from_service_account_file(
                                  ^^^^^^^^^^^^^^^^^^^^^^^^^^^^^^^^^^^^^^^^^^^^^^^^^^^^^^
  File "/home/airflow/.local/lib/python3.11/site-packages/google/oauth2/service_account.py", line 258, in from_service_account_file
    info, signer = _service_account_info.from_filename(
                   ^^^^^^^^^^^^^^^^^^^^^^^^^^^^^^^^^^^^
  File "/home/airflow/.local/lib/python3.11/site-packages/google/auth/_service_account_info.py", line 78, in from_filename
    with io.open(filename, "r", encoding="utf-8") as json_file:
         ^^^^^^^^^^^^^^^^^^^^^^^^^^^^^^^^^^^^^^^^
FileNotFoundError: [Errno 2] No such file or directory: '/.gc/my-creds.json'
[2024-06-27T23:41:17.430+0000] {processor.py:842} WARNING - No viable dags retrieved from /opt/airflow/dags/ingestion_dag.py
[2024-06-27T23:41:17.480+0000] {processor.py:183} INFO - Processing /opt/airflow/dags/ingestion_dag.py took 0.092 seconds
[2024-06-27T23:41:47.780+0000] {processor.py:161} INFO - Started process (PID=7702) to work on /opt/airflow/dags/ingestion_dag.py
[2024-06-27T23:41:47.782+0000] {processor.py:830} INFO - Processing file /opt/airflow/dags/ingestion_dag.py for tasks to queue
[2024-06-27T23:41:47.787+0000] {logging_mixin.py:188} INFO - [2024-06-27T23:41:47.786+0000] {dagbag.py:545} INFO - Filling up the DagBag from /opt/airflow/dags/ingestion_dag.py
[2024-06-27T23:41:47.794+0000] {logging_mixin.py:188} INFO - [2024-06-27T23:41:47.792+0000] {dagbag.py:355} ERROR - Failed to import: /opt/airflow/dags/ingestion_dag.py
Traceback (most recent call last):
  File "/home/airflow/.local/lib/python3.11/site-packages/airflow/models/dagbag.py", line 351, in parse
    loader.exec_module(new_module)
  File "<frozen importlib._bootstrap_external>", line 940, in exec_module
  File "<frozen importlib._bootstrap>", line 241, in _call_with_frames_removed
  File "/opt/airflow/dags/ingestion_dag.py", line 20, in <module>
    SERVICE_ACCOUNT_CREDENTIALS = service_account.Credentials.from_service_account_file(
                                  ^^^^^^^^^^^^^^^^^^^^^^^^^^^^^^^^^^^^^^^^^^^^^^^^^^^^^^
  File "/home/airflow/.local/lib/python3.11/site-packages/google/oauth2/service_account.py", line 258, in from_service_account_file
    info, signer = _service_account_info.from_filename(
                   ^^^^^^^^^^^^^^^^^^^^^^^^^^^^^^^^^^^^
  File "/home/airflow/.local/lib/python3.11/site-packages/google/auth/_service_account_info.py", line 78, in from_filename
    with io.open(filename, "r", encoding="utf-8") as json_file:
         ^^^^^^^^^^^^^^^^^^^^^^^^^^^^^^^^^^^^^^^^
FileNotFoundError: [Errno 2] No such file or directory: '/.gc/my-creds.json'
[2024-06-27T23:41:47.796+0000] {processor.py:842} WARNING - No viable dags retrieved from /opt/airflow/dags/ingestion_dag.py
[2024-06-27T23:41:47.836+0000] {processor.py:183} INFO - Processing /opt/airflow/dags/ingestion_dag.py took 0.070 seconds
[2024-06-27T23:42:18.292+0000] {processor.py:161} INFO - Started process (PID=7765) to work on /opt/airflow/dags/ingestion_dag.py
[2024-06-27T23:42:18.295+0000] {processor.py:830} INFO - Processing file /opt/airflow/dags/ingestion_dag.py for tasks to queue
[2024-06-27T23:42:18.299+0000] {logging_mixin.py:188} INFO - [2024-06-27T23:42:18.299+0000] {dagbag.py:545} INFO - Filling up the DagBag from /opt/airflow/dags/ingestion_dag.py
[2024-06-27T23:42:18.306+0000] {logging_mixin.py:188} INFO - [2024-06-27T23:42:18.304+0000] {dagbag.py:355} ERROR - Failed to import: /opt/airflow/dags/ingestion_dag.py
Traceback (most recent call last):
  File "/home/airflow/.local/lib/python3.11/site-packages/airflow/models/dagbag.py", line 351, in parse
    loader.exec_module(new_module)
  File "<frozen importlib._bootstrap_external>", line 940, in exec_module
  File "<frozen importlib._bootstrap>", line 241, in _call_with_frames_removed
  File "/opt/airflow/dags/ingestion_dag.py", line 20, in <module>
    SERVICE_ACCOUNT_CREDENTIALS = service_account.Credentials.from_service_account_file(
                                  ^^^^^^^^^^^^^^^^^^^^^^^^^^^^^^^^^^^^^^^^^^^^^^^^^^^^^^
  File "/home/airflow/.local/lib/python3.11/site-packages/google/oauth2/service_account.py", line 258, in from_service_account_file
    info, signer = _service_account_info.from_filename(
                   ^^^^^^^^^^^^^^^^^^^^^^^^^^^^^^^^^^^^
  File "/home/airflow/.local/lib/python3.11/site-packages/google/auth/_service_account_info.py", line 78, in from_filename
    with io.open(filename, "r", encoding="utf-8") as json_file:
         ^^^^^^^^^^^^^^^^^^^^^^^^^^^^^^^^^^^^^^^^
FileNotFoundError: [Errno 2] No such file or directory: '/.gc/my-creds.json'
[2024-06-27T23:42:18.308+0000] {processor.py:842} WARNING - No viable dags retrieved from /opt/airflow/dags/ingestion_dag.py
[2024-06-27T23:42:18.347+0000] {processor.py:183} INFO - Processing /opt/airflow/dags/ingestion_dag.py took 0.068 seconds
[2024-06-27T23:42:48.782+0000] {processor.py:161} INFO - Started process (PID=7827) to work on /opt/airflow/dags/ingestion_dag.py
[2024-06-27T23:42:48.784+0000] {processor.py:830} INFO - Processing file /opt/airflow/dags/ingestion_dag.py for tasks to queue
[2024-06-27T23:42:48.789+0000] {logging_mixin.py:188} INFO - [2024-06-27T23:42:48.788+0000] {dagbag.py:545} INFO - Filling up the DagBag from /opt/airflow/dags/ingestion_dag.py
[2024-06-27T23:42:48.796+0000] {logging_mixin.py:188} INFO - [2024-06-27T23:42:48.794+0000] {dagbag.py:355} ERROR - Failed to import: /opt/airflow/dags/ingestion_dag.py
Traceback (most recent call last):
  File "/home/airflow/.local/lib/python3.11/site-packages/airflow/models/dagbag.py", line 351, in parse
    loader.exec_module(new_module)
  File "<frozen importlib._bootstrap_external>", line 940, in exec_module
  File "<frozen importlib._bootstrap>", line 241, in _call_with_frames_removed
  File "/opt/airflow/dags/ingestion_dag.py", line 20, in <module>
    SERVICE_ACCOUNT_CREDENTIALS = service_account.Credentials.from_service_account_file(
                                  ^^^^^^^^^^^^^^^^^^^^^^^^^^^^^^^^^^^^^^^^^^^^^^^^^^^^^^
  File "/home/airflow/.local/lib/python3.11/site-packages/google/oauth2/service_account.py", line 258, in from_service_account_file
    info, signer = _service_account_info.from_filename(
                   ^^^^^^^^^^^^^^^^^^^^^^^^^^^^^^^^^^^^
  File "/home/airflow/.local/lib/python3.11/site-packages/google/auth/_service_account_info.py", line 78, in from_filename
    with io.open(filename, "r", encoding="utf-8") as json_file:
         ^^^^^^^^^^^^^^^^^^^^^^^^^^^^^^^^^^^^^^^^
FileNotFoundError: [Errno 2] No such file or directory: '/.gc/my-creds.json'
[2024-06-27T23:42:48.797+0000] {processor.py:842} WARNING - No viable dags retrieved from /opt/airflow/dags/ingestion_dag.py
[2024-06-27T23:42:48.837+0000] {processor.py:183} INFO - Processing /opt/airflow/dags/ingestion_dag.py took 0.070 seconds
[2024-06-27T23:43:19.198+0000] {processor.py:161} INFO - Started process (PID=7889) to work on /opt/airflow/dags/ingestion_dag.py
[2024-06-27T23:43:19.201+0000] {processor.py:830} INFO - Processing file /opt/airflow/dags/ingestion_dag.py for tasks to queue
[2024-06-27T23:43:19.205+0000] {logging_mixin.py:188} INFO - [2024-06-27T23:43:19.204+0000] {dagbag.py:545} INFO - Filling up the DagBag from /opt/airflow/dags/ingestion_dag.py
[2024-06-27T23:43:19.212+0000] {logging_mixin.py:188} INFO - [2024-06-27T23:43:19.210+0000] {dagbag.py:355} ERROR - Failed to import: /opt/airflow/dags/ingestion_dag.py
Traceback (most recent call last):
  File "/home/airflow/.local/lib/python3.11/site-packages/airflow/models/dagbag.py", line 351, in parse
    loader.exec_module(new_module)
  File "<frozen importlib._bootstrap_external>", line 940, in exec_module
  File "<frozen importlib._bootstrap>", line 241, in _call_with_frames_removed
  File "/opt/airflow/dags/ingestion_dag.py", line 20, in <module>
    SERVICE_ACCOUNT_CREDENTIALS = service_account.Credentials.from_service_account_file(
                                  ^^^^^^^^^^^^^^^^^^^^^^^^^^^^^^^^^^^^^^^^^^^^^^^^^^^^^^
  File "/home/airflow/.local/lib/python3.11/site-packages/google/oauth2/service_account.py", line 258, in from_service_account_file
    info, signer = _service_account_info.from_filename(
                   ^^^^^^^^^^^^^^^^^^^^^^^^^^^^^^^^^^^^
  File "/home/airflow/.local/lib/python3.11/site-packages/google/auth/_service_account_info.py", line 78, in from_filename
    with io.open(filename, "r", encoding="utf-8") as json_file:
         ^^^^^^^^^^^^^^^^^^^^^^^^^^^^^^^^^^^^^^^^
FileNotFoundError: [Errno 2] No such file or directory: '/.gc/my-creds.json'
[2024-06-27T23:43:19.214+0000] {processor.py:842} WARNING - No viable dags retrieved from /opt/airflow/dags/ingestion_dag.py
[2024-06-27T23:43:19.251+0000] {processor.py:183} INFO - Processing /opt/airflow/dags/ingestion_dag.py took 0.066 seconds
[2024-06-27T23:43:49.510+0000] {processor.py:161} INFO - Started process (PID=7951) to work on /opt/airflow/dags/ingestion_dag.py
[2024-06-27T23:43:49.514+0000] {processor.py:830} INFO - Processing file /opt/airflow/dags/ingestion_dag.py for tasks to queue
[2024-06-27T23:43:49.518+0000] {logging_mixin.py:188} INFO - [2024-06-27T23:43:49.517+0000] {dagbag.py:545} INFO - Filling up the DagBag from /opt/airflow/dags/ingestion_dag.py
[2024-06-27T23:43:49.526+0000] {logging_mixin.py:188} INFO - [2024-06-27T23:43:49.523+0000] {dagbag.py:355} ERROR - Failed to import: /opt/airflow/dags/ingestion_dag.py
Traceback (most recent call last):
  File "/home/airflow/.local/lib/python3.11/site-packages/airflow/models/dagbag.py", line 351, in parse
    loader.exec_module(new_module)
  File "<frozen importlib._bootstrap_external>", line 940, in exec_module
  File "<frozen importlib._bootstrap>", line 241, in _call_with_frames_removed
  File "/opt/airflow/dags/ingestion_dag.py", line 20, in <module>
    SERVICE_ACCOUNT_CREDENTIALS = service_account.Credentials.from_service_account_file(
                                  ^^^^^^^^^^^^^^^^^^^^^^^^^^^^^^^^^^^^^^^^^^^^^^^^^^^^^^
  File "/home/airflow/.local/lib/python3.11/site-packages/google/oauth2/service_account.py", line 258, in from_service_account_file
    info, signer = _service_account_info.from_filename(
                   ^^^^^^^^^^^^^^^^^^^^^^^^^^^^^^^^^^^^
  File "/home/airflow/.local/lib/python3.11/site-packages/google/auth/_service_account_info.py", line 78, in from_filename
    with io.open(filename, "r", encoding="utf-8") as json_file:
         ^^^^^^^^^^^^^^^^^^^^^^^^^^^^^^^^^^^^^^^^
FileNotFoundError: [Errno 2] No such file or directory: '/.gc/my-creds.json'
[2024-06-27T23:43:49.528+0000] {processor.py:842} WARNING - No viable dags retrieved from /opt/airflow/dags/ingestion_dag.py
[2024-06-27T23:43:49.575+0000] {processor.py:183} INFO - Processing /opt/airflow/dags/ingestion_dag.py took 0.079 seconds
[2024-06-27T23:44:19.685+0000] {processor.py:161} INFO - Started process (PID=8013) to work on /opt/airflow/dags/ingestion_dag.py
[2024-06-27T23:44:19.687+0000] {processor.py:830} INFO - Processing file /opt/airflow/dags/ingestion_dag.py for tasks to queue
[2024-06-27T23:44:19.691+0000] {logging_mixin.py:188} INFO - [2024-06-27T23:44:19.690+0000] {dagbag.py:545} INFO - Filling up the DagBag from /opt/airflow/dags/ingestion_dag.py
[2024-06-27T23:44:19.698+0000] {logging_mixin.py:188} INFO - [2024-06-27T23:44:19.695+0000] {dagbag.py:355} ERROR - Failed to import: /opt/airflow/dags/ingestion_dag.py
Traceback (most recent call last):
  File "/home/airflow/.local/lib/python3.11/site-packages/airflow/models/dagbag.py", line 351, in parse
    loader.exec_module(new_module)
  File "<frozen importlib._bootstrap_external>", line 940, in exec_module
  File "<frozen importlib._bootstrap>", line 241, in _call_with_frames_removed
  File "/opt/airflow/dags/ingestion_dag.py", line 20, in <module>
    SERVICE_ACCOUNT_CREDENTIALS = service_account.Credentials.from_service_account_file(
                                  ^^^^^^^^^^^^^^^^^^^^^^^^^^^^^^^^^^^^^^^^^^^^^^^^^^^^^^
  File "/home/airflow/.local/lib/python3.11/site-packages/google/oauth2/service_account.py", line 258, in from_service_account_file
    info, signer = _service_account_info.from_filename(
                   ^^^^^^^^^^^^^^^^^^^^^^^^^^^^^^^^^^^^
  File "/home/airflow/.local/lib/python3.11/site-packages/google/auth/_service_account_info.py", line 78, in from_filename
    with io.open(filename, "r", encoding="utf-8") as json_file:
         ^^^^^^^^^^^^^^^^^^^^^^^^^^^^^^^^^^^^^^^^
FileNotFoundError: [Errno 2] No such file or directory: '/.gc/my-creds.json'
[2024-06-27T23:44:19.699+0000] {processor.py:842} WARNING - No viable dags retrieved from /opt/airflow/dags/ingestion_dag.py
[2024-06-27T23:44:19.737+0000] {processor.py:183} INFO - Processing /opt/airflow/dags/ingestion_dag.py took 0.066 seconds
[2024-06-27T23:44:49.950+0000] {processor.py:161} INFO - Started process (PID=8075) to work on /opt/airflow/dags/ingestion_dag.py
[2024-06-27T23:44:49.953+0000] {processor.py:830} INFO - Processing file /opt/airflow/dags/ingestion_dag.py for tasks to queue
[2024-06-27T23:44:49.958+0000] {logging_mixin.py:188} INFO - [2024-06-27T23:44:49.958+0000] {dagbag.py:545} INFO - Filling up the DagBag from /opt/airflow/dags/ingestion_dag.py
[2024-06-27T23:44:49.967+0000] {logging_mixin.py:188} INFO - [2024-06-27T23:44:49.964+0000] {dagbag.py:355} ERROR - Failed to import: /opt/airflow/dags/ingestion_dag.py
Traceback (most recent call last):
  File "/home/airflow/.local/lib/python3.11/site-packages/airflow/models/dagbag.py", line 351, in parse
    loader.exec_module(new_module)
  File "<frozen importlib._bootstrap_external>", line 940, in exec_module
  File "<frozen importlib._bootstrap>", line 241, in _call_with_frames_removed
  File "/opt/airflow/dags/ingestion_dag.py", line 20, in <module>
    SERVICE_ACCOUNT_CREDENTIALS = service_account.Credentials.from_service_account_file(
                                  ^^^^^^^^^^^^^^^^^^^^^^^^^^^^^^^^^^^^^^^^^^^^^^^^^^^^^^
  File "/home/airflow/.local/lib/python3.11/site-packages/google/oauth2/service_account.py", line 258, in from_service_account_file
    info, signer = _service_account_info.from_filename(
                   ^^^^^^^^^^^^^^^^^^^^^^^^^^^^^^^^^^^^
  File "/home/airflow/.local/lib/python3.11/site-packages/google/auth/_service_account_info.py", line 78, in from_filename
    with io.open(filename, "r", encoding="utf-8") as json_file:
         ^^^^^^^^^^^^^^^^^^^^^^^^^^^^^^^^^^^^^^^^
FileNotFoundError: [Errno 2] No such file or directory: '/.gc/my-creds.json'
[2024-06-27T23:44:49.969+0000] {processor.py:842} WARNING - No viable dags retrieved from /opt/airflow/dags/ingestion_dag.py
[2024-06-27T23:44:50.007+0000] {processor.py:183} INFO - Processing /opt/airflow/dags/ingestion_dag.py took 0.070 seconds
[2024-06-27T23:45:20.295+0000] {processor.py:161} INFO - Started process (PID=8137) to work on /opt/airflow/dags/ingestion_dag.py
[2024-06-27T23:45:20.297+0000] {processor.py:830} INFO - Processing file /opt/airflow/dags/ingestion_dag.py for tasks to queue
[2024-06-27T23:45:20.302+0000] {logging_mixin.py:188} INFO - [2024-06-27T23:45:20.301+0000] {dagbag.py:545} INFO - Filling up the DagBag from /opt/airflow/dags/ingestion_dag.py
[2024-06-27T23:45:20.309+0000] {logging_mixin.py:188} INFO - [2024-06-27T23:45:20.306+0000] {dagbag.py:355} ERROR - Failed to import: /opt/airflow/dags/ingestion_dag.py
Traceback (most recent call last):
  File "/home/airflow/.local/lib/python3.11/site-packages/airflow/models/dagbag.py", line 351, in parse
    loader.exec_module(new_module)
  File "<frozen importlib._bootstrap_external>", line 940, in exec_module
  File "<frozen importlib._bootstrap>", line 241, in _call_with_frames_removed
  File "/opt/airflow/dags/ingestion_dag.py", line 20, in <module>
    SERVICE_ACCOUNT_CREDENTIALS = service_account.Credentials.from_service_account_file(
                                  ^^^^^^^^^^^^^^^^^^^^^^^^^^^^^^^^^^^^^^^^^^^^^^^^^^^^^^
  File "/home/airflow/.local/lib/python3.11/site-packages/google/oauth2/service_account.py", line 258, in from_service_account_file
    info, signer = _service_account_info.from_filename(
                   ^^^^^^^^^^^^^^^^^^^^^^^^^^^^^^^^^^^^
  File "/home/airflow/.local/lib/python3.11/site-packages/google/auth/_service_account_info.py", line 78, in from_filename
    with io.open(filename, "r", encoding="utf-8") as json_file:
         ^^^^^^^^^^^^^^^^^^^^^^^^^^^^^^^^^^^^^^^^
FileNotFoundError: [Errno 2] No such file or directory: '/.gc/my-creds.json'
[2024-06-27T23:45:20.310+0000] {processor.py:842} WARNING - No viable dags retrieved from /opt/airflow/dags/ingestion_dag.py
[2024-06-27T23:45:20.355+0000] {processor.py:183} INFO - Processing /opt/airflow/dags/ingestion_dag.py took 0.074 seconds
[2024-06-27T23:45:51.191+0000] {processor.py:161} INFO - Started process (PID=8199) to work on /opt/airflow/dags/ingestion_dag.py
[2024-06-27T23:45:51.193+0000] {processor.py:830} INFO - Processing file /opt/airflow/dags/ingestion_dag.py for tasks to queue
[2024-06-27T23:45:51.197+0000] {logging_mixin.py:188} INFO - [2024-06-27T23:45:51.197+0000] {dagbag.py:545} INFO - Filling up the DagBag from /opt/airflow/dags/ingestion_dag.py
[2024-06-27T23:45:51.204+0000] {logging_mixin.py:188} INFO - [2024-06-27T23:45:51.202+0000] {dagbag.py:355} ERROR - Failed to import: /opt/airflow/dags/ingestion_dag.py
Traceback (most recent call last):
  File "/home/airflow/.local/lib/python3.11/site-packages/airflow/models/dagbag.py", line 351, in parse
    loader.exec_module(new_module)
  File "<frozen importlib._bootstrap_external>", line 940, in exec_module
  File "<frozen importlib._bootstrap>", line 241, in _call_with_frames_removed
  File "/opt/airflow/dags/ingestion_dag.py", line 20, in <module>
    SERVICE_ACCOUNT_CREDENTIALS = service_account.Credentials.from_service_account_file(
                                  ^^^^^^^^^^^^^^^^^^^^^^^^^^^^^^^^^^^^^^^^^^^^^^^^^^^^^^
  File "/home/airflow/.local/lib/python3.11/site-packages/google/oauth2/service_account.py", line 258, in from_service_account_file
    info, signer = _service_account_info.from_filename(
                   ^^^^^^^^^^^^^^^^^^^^^^^^^^^^^^^^^^^^
  File "/home/airflow/.local/lib/python3.11/site-packages/google/auth/_service_account_info.py", line 78, in from_filename
    with io.open(filename, "r", encoding="utf-8") as json_file:
         ^^^^^^^^^^^^^^^^^^^^^^^^^^^^^^^^^^^^^^^^
FileNotFoundError: [Errno 2] No such file or directory: '/.gc/my-creds.json'
[2024-06-27T23:45:51.205+0000] {processor.py:842} WARNING - No viable dags retrieved from /opt/airflow/dags/ingestion_dag.py
[2024-06-27T23:45:51.248+0000] {processor.py:183} INFO - Processing /opt/airflow/dags/ingestion_dag.py took 0.071 seconds
[2024-06-27T23:46:21.976+0000] {processor.py:161} INFO - Started process (PID=8261) to work on /opt/airflow/dags/ingestion_dag.py
[2024-06-27T23:46:21.978+0000] {processor.py:830} INFO - Processing file /opt/airflow/dags/ingestion_dag.py for tasks to queue
[2024-06-27T23:46:21.983+0000] {logging_mixin.py:188} INFO - [2024-06-27T23:46:21.982+0000] {dagbag.py:545} INFO - Filling up the DagBag from /opt/airflow/dags/ingestion_dag.py
[2024-06-27T23:46:21.990+0000] {logging_mixin.py:188} INFO - [2024-06-27T23:46:21.987+0000] {dagbag.py:355} ERROR - Failed to import: /opt/airflow/dags/ingestion_dag.py
Traceback (most recent call last):
  File "/home/airflow/.local/lib/python3.11/site-packages/airflow/models/dagbag.py", line 351, in parse
    loader.exec_module(new_module)
  File "<frozen importlib._bootstrap_external>", line 940, in exec_module
  File "<frozen importlib._bootstrap>", line 241, in _call_with_frames_removed
  File "/opt/airflow/dags/ingestion_dag.py", line 20, in <module>
    SERVICE_ACCOUNT_CREDENTIALS = service_account.Credentials.from_service_account_file(
                                  ^^^^^^^^^^^^^^^^^^^^^^^^^^^^^^^^^^^^^^^^^^^^^^^^^^^^^^
  File "/home/airflow/.local/lib/python3.11/site-packages/google/oauth2/service_account.py", line 258, in from_service_account_file
    info, signer = _service_account_info.from_filename(
                   ^^^^^^^^^^^^^^^^^^^^^^^^^^^^^^^^^^^^
  File "/home/airflow/.local/lib/python3.11/site-packages/google/auth/_service_account_info.py", line 78, in from_filename
    with io.open(filename, "r", encoding="utf-8") as json_file:
         ^^^^^^^^^^^^^^^^^^^^^^^^^^^^^^^^^^^^^^^^
FileNotFoundError: [Errno 2] No such file or directory: '/.gc/my-creds.json'
[2024-06-27T23:46:21.992+0000] {processor.py:842} WARNING - No viable dags retrieved from /opt/airflow/dags/ingestion_dag.py
[2024-06-27T23:46:22.032+0000] {processor.py:183} INFO - Processing /opt/airflow/dags/ingestion_dag.py took 0.070 seconds
[2024-06-27T23:46:52.492+0000] {processor.py:161} INFO - Started process (PID=8323) to work on /opt/airflow/dags/ingestion_dag.py
[2024-06-27T23:46:52.495+0000] {processor.py:830} INFO - Processing file /opt/airflow/dags/ingestion_dag.py for tasks to queue
[2024-06-27T23:46:52.500+0000] {logging_mixin.py:188} INFO - [2024-06-27T23:46:52.499+0000] {dagbag.py:545} INFO - Filling up the DagBag from /opt/airflow/dags/ingestion_dag.py
[2024-06-27T23:46:52.507+0000] {logging_mixin.py:188} INFO - [2024-06-27T23:46:52.504+0000] {dagbag.py:355} ERROR - Failed to import: /opt/airflow/dags/ingestion_dag.py
Traceback (most recent call last):
  File "/home/airflow/.local/lib/python3.11/site-packages/airflow/models/dagbag.py", line 351, in parse
    loader.exec_module(new_module)
  File "<frozen importlib._bootstrap_external>", line 940, in exec_module
  File "<frozen importlib._bootstrap>", line 241, in _call_with_frames_removed
  File "/opt/airflow/dags/ingestion_dag.py", line 20, in <module>
    SERVICE_ACCOUNT_CREDENTIALS = service_account.Credentials.from_service_account_file(
                                  ^^^^^^^^^^^^^^^^^^^^^^^^^^^^^^^^^^^^^^^^^^^^^^^^^^^^^^
  File "/home/airflow/.local/lib/python3.11/site-packages/google/oauth2/service_account.py", line 258, in from_service_account_file
    info, signer = _service_account_info.from_filename(
                   ^^^^^^^^^^^^^^^^^^^^^^^^^^^^^^^^^^^^
  File "/home/airflow/.local/lib/python3.11/site-packages/google/auth/_service_account_info.py", line 78, in from_filename
    with io.open(filename, "r", encoding="utf-8") as json_file:
         ^^^^^^^^^^^^^^^^^^^^^^^^^^^^^^^^^^^^^^^^
FileNotFoundError: [Errno 2] No such file or directory: '/.gc/my-creds.json'
[2024-06-27T23:46:52.508+0000] {processor.py:842} WARNING - No viable dags retrieved from /opt/airflow/dags/ingestion_dag.py
[2024-06-27T23:46:52.557+0000] {processor.py:183} INFO - Processing /opt/airflow/dags/ingestion_dag.py took 0.083 seconds
[2024-06-27T23:47:22.752+0000] {processor.py:161} INFO - Started process (PID=8385) to work on /opt/airflow/dags/ingestion_dag.py
[2024-06-27T23:47:22.755+0000] {processor.py:830} INFO - Processing file /opt/airflow/dags/ingestion_dag.py for tasks to queue
[2024-06-27T23:47:22.759+0000] {logging_mixin.py:188} INFO - [2024-06-27T23:47:22.758+0000] {dagbag.py:545} INFO - Filling up the DagBag from /opt/airflow/dags/ingestion_dag.py
[2024-06-27T23:47:22.766+0000] {logging_mixin.py:188} INFO - [2024-06-27T23:47:22.764+0000] {dagbag.py:355} ERROR - Failed to import: /opt/airflow/dags/ingestion_dag.py
Traceback (most recent call last):
  File "/home/airflow/.local/lib/python3.11/site-packages/airflow/models/dagbag.py", line 351, in parse
    loader.exec_module(new_module)
  File "<frozen importlib._bootstrap_external>", line 940, in exec_module
  File "<frozen importlib._bootstrap>", line 241, in _call_with_frames_removed
  File "/opt/airflow/dags/ingestion_dag.py", line 20, in <module>
    SERVICE_ACCOUNT_CREDENTIALS = service_account.Credentials.from_service_account_file(
                                  ^^^^^^^^^^^^^^^^^^^^^^^^^^^^^^^^^^^^^^^^^^^^^^^^^^^^^^
  File "/home/airflow/.local/lib/python3.11/site-packages/google/oauth2/service_account.py", line 258, in from_service_account_file
    info, signer = _service_account_info.from_filename(
                   ^^^^^^^^^^^^^^^^^^^^^^^^^^^^^^^^^^^^
  File "/home/airflow/.local/lib/python3.11/site-packages/google/auth/_service_account_info.py", line 78, in from_filename
    with io.open(filename, "r", encoding="utf-8") as json_file:
         ^^^^^^^^^^^^^^^^^^^^^^^^^^^^^^^^^^^^^^^^
FileNotFoundError: [Errno 2] No such file or directory: '/.gc/my-creds.json'
[2024-06-27T23:47:22.768+0000] {processor.py:842} WARNING - No viable dags retrieved from /opt/airflow/dags/ingestion_dag.py
[2024-06-27T23:47:22.805+0000] {processor.py:183} INFO - Processing /opt/airflow/dags/ingestion_dag.py took 0.067 seconds
[2024-06-27T23:47:53.248+0000] {processor.py:161} INFO - Started process (PID=8447) to work on /opt/airflow/dags/ingestion_dag.py
[2024-06-27T23:47:53.251+0000] {processor.py:830} INFO - Processing file /opt/airflow/dags/ingestion_dag.py for tasks to queue
[2024-06-27T23:47:53.257+0000] {logging_mixin.py:188} INFO - [2024-06-27T23:47:53.256+0000] {dagbag.py:545} INFO - Filling up the DagBag from /opt/airflow/dags/ingestion_dag.py
[2024-06-27T23:47:53.265+0000] {logging_mixin.py:188} INFO - [2024-06-27T23:47:53.262+0000] {dagbag.py:355} ERROR - Failed to import: /opt/airflow/dags/ingestion_dag.py
Traceback (most recent call last):
  File "/home/airflow/.local/lib/python3.11/site-packages/airflow/models/dagbag.py", line 351, in parse
    loader.exec_module(new_module)
  File "<frozen importlib._bootstrap_external>", line 940, in exec_module
  File "<frozen importlib._bootstrap>", line 241, in _call_with_frames_removed
  File "/opt/airflow/dags/ingestion_dag.py", line 20, in <module>
    SERVICE_ACCOUNT_CREDENTIALS = service_account.Credentials.from_service_account_file(
                                  ^^^^^^^^^^^^^^^^^^^^^^^^^^^^^^^^^^^^^^^^^^^^^^^^^^^^^^
  File "/home/airflow/.local/lib/python3.11/site-packages/google/oauth2/service_account.py", line 258, in from_service_account_file
    info, signer = _service_account_info.from_filename(
                   ^^^^^^^^^^^^^^^^^^^^^^^^^^^^^^^^^^^^
  File "/home/airflow/.local/lib/python3.11/site-packages/google/auth/_service_account_info.py", line 78, in from_filename
    with io.open(filename, "r", encoding="utf-8") as json_file:
         ^^^^^^^^^^^^^^^^^^^^^^^^^^^^^^^^^^^^^^^^
FileNotFoundError: [Errno 2] No such file or directory: '/.gc/my-creds.json'
[2024-06-27T23:47:53.266+0000] {processor.py:842} WARNING - No viable dags retrieved from /opt/airflow/dags/ingestion_dag.py
[2024-06-27T23:47:53.311+0000] {processor.py:183} INFO - Processing /opt/airflow/dags/ingestion_dag.py took 0.080 seconds
[2024-06-27T23:48:24.058+0000] {processor.py:161} INFO - Started process (PID=8509) to work on /opt/airflow/dags/ingestion_dag.py
[2024-06-27T23:48:24.062+0000] {processor.py:830} INFO - Processing file /opt/airflow/dags/ingestion_dag.py for tasks to queue
[2024-06-27T23:48:24.068+0000] {logging_mixin.py:188} INFO - [2024-06-27T23:48:24.067+0000] {dagbag.py:545} INFO - Filling up the DagBag from /opt/airflow/dags/ingestion_dag.py
[2024-06-27T23:48:24.079+0000] {logging_mixin.py:188} INFO - [2024-06-27T23:48:24.075+0000] {dagbag.py:355} ERROR - Failed to import: /opt/airflow/dags/ingestion_dag.py
Traceback (most recent call last):
  File "/home/airflow/.local/lib/python3.11/site-packages/airflow/models/dagbag.py", line 351, in parse
    loader.exec_module(new_module)
  File "<frozen importlib._bootstrap_external>", line 940, in exec_module
  File "<frozen importlib._bootstrap>", line 241, in _call_with_frames_removed
  File "/opt/airflow/dags/ingestion_dag.py", line 20, in <module>
    SERVICE_ACCOUNT_CREDENTIALS = service_account.Credentials.from_service_account_file(
                                  ^^^^^^^^^^^^^^^^^^^^^^^^^^^^^^^^^^^^^^^^^^^^^^^^^^^^^^
  File "/home/airflow/.local/lib/python3.11/site-packages/google/oauth2/service_account.py", line 258, in from_service_account_file
    info, signer = _service_account_info.from_filename(
                   ^^^^^^^^^^^^^^^^^^^^^^^^^^^^^^^^^^^^
  File "/home/airflow/.local/lib/python3.11/site-packages/google/auth/_service_account_info.py", line 78, in from_filename
    with io.open(filename, "r", encoding="utf-8") as json_file:
         ^^^^^^^^^^^^^^^^^^^^^^^^^^^^^^^^^^^^^^^^
FileNotFoundError: [Errno 2] No such file or directory: '/.gc/my-creds.json'
[2024-06-27T23:48:24.081+0000] {processor.py:842} WARNING - No viable dags retrieved from /opt/airflow/dags/ingestion_dag.py
[2024-06-27T23:48:24.135+0000] {processor.py:183} INFO - Processing /opt/airflow/dags/ingestion_dag.py took 0.093 seconds
[2024-06-27T23:48:54.920+0000] {processor.py:161} INFO - Started process (PID=8571) to work on /opt/airflow/dags/ingestion_dag.py
[2024-06-27T23:48:54.922+0000] {processor.py:830} INFO - Processing file /opt/airflow/dags/ingestion_dag.py for tasks to queue
[2024-06-27T23:48:54.927+0000] {logging_mixin.py:188} INFO - [2024-06-27T23:48:54.926+0000] {dagbag.py:545} INFO - Filling up the DagBag from /opt/airflow/dags/ingestion_dag.py
[2024-06-27T23:48:54.934+0000] {logging_mixin.py:188} INFO - [2024-06-27T23:48:54.931+0000] {dagbag.py:355} ERROR - Failed to import: /opt/airflow/dags/ingestion_dag.py
Traceback (most recent call last):
  File "/home/airflow/.local/lib/python3.11/site-packages/airflow/models/dagbag.py", line 351, in parse
    loader.exec_module(new_module)
  File "<frozen importlib._bootstrap_external>", line 940, in exec_module
  File "<frozen importlib._bootstrap>", line 241, in _call_with_frames_removed
  File "/opt/airflow/dags/ingestion_dag.py", line 20, in <module>
    SERVICE_ACCOUNT_CREDENTIALS = service_account.Credentials.from_service_account_file(
                                  ^^^^^^^^^^^^^^^^^^^^^^^^^^^^^^^^^^^^^^^^^^^^^^^^^^^^^^
  File "/home/airflow/.local/lib/python3.11/site-packages/google/oauth2/service_account.py", line 258, in from_service_account_file
    info, signer = _service_account_info.from_filename(
                   ^^^^^^^^^^^^^^^^^^^^^^^^^^^^^^^^^^^^
  File "/home/airflow/.local/lib/python3.11/site-packages/google/auth/_service_account_info.py", line 78, in from_filename
    with io.open(filename, "r", encoding="utf-8") as json_file:
         ^^^^^^^^^^^^^^^^^^^^^^^^^^^^^^^^^^^^^^^^
FileNotFoundError: [Errno 2] No such file or directory: '/.gc/my-creds.json'
[2024-06-27T23:48:54.935+0000] {processor.py:842} WARNING - No viable dags retrieved from /opt/airflow/dags/ingestion_dag.py
[2024-06-27T23:48:54.980+0000] {processor.py:183} INFO - Processing /opt/airflow/dags/ingestion_dag.py took 0.074 seconds
[2024-06-27T23:49:25.065+0000] {processor.py:161} INFO - Started process (PID=8633) to work on /opt/airflow/dags/ingestion_dag.py
[2024-06-27T23:49:25.067+0000] {processor.py:830} INFO - Processing file /opt/airflow/dags/ingestion_dag.py for tasks to queue
[2024-06-27T23:49:25.071+0000] {logging_mixin.py:188} INFO - [2024-06-27T23:49:25.071+0000] {dagbag.py:545} INFO - Filling up the DagBag from /opt/airflow/dags/ingestion_dag.py
[2024-06-27T23:49:25.079+0000] {logging_mixin.py:188} INFO - [2024-06-27T23:49:25.076+0000] {dagbag.py:355} ERROR - Failed to import: /opt/airflow/dags/ingestion_dag.py
Traceback (most recent call last):
  File "/home/airflow/.local/lib/python3.11/site-packages/airflow/models/dagbag.py", line 351, in parse
    loader.exec_module(new_module)
  File "<frozen importlib._bootstrap_external>", line 940, in exec_module
  File "<frozen importlib._bootstrap>", line 241, in _call_with_frames_removed
  File "/opt/airflow/dags/ingestion_dag.py", line 20, in <module>
    SERVICE_ACCOUNT_CREDENTIALS = service_account.Credentials.from_service_account_file(
                                  ^^^^^^^^^^^^^^^^^^^^^^^^^^^^^^^^^^^^^^^^^^^^^^^^^^^^^^
  File "/home/airflow/.local/lib/python3.11/site-packages/google/oauth2/service_account.py", line 258, in from_service_account_file
    info, signer = _service_account_info.from_filename(
                   ^^^^^^^^^^^^^^^^^^^^^^^^^^^^^^^^^^^^
  File "/home/airflow/.local/lib/python3.11/site-packages/google/auth/_service_account_info.py", line 78, in from_filename
    with io.open(filename, "r", encoding="utf-8") as json_file:
         ^^^^^^^^^^^^^^^^^^^^^^^^^^^^^^^^^^^^^^^^
FileNotFoundError: [Errno 2] No such file or directory: '/.gc/my-creds.json'
[2024-06-27T23:49:25.080+0000] {processor.py:842} WARNING - No viable dags retrieved from /opt/airflow/dags/ingestion_dag.py
[2024-06-27T23:49:25.121+0000] {processor.py:183} INFO - Processing /opt/airflow/dags/ingestion_dag.py took 0.070 seconds
[2024-06-27T23:49:56.084+0000] {processor.py:161} INFO - Started process (PID=8694) to work on /opt/airflow/dags/ingestion_dag.py
[2024-06-27T23:49:56.086+0000] {processor.py:830} INFO - Processing file /opt/airflow/dags/ingestion_dag.py for tasks to queue
[2024-06-27T23:49:56.091+0000] {logging_mixin.py:188} INFO - [2024-06-27T23:49:56.090+0000] {dagbag.py:545} INFO - Filling up the DagBag from /opt/airflow/dags/ingestion_dag.py
[2024-06-27T23:49:56.100+0000] {logging_mixin.py:188} INFO - [2024-06-27T23:49:56.097+0000] {dagbag.py:355} ERROR - Failed to import: /opt/airflow/dags/ingestion_dag.py
Traceback (most recent call last):
  File "/home/airflow/.local/lib/python3.11/site-packages/airflow/models/dagbag.py", line 351, in parse
    loader.exec_module(new_module)
  File "<frozen importlib._bootstrap_external>", line 940, in exec_module
  File "<frozen importlib._bootstrap>", line 241, in _call_with_frames_removed
  File "/opt/airflow/dags/ingestion_dag.py", line 20, in <module>
    SERVICE_ACCOUNT_CREDENTIALS = service_account.Credentials.from_service_account_file(
                                  ^^^^^^^^^^^^^^^^^^^^^^^^^^^^^^^^^^^^^^^^^^^^^^^^^^^^^^
  File "/home/airflow/.local/lib/python3.11/site-packages/google/oauth2/service_account.py", line 258, in from_service_account_file
    info, signer = _service_account_info.from_filename(
                   ^^^^^^^^^^^^^^^^^^^^^^^^^^^^^^^^^^^^
  File "/home/airflow/.local/lib/python3.11/site-packages/google/auth/_service_account_info.py", line 78, in from_filename
    with io.open(filename, "r", encoding="utf-8") as json_file:
         ^^^^^^^^^^^^^^^^^^^^^^^^^^^^^^^^^^^^^^^^
FileNotFoundError: [Errno 2] No such file or directory: '/.gc/my-creds.json'
[2024-06-27T23:49:56.101+0000] {processor.py:842} WARNING - No viable dags retrieved from /opt/airflow/dags/ingestion_dag.py
[2024-06-27T23:49:56.142+0000] {processor.py:183} INFO - Processing /opt/airflow/dags/ingestion_dag.py took 0.075 seconds
[2024-06-27T23:50:26.751+0000] {processor.py:161} INFO - Started process (PID=8754) to work on /opt/airflow/dags/ingestion_dag.py
[2024-06-27T23:50:26.755+0000] {processor.py:830} INFO - Processing file /opt/airflow/dags/ingestion_dag.py for tasks to queue
[2024-06-27T23:50:26.760+0000] {logging_mixin.py:188} INFO - [2024-06-27T23:50:26.759+0000] {dagbag.py:545} INFO - Filling up the DagBag from /opt/airflow/dags/ingestion_dag.py
[2024-06-27T23:50:26.770+0000] {logging_mixin.py:188} INFO - [2024-06-27T23:50:26.766+0000] {dagbag.py:355} ERROR - Failed to import: /opt/airflow/dags/ingestion_dag.py
Traceback (most recent call last):
  File "/home/airflow/.local/lib/python3.11/site-packages/airflow/models/dagbag.py", line 351, in parse
    loader.exec_module(new_module)
  File "<frozen importlib._bootstrap_external>", line 940, in exec_module
  File "<frozen importlib._bootstrap>", line 241, in _call_with_frames_removed
  File "/opt/airflow/dags/ingestion_dag.py", line 20, in <module>
    SERVICE_ACCOUNT_CREDENTIALS = service_account.Credentials.from_service_account_file(
                                  ^^^^^^^^^^^^^^^^^^^^^^^^^^^^^^^^^^^^^^^^^^^^^^^^^^^^^^
  File "/home/airflow/.local/lib/python3.11/site-packages/google/oauth2/service_account.py", line 258, in from_service_account_file
    info, signer = _service_account_info.from_filename(
                   ^^^^^^^^^^^^^^^^^^^^^^^^^^^^^^^^^^^^
  File "/home/airflow/.local/lib/python3.11/site-packages/google/auth/_service_account_info.py", line 78, in from_filename
    with io.open(filename, "r", encoding="utf-8") as json_file:
         ^^^^^^^^^^^^^^^^^^^^^^^^^^^^^^^^^^^^^^^^
FileNotFoundError: [Errno 2] No such file or directory: '/.gc/my-creds.json'
[2024-06-27T23:50:26.771+0000] {processor.py:842} WARNING - No viable dags retrieved from /opt/airflow/dags/ingestion_dag.py
[2024-06-27T23:50:26.811+0000] {processor.py:183} INFO - Processing /opt/airflow/dags/ingestion_dag.py took 0.077 seconds
[2024-06-27T23:50:57.489+0000] {processor.py:161} INFO - Started process (PID=8815) to work on /opt/airflow/dags/ingestion_dag.py
[2024-06-27T23:50:57.491+0000] {processor.py:830} INFO - Processing file /opt/airflow/dags/ingestion_dag.py for tasks to queue
[2024-06-27T23:50:57.496+0000] {logging_mixin.py:188} INFO - [2024-06-27T23:50:57.495+0000] {dagbag.py:545} INFO - Filling up the DagBag from /opt/airflow/dags/ingestion_dag.py
[2024-06-27T23:50:57.504+0000] {logging_mixin.py:188} INFO - [2024-06-27T23:50:57.501+0000] {dagbag.py:355} ERROR - Failed to import: /opt/airflow/dags/ingestion_dag.py
Traceback (most recent call last):
  File "/home/airflow/.local/lib/python3.11/site-packages/airflow/models/dagbag.py", line 351, in parse
    loader.exec_module(new_module)
  File "<frozen importlib._bootstrap_external>", line 940, in exec_module
  File "<frozen importlib._bootstrap>", line 241, in _call_with_frames_removed
  File "/opt/airflow/dags/ingestion_dag.py", line 20, in <module>
    SERVICE_ACCOUNT_CREDENTIALS = service_account.Credentials.from_service_account_file(
                                  ^^^^^^^^^^^^^^^^^^^^^^^^^^^^^^^^^^^^^^^^^^^^^^^^^^^^^^
  File "/home/airflow/.local/lib/python3.11/site-packages/google/oauth2/service_account.py", line 258, in from_service_account_file
    info, signer = _service_account_info.from_filename(
                   ^^^^^^^^^^^^^^^^^^^^^^^^^^^^^^^^^^^^
  File "/home/airflow/.local/lib/python3.11/site-packages/google/auth/_service_account_info.py", line 78, in from_filename
    with io.open(filename, "r", encoding="utf-8") as json_file:
         ^^^^^^^^^^^^^^^^^^^^^^^^^^^^^^^^^^^^^^^^
FileNotFoundError: [Errno 2] No such file or directory: '/.gc/my-creds.json'
[2024-06-27T23:50:57.505+0000] {processor.py:842} WARNING - No viable dags retrieved from /opt/airflow/dags/ingestion_dag.py
[2024-06-27T23:50:57.539+0000] {processor.py:183} INFO - Processing /opt/airflow/dags/ingestion_dag.py took 0.065 seconds
[2024-06-27T23:51:27.865+0000] {processor.py:161} INFO - Started process (PID=8872) to work on /opt/airflow/dags/ingestion_dag.py
[2024-06-27T23:51:27.867+0000] {processor.py:830} INFO - Processing file /opt/airflow/dags/ingestion_dag.py for tasks to queue
[2024-06-27T23:51:27.871+0000] {logging_mixin.py:188} INFO - [2024-06-27T23:51:27.871+0000] {dagbag.py:545} INFO - Filling up the DagBag from /opt/airflow/dags/ingestion_dag.py
[2024-06-27T23:51:27.880+0000] {logging_mixin.py:188} INFO - [2024-06-27T23:51:27.878+0000] {dagbag.py:355} ERROR - Failed to import: /opt/airflow/dags/ingestion_dag.py
Traceback (most recent call last):
  File "/home/airflow/.local/lib/python3.11/site-packages/airflow/models/dagbag.py", line 351, in parse
    loader.exec_module(new_module)
  File "<frozen importlib._bootstrap_external>", line 940, in exec_module
  File "<frozen importlib._bootstrap>", line 241, in _call_with_frames_removed
  File "/opt/airflow/dags/ingestion_dag.py", line 20, in <module>
    SERVICE_ACCOUNT_CREDENTIALS = service_account.Credentials.from_service_account_file(
                                  ^^^^^^^^^^^^^^^^^^^^^^^^^^^^^^^^^^^^^^^^^^^^^^^^^^^^^^
  File "/home/airflow/.local/lib/python3.11/site-packages/google/oauth2/service_account.py", line 258, in from_service_account_file
    info, signer = _service_account_info.from_filename(
                   ^^^^^^^^^^^^^^^^^^^^^^^^^^^^^^^^^^^^
  File "/home/airflow/.local/lib/python3.11/site-packages/google/auth/_service_account_info.py", line 78, in from_filename
    with io.open(filename, "r", encoding="utf-8") as json_file:
         ^^^^^^^^^^^^^^^^^^^^^^^^^^^^^^^^^^^^^^^^
FileNotFoundError: [Errno 2] No such file or directory: '/.gc/my-creds.json'
[2024-06-27T23:51:27.882+0000] {processor.py:842} WARNING - No viable dags retrieved from /opt/airflow/dags/ingestion_dag.py
[2024-06-27T23:51:27.918+0000] {processor.py:183} INFO - Processing /opt/airflow/dags/ingestion_dag.py took 0.067 seconds
[2024-06-27T23:51:58.259+0000] {processor.py:161} INFO - Started process (PID=8934) to work on /opt/airflow/dags/ingestion_dag.py
[2024-06-27T23:51:58.263+0000] {processor.py:830} INFO - Processing file /opt/airflow/dags/ingestion_dag.py for tasks to queue
[2024-06-27T23:51:58.273+0000] {logging_mixin.py:188} INFO - [2024-06-27T23:51:58.269+0000] {dagbag.py:545} INFO - Filling up the DagBag from /opt/airflow/dags/ingestion_dag.py
[2024-06-27T23:51:58.283+0000] {logging_mixin.py:188} INFO - [2024-06-27T23:51:58.280+0000] {dagbag.py:355} ERROR - Failed to import: /opt/airflow/dags/ingestion_dag.py
Traceback (most recent call last):
  File "/home/airflow/.local/lib/python3.11/site-packages/airflow/models/dagbag.py", line 351, in parse
    loader.exec_module(new_module)
  File "<frozen importlib._bootstrap_external>", line 940, in exec_module
  File "<frozen importlib._bootstrap>", line 241, in _call_with_frames_removed
  File "/opt/airflow/dags/ingestion_dag.py", line 20, in <module>
    SERVICE_ACCOUNT_CREDENTIALS = service_account.Credentials.from_service_account_file(
                                  ^^^^^^^^^^^^^^^^^^^^^^^^^^^^^^^^^^^^^^^^^^^^^^^^^^^^^^
  File "/home/airflow/.local/lib/python3.11/site-packages/google/oauth2/service_account.py", line 258, in from_service_account_file
    info, signer = _service_account_info.from_filename(
                   ^^^^^^^^^^^^^^^^^^^^^^^^^^^^^^^^^^^^
  File "/home/airflow/.local/lib/python3.11/site-packages/google/auth/_service_account_info.py", line 78, in from_filename
    with io.open(filename, "r", encoding="utf-8") as json_file:
         ^^^^^^^^^^^^^^^^^^^^^^^^^^^^^^^^^^^^^^^^
FileNotFoundError: [Errno 2] No such file or directory: '/.gc/my-creds.json'
[2024-06-27T23:51:58.285+0000] {processor.py:842} WARNING - No viable dags retrieved from /opt/airflow/dags/ingestion_dag.py
[2024-06-27T23:51:58.333+0000] {processor.py:183} INFO - Processing /opt/airflow/dags/ingestion_dag.py took 0.088 seconds
[2024-06-27T23:52:28.498+0000] {processor.py:161} INFO - Started process (PID=8996) to work on /opt/airflow/dags/ingestion_dag.py
[2024-06-27T23:52:28.501+0000] {processor.py:830} INFO - Processing file /opt/airflow/dags/ingestion_dag.py for tasks to queue
[2024-06-27T23:52:28.507+0000] {logging_mixin.py:188} INFO - [2024-06-27T23:52:28.504+0000] {dagbag.py:545} INFO - Filling up the DagBag from /opt/airflow/dags/ingestion_dag.py
[2024-06-27T23:52:28.514+0000] {logging_mixin.py:188} INFO - [2024-06-27T23:52:28.511+0000] {dagbag.py:355} ERROR - Failed to import: /opt/airflow/dags/ingestion_dag.py
Traceback (most recent call last):
  File "/home/airflow/.local/lib/python3.11/site-packages/airflow/models/dagbag.py", line 351, in parse
    loader.exec_module(new_module)
  File "<frozen importlib._bootstrap_external>", line 940, in exec_module
  File "<frozen importlib._bootstrap>", line 241, in _call_with_frames_removed
  File "/opt/airflow/dags/ingestion_dag.py", line 20, in <module>
    SERVICE_ACCOUNT_CREDENTIALS = service_account.Credentials.from_service_account_file(
                                  ^^^^^^^^^^^^^^^^^^^^^^^^^^^^^^^^^^^^^^^^^^^^^^^^^^^^^^
  File "/home/airflow/.local/lib/python3.11/site-packages/google/oauth2/service_account.py", line 258, in from_service_account_file
    info, signer = _service_account_info.from_filename(
                   ^^^^^^^^^^^^^^^^^^^^^^^^^^^^^^^^^^^^
  File "/home/airflow/.local/lib/python3.11/site-packages/google/auth/_service_account_info.py", line 78, in from_filename
    with io.open(filename, "r", encoding="utf-8") as json_file:
         ^^^^^^^^^^^^^^^^^^^^^^^^^^^^^^^^^^^^^^^^
FileNotFoundError: [Errno 2] No such file or directory: '/.gc/my-creds.json'
[2024-06-27T23:52:28.515+0000] {processor.py:842} WARNING - No viable dags retrieved from /opt/airflow/dags/ingestion_dag.py
[2024-06-27T23:52:28.555+0000] {processor.py:183} INFO - Processing /opt/airflow/dags/ingestion_dag.py took 0.071 seconds
[2024-06-27T23:52:58.809+0000] {processor.py:161} INFO - Started process (PID=9058) to work on /opt/airflow/dags/ingestion_dag.py
[2024-06-27T23:52:58.811+0000] {processor.py:830} INFO - Processing file /opt/airflow/dags/ingestion_dag.py for tasks to queue
[2024-06-27T23:52:58.815+0000] {logging_mixin.py:188} INFO - [2024-06-27T23:52:58.815+0000] {dagbag.py:545} INFO - Filling up the DagBag from /opt/airflow/dags/ingestion_dag.py
[2024-06-27T23:52:58.824+0000] {logging_mixin.py:188} INFO - [2024-06-27T23:52:58.822+0000] {dagbag.py:355} ERROR - Failed to import: /opt/airflow/dags/ingestion_dag.py
Traceback (most recent call last):
  File "/home/airflow/.local/lib/python3.11/site-packages/airflow/models/dagbag.py", line 351, in parse
    loader.exec_module(new_module)
  File "<frozen importlib._bootstrap_external>", line 940, in exec_module
  File "<frozen importlib._bootstrap>", line 241, in _call_with_frames_removed
  File "/opt/airflow/dags/ingestion_dag.py", line 20, in <module>
    SERVICE_ACCOUNT_CREDENTIALS = service_account.Credentials.from_service_account_file(
                                  ^^^^^^^^^^^^^^^^^^^^^^^^^^^^^^^^^^^^^^^^^^^^^^^^^^^^^^
  File "/home/airflow/.local/lib/python3.11/site-packages/google/oauth2/service_account.py", line 258, in from_service_account_file
    info, signer = _service_account_info.from_filename(
                   ^^^^^^^^^^^^^^^^^^^^^^^^^^^^^^^^^^^^
  File "/home/airflow/.local/lib/python3.11/site-packages/google/auth/_service_account_info.py", line 78, in from_filename
    with io.open(filename, "r", encoding="utf-8") as json_file:
         ^^^^^^^^^^^^^^^^^^^^^^^^^^^^^^^^^^^^^^^^
FileNotFoundError: [Errno 2] No such file or directory: '/.gc/my-creds.json'
[2024-06-27T23:52:58.825+0000] {processor.py:842} WARNING - No viable dags retrieved from /opt/airflow/dags/ingestion_dag.py
[2024-06-27T23:52:58.860+0000] {processor.py:183} INFO - Processing /opt/airflow/dags/ingestion_dag.py took 0.065 seconds
[2024-06-27T23:53:29.687+0000] {processor.py:161} INFO - Started process (PID=9120) to work on /opt/airflow/dags/ingestion_dag.py
[2024-06-27T23:53:29.690+0000] {processor.py:830} INFO - Processing file /opt/airflow/dags/ingestion_dag.py for tasks to queue
[2024-06-27T23:53:29.696+0000] {logging_mixin.py:188} INFO - [2024-06-27T23:53:29.695+0000] {dagbag.py:545} INFO - Filling up the DagBag from /opt/airflow/dags/ingestion_dag.py
[2024-06-27T23:53:29.703+0000] {logging_mixin.py:188} INFO - [2024-06-27T23:53:29.700+0000] {dagbag.py:355} ERROR - Failed to import: /opt/airflow/dags/ingestion_dag.py
Traceback (most recent call last):
  File "/home/airflow/.local/lib/python3.11/site-packages/airflow/models/dagbag.py", line 351, in parse
    loader.exec_module(new_module)
  File "<frozen importlib._bootstrap_external>", line 940, in exec_module
  File "<frozen importlib._bootstrap>", line 241, in _call_with_frames_removed
  File "/opt/airflow/dags/ingestion_dag.py", line 20, in <module>
    SERVICE_ACCOUNT_CREDENTIALS = service_account.Credentials.from_service_account_file(
                                  ^^^^^^^^^^^^^^^^^^^^^^^^^^^^^^^^^^^^^^^^^^^^^^^^^^^^^^
  File "/home/airflow/.local/lib/python3.11/site-packages/google/oauth2/service_account.py", line 258, in from_service_account_file
    info, signer = _service_account_info.from_filename(
                   ^^^^^^^^^^^^^^^^^^^^^^^^^^^^^^^^^^^^
  File "/home/airflow/.local/lib/python3.11/site-packages/google/auth/_service_account_info.py", line 78, in from_filename
    with io.open(filename, "r", encoding="utf-8") as json_file:
         ^^^^^^^^^^^^^^^^^^^^^^^^^^^^^^^^^^^^^^^^
FileNotFoundError: [Errno 2] No such file or directory: '/.gc/my-creds.json'
[2024-06-27T23:53:29.704+0000] {processor.py:842} WARNING - No viable dags retrieved from /opt/airflow/dags/ingestion_dag.py
[2024-06-27T23:53:29.743+0000] {processor.py:183} INFO - Processing /opt/airflow/dags/ingestion_dag.py took 0.070 seconds
[2024-06-27T23:54:00.466+0000] {processor.py:161} INFO - Started process (PID=9182) to work on /opt/airflow/dags/ingestion_dag.py
[2024-06-27T23:54:00.469+0000] {processor.py:830} INFO - Processing file /opt/airflow/dags/ingestion_dag.py for tasks to queue
[2024-06-27T23:54:00.473+0000] {logging_mixin.py:188} INFO - [2024-06-27T23:54:00.472+0000] {dagbag.py:545} INFO - Filling up the DagBag from /opt/airflow/dags/ingestion_dag.py
[2024-06-27T23:54:00.482+0000] {logging_mixin.py:188} INFO - [2024-06-27T23:54:00.479+0000] {dagbag.py:355} ERROR - Failed to import: /opt/airflow/dags/ingestion_dag.py
Traceback (most recent call last):
  File "/home/airflow/.local/lib/python3.11/site-packages/airflow/models/dagbag.py", line 351, in parse
    loader.exec_module(new_module)
  File "<frozen importlib._bootstrap_external>", line 940, in exec_module
  File "<frozen importlib._bootstrap>", line 241, in _call_with_frames_removed
  File "/opt/airflow/dags/ingestion_dag.py", line 20, in <module>
    SERVICE_ACCOUNT_CREDENTIALS = service_account.Credentials.from_service_account_file(
                                  ^^^^^^^^^^^^^^^^^^^^^^^^^^^^^^^^^^^^^^^^^^^^^^^^^^^^^^
  File "/home/airflow/.local/lib/python3.11/site-packages/google/oauth2/service_account.py", line 258, in from_service_account_file
    info, signer = _service_account_info.from_filename(
                   ^^^^^^^^^^^^^^^^^^^^^^^^^^^^^^^^^^^^
  File "/home/airflow/.local/lib/python3.11/site-packages/google/auth/_service_account_info.py", line 78, in from_filename
    with io.open(filename, "r", encoding="utf-8") as json_file:
         ^^^^^^^^^^^^^^^^^^^^^^^^^^^^^^^^^^^^^^^^
FileNotFoundError: [Errno 2] No such file or directory: '/.gc/my-creds.json'
[2024-06-27T23:54:00.483+0000] {processor.py:842} WARNING - No viable dags retrieved from /opt/airflow/dags/ingestion_dag.py
[2024-06-27T23:54:00.519+0000] {processor.py:183} INFO - Processing /opt/airflow/dags/ingestion_dag.py took 0.066 seconds
[2024-06-27T23:54:31.163+0000] {processor.py:161} INFO - Started process (PID=9243) to work on /opt/airflow/dags/ingestion_dag.py
[2024-06-27T23:54:31.166+0000] {processor.py:830} INFO - Processing file /opt/airflow/dags/ingestion_dag.py for tasks to queue
[2024-06-27T23:54:31.171+0000] {logging_mixin.py:188} INFO - [2024-06-27T23:54:31.169+0000] {dagbag.py:545} INFO - Filling up the DagBag from /opt/airflow/dags/ingestion_dag.py
[2024-06-27T23:54:31.178+0000] {logging_mixin.py:188} INFO - [2024-06-27T23:54:31.176+0000] {dagbag.py:355} ERROR - Failed to import: /opt/airflow/dags/ingestion_dag.py
Traceback (most recent call last):
  File "/home/airflow/.local/lib/python3.11/site-packages/airflow/models/dagbag.py", line 351, in parse
    loader.exec_module(new_module)
  File "<frozen importlib._bootstrap_external>", line 940, in exec_module
  File "<frozen importlib._bootstrap>", line 241, in _call_with_frames_removed
  File "/opt/airflow/dags/ingestion_dag.py", line 20, in <module>
    SERVICE_ACCOUNT_CREDENTIALS = service_account.Credentials.from_service_account_file(
                                  ^^^^^^^^^^^^^^^^^^^^^^^^^^^^^^^^^^^^^^^^^^^^^^^^^^^^^^
  File "/home/airflow/.local/lib/python3.11/site-packages/google/oauth2/service_account.py", line 258, in from_service_account_file
    info, signer = _service_account_info.from_filename(
                   ^^^^^^^^^^^^^^^^^^^^^^^^^^^^^^^^^^^^
  File "/home/airflow/.local/lib/python3.11/site-packages/google/auth/_service_account_info.py", line 78, in from_filename
    with io.open(filename, "r", encoding="utf-8") as json_file:
         ^^^^^^^^^^^^^^^^^^^^^^^^^^^^^^^^^^^^^^^^
FileNotFoundError: [Errno 2] No such file or directory: '/.gc/my-creds.json'
[2024-06-27T23:54:31.180+0000] {processor.py:842} WARNING - No viable dags retrieved from /opt/airflow/dags/ingestion_dag.py
[2024-06-27T23:54:31.220+0000] {processor.py:183} INFO - Processing /opt/airflow/dags/ingestion_dag.py took 0.070 seconds
[2024-06-27T23:55:02.033+0000] {processor.py:161} INFO - Started process (PID=9304) to work on /opt/airflow/dags/ingestion_dag.py
[2024-06-27T23:55:02.036+0000] {processor.py:830} INFO - Processing file /opt/airflow/dags/ingestion_dag.py for tasks to queue
[2024-06-27T23:55:02.040+0000] {logging_mixin.py:188} INFO - [2024-06-27T23:55:02.040+0000] {dagbag.py:545} INFO - Filling up the DagBag from /opt/airflow/dags/ingestion_dag.py
[2024-06-27T23:55:02.050+0000] {logging_mixin.py:188} INFO - [2024-06-27T23:55:02.047+0000] {dagbag.py:355} ERROR - Failed to import: /opt/airflow/dags/ingestion_dag.py
Traceback (most recent call last):
  File "/home/airflow/.local/lib/python3.11/site-packages/airflow/models/dagbag.py", line 351, in parse
    loader.exec_module(new_module)
  File "<frozen importlib._bootstrap_external>", line 940, in exec_module
  File "<frozen importlib._bootstrap>", line 241, in _call_with_frames_removed
  File "/opt/airflow/dags/ingestion_dag.py", line 20, in <module>
    SERVICE_ACCOUNT_CREDENTIALS = service_account.Credentials.from_service_account_file(
                                  ^^^^^^^^^^^^^^^^^^^^^^^^^^^^^^^^^^^^^^^^^^^^^^^^^^^^^^
  File "/home/airflow/.local/lib/python3.11/site-packages/google/oauth2/service_account.py", line 258, in from_service_account_file
    info, signer = _service_account_info.from_filename(
                   ^^^^^^^^^^^^^^^^^^^^^^^^^^^^^^^^^^^^
  File "/home/airflow/.local/lib/python3.11/site-packages/google/auth/_service_account_info.py", line 78, in from_filename
    with io.open(filename, "r", encoding="utf-8") as json_file:
         ^^^^^^^^^^^^^^^^^^^^^^^^^^^^^^^^^^^^^^^^
FileNotFoundError: [Errno 2] No such file or directory: '/.gc/my-creds.json'
[2024-06-27T23:55:02.051+0000] {processor.py:842} WARNING - No viable dags retrieved from /opt/airflow/dags/ingestion_dag.py
[2024-06-27T23:55:02.089+0000] {processor.py:183} INFO - Processing /opt/airflow/dags/ingestion_dag.py took 0.069 seconds
[2024-06-27T23:55:33.066+0000] {processor.py:161} INFO - Started process (PID=9366) to work on /opt/airflow/dags/ingestion_dag.py
[2024-06-27T23:55:33.069+0000] {processor.py:830} INFO - Processing file /opt/airflow/dags/ingestion_dag.py for tasks to queue
[2024-06-27T23:55:33.073+0000] {logging_mixin.py:188} INFO - [2024-06-27T23:55:33.072+0000] {dagbag.py:545} INFO - Filling up the DagBag from /opt/airflow/dags/ingestion_dag.py
[2024-06-27T23:55:33.082+0000] {logging_mixin.py:188} INFO - [2024-06-27T23:55:33.080+0000] {dagbag.py:355} ERROR - Failed to import: /opt/airflow/dags/ingestion_dag.py
Traceback (most recent call last):
  File "/home/airflow/.local/lib/python3.11/site-packages/airflow/models/dagbag.py", line 351, in parse
    loader.exec_module(new_module)
  File "<frozen importlib._bootstrap_external>", line 940, in exec_module
  File "<frozen importlib._bootstrap>", line 241, in _call_with_frames_removed
  File "/opt/airflow/dags/ingestion_dag.py", line 20, in <module>
    SERVICE_ACCOUNT_CREDENTIALS = service_account.Credentials.from_service_account_file(
                                  ^^^^^^^^^^^^^^^^^^^^^^^^^^^^^^^^^^^^^^^^^^^^^^^^^^^^^^
  File "/home/airflow/.local/lib/python3.11/site-packages/google/oauth2/service_account.py", line 258, in from_service_account_file
    info, signer = _service_account_info.from_filename(
                   ^^^^^^^^^^^^^^^^^^^^^^^^^^^^^^^^^^^^
  File "/home/airflow/.local/lib/python3.11/site-packages/google/auth/_service_account_info.py", line 78, in from_filename
    with io.open(filename, "r", encoding="utf-8") as json_file:
         ^^^^^^^^^^^^^^^^^^^^^^^^^^^^^^^^^^^^^^^^
FileNotFoundError: [Errno 2] No such file or directory: '/.gc/my-creds.json'
[2024-06-27T23:55:33.084+0000] {processor.py:842} WARNING - No viable dags retrieved from /opt/airflow/dags/ingestion_dag.py
[2024-06-27T23:55:33.124+0000] {processor.py:183} INFO - Processing /opt/airflow/dags/ingestion_dag.py took 0.071 seconds
[2024-06-27T23:56:03.756+0000] {processor.py:161} INFO - Started process (PID=9428) to work on /opt/airflow/dags/ingestion_dag.py
[2024-06-27T23:56:03.758+0000] {processor.py:830} INFO - Processing file /opt/airflow/dags/ingestion_dag.py for tasks to queue
[2024-06-27T23:56:03.763+0000] {logging_mixin.py:188} INFO - [2024-06-27T23:56:03.762+0000] {dagbag.py:545} INFO - Filling up the DagBag from /opt/airflow/dags/ingestion_dag.py
[2024-06-27T23:56:03.777+0000] {logging_mixin.py:188} INFO - [2024-06-27T23:56:03.773+0000] {dagbag.py:355} ERROR - Failed to import: /opt/airflow/dags/ingestion_dag.py
Traceback (most recent call last):
  File "/home/airflow/.local/lib/python3.11/site-packages/airflow/models/dagbag.py", line 351, in parse
    loader.exec_module(new_module)
  File "<frozen importlib._bootstrap_external>", line 940, in exec_module
  File "<frozen importlib._bootstrap>", line 241, in _call_with_frames_removed
  File "/opt/airflow/dags/ingestion_dag.py", line 20, in <module>
    SERVICE_ACCOUNT_CREDENTIALS = service_account.Credentials.from_service_account_file(
                                  ^^^^^^^^^^^^^^^^^^^^^^^^^^^^^^^^^^^^^^^^^^^^^^^^^^^^^^
  File "/home/airflow/.local/lib/python3.11/site-packages/google/oauth2/service_account.py", line 258, in from_service_account_file
    info, signer = _service_account_info.from_filename(
                   ^^^^^^^^^^^^^^^^^^^^^^^^^^^^^^^^^^^^
  File "/home/airflow/.local/lib/python3.11/site-packages/google/auth/_service_account_info.py", line 78, in from_filename
    with io.open(filename, "r", encoding="utf-8") as json_file:
         ^^^^^^^^^^^^^^^^^^^^^^^^^^^^^^^^^^^^^^^^
FileNotFoundError: [Errno 2] No such file or directory: '/.gc/my-creds.json'
[2024-06-27T23:56:03.779+0000] {processor.py:842} WARNING - No viable dags retrieved from /opt/airflow/dags/ingestion_dag.py
[2024-06-27T23:56:03.825+0000] {processor.py:183} INFO - Processing /opt/airflow/dags/ingestion_dag.py took 0.082 seconds
[2024-06-27T23:56:34.558+0000] {processor.py:161} INFO - Started process (PID=9491) to work on /opt/airflow/dags/ingestion_dag.py
[2024-06-27T23:56:34.563+0000] {processor.py:830} INFO - Processing file /opt/airflow/dags/ingestion_dag.py for tasks to queue
[2024-06-27T23:56:34.570+0000] {logging_mixin.py:188} INFO - [2024-06-27T23:56:34.569+0000] {dagbag.py:545} INFO - Filling up the DagBag from /opt/airflow/dags/ingestion_dag.py
[2024-06-27T23:56:34.578+0000] {logging_mixin.py:188} INFO - [2024-06-27T23:56:34.575+0000] {dagbag.py:355} ERROR - Failed to import: /opt/airflow/dags/ingestion_dag.py
Traceback (most recent call last):
  File "/home/airflow/.local/lib/python3.11/site-packages/airflow/models/dagbag.py", line 351, in parse
    loader.exec_module(new_module)
  File "<frozen importlib._bootstrap_external>", line 940, in exec_module
  File "<frozen importlib._bootstrap>", line 241, in _call_with_frames_removed
  File "/opt/airflow/dags/ingestion_dag.py", line 20, in <module>
    SERVICE_ACCOUNT_CREDENTIALS = service_account.Credentials.from_service_account_file(
                                  ^^^^^^^^^^^^^^^^^^^^^^^^^^^^^^^^^^^^^^^^^^^^^^^^^^^^^^
  File "/home/airflow/.local/lib/python3.11/site-packages/google/oauth2/service_account.py", line 258, in from_service_account_file
    info, signer = _service_account_info.from_filename(
                   ^^^^^^^^^^^^^^^^^^^^^^^^^^^^^^^^^^^^
  File "/home/airflow/.local/lib/python3.11/site-packages/google/auth/_service_account_info.py", line 78, in from_filename
    with io.open(filename, "r", encoding="utf-8") as json_file:
         ^^^^^^^^^^^^^^^^^^^^^^^^^^^^^^^^^^^^^^^^
FileNotFoundError: [Errno 2] No such file or directory: '/.gc/my-creds.json'
[2024-06-27T23:56:34.579+0000] {processor.py:842} WARNING - No viable dags retrieved from /opt/airflow/dags/ingestion_dag.py
[2024-06-27T23:56:34.624+0000] {processor.py:183} INFO - Processing /opt/airflow/dags/ingestion_dag.py took 0.079 seconds
[2024-06-27T23:57:05.462+0000] {processor.py:161} INFO - Started process (PID=9553) to work on /opt/airflow/dags/ingestion_dag.py
[2024-06-27T23:57:05.465+0000] {processor.py:830} INFO - Processing file /opt/airflow/dags/ingestion_dag.py for tasks to queue
[2024-06-27T23:57:05.469+0000] {logging_mixin.py:188} INFO - [2024-06-27T23:57:05.469+0000] {dagbag.py:545} INFO - Filling up the DagBag from /opt/airflow/dags/ingestion_dag.py
[2024-06-27T23:57:05.479+0000] {logging_mixin.py:188} INFO - [2024-06-27T23:57:05.476+0000] {dagbag.py:355} ERROR - Failed to import: /opt/airflow/dags/ingestion_dag.py
Traceback (most recent call last):
  File "/home/airflow/.local/lib/python3.11/site-packages/airflow/models/dagbag.py", line 351, in parse
    loader.exec_module(new_module)
  File "<frozen importlib._bootstrap_external>", line 940, in exec_module
  File "<frozen importlib._bootstrap>", line 241, in _call_with_frames_removed
  File "/opt/airflow/dags/ingestion_dag.py", line 20, in <module>
    SERVICE_ACCOUNT_CREDENTIALS = service_account.Credentials.from_service_account_file(
                                  ^^^^^^^^^^^^^^^^^^^^^^^^^^^^^^^^^^^^^^^^^^^^^^^^^^^^^^
  File "/home/airflow/.local/lib/python3.11/site-packages/google/oauth2/service_account.py", line 258, in from_service_account_file
    info, signer = _service_account_info.from_filename(
                   ^^^^^^^^^^^^^^^^^^^^^^^^^^^^^^^^^^^^
  File "/home/airflow/.local/lib/python3.11/site-packages/google/auth/_service_account_info.py", line 78, in from_filename
    with io.open(filename, "r", encoding="utf-8") as json_file:
         ^^^^^^^^^^^^^^^^^^^^^^^^^^^^^^^^^^^^^^^^
FileNotFoundError: [Errno 2] No such file or directory: '/.gc/my-creds.json'
[2024-06-27T23:57:05.481+0000] {processor.py:842} WARNING - No viable dags retrieved from /opt/airflow/dags/ingestion_dag.py
[2024-06-27T23:57:05.527+0000] {processor.py:183} INFO - Processing /opt/airflow/dags/ingestion_dag.py took 0.082 seconds
[2024-06-27T23:57:36.362+0000] {processor.py:161} INFO - Started process (PID=9615) to work on /opt/airflow/dags/ingestion_dag.py
[2024-06-27T23:57:36.364+0000] {processor.py:830} INFO - Processing file /opt/airflow/dags/ingestion_dag.py for tasks to queue
[2024-06-27T23:57:36.370+0000] {logging_mixin.py:188} INFO - [2024-06-27T23:57:36.369+0000] {dagbag.py:545} INFO - Filling up the DagBag from /opt/airflow/dags/ingestion_dag.py
[2024-06-27T23:57:36.382+0000] {logging_mixin.py:188} INFO - [2024-06-27T23:57:36.378+0000] {dagbag.py:355} ERROR - Failed to import: /opt/airflow/dags/ingestion_dag.py
Traceback (most recent call last):
  File "/home/airflow/.local/lib/python3.11/site-packages/airflow/models/dagbag.py", line 351, in parse
    loader.exec_module(new_module)
  File "<frozen importlib._bootstrap_external>", line 940, in exec_module
  File "<frozen importlib._bootstrap>", line 241, in _call_with_frames_removed
  File "/opt/airflow/dags/ingestion_dag.py", line 20, in <module>
    SERVICE_ACCOUNT_CREDENTIALS = service_account.Credentials.from_service_account_file(
                                  ^^^^^^^^^^^^^^^^^^^^^^^^^^^^^^^^^^^^^^^^^^^^^^^^^^^^^^
  File "/home/airflow/.local/lib/python3.11/site-packages/google/oauth2/service_account.py", line 258, in from_service_account_file
    info, signer = _service_account_info.from_filename(
                   ^^^^^^^^^^^^^^^^^^^^^^^^^^^^^^^^^^^^
  File "/home/airflow/.local/lib/python3.11/site-packages/google/auth/_service_account_info.py", line 78, in from_filename
    with io.open(filename, "r", encoding="utf-8") as json_file:
         ^^^^^^^^^^^^^^^^^^^^^^^^^^^^^^^^^^^^^^^^
FileNotFoundError: [Errno 2] No such file or directory: '/.gc/my-creds.json'
[2024-06-27T23:57:36.383+0000] {processor.py:842} WARNING - No viable dags retrieved from /opt/airflow/dags/ingestion_dag.py
[2024-06-27T23:57:36.418+0000] {processor.py:183} INFO - Processing /opt/airflow/dags/ingestion_dag.py took 0.069 seconds
[2024-06-27T23:58:07.415+0000] {processor.py:161} INFO - Started process (PID=9677) to work on /opt/airflow/dags/ingestion_dag.py
[2024-06-27T23:58:07.418+0000] {processor.py:830} INFO - Processing file /opt/airflow/dags/ingestion_dag.py for tasks to queue
[2024-06-27T23:58:07.422+0000] {logging_mixin.py:188} INFO - [2024-06-27T23:58:07.421+0000] {dagbag.py:545} INFO - Filling up the DagBag from /opt/airflow/dags/ingestion_dag.py
[2024-06-27T23:58:07.431+0000] {logging_mixin.py:188} INFO - [2024-06-27T23:58:07.428+0000] {dagbag.py:355} ERROR - Failed to import: /opt/airflow/dags/ingestion_dag.py
Traceback (most recent call last):
  File "/home/airflow/.local/lib/python3.11/site-packages/airflow/models/dagbag.py", line 351, in parse
    loader.exec_module(new_module)
  File "<frozen importlib._bootstrap_external>", line 940, in exec_module
  File "<frozen importlib._bootstrap>", line 241, in _call_with_frames_removed
  File "/opt/airflow/dags/ingestion_dag.py", line 20, in <module>
    SERVICE_ACCOUNT_CREDENTIALS = service_account.Credentials.from_service_account_file(
                                  ^^^^^^^^^^^^^^^^^^^^^^^^^^^^^^^^^^^^^^^^^^^^^^^^^^^^^^
  File "/home/airflow/.local/lib/python3.11/site-packages/google/oauth2/service_account.py", line 258, in from_service_account_file
    info, signer = _service_account_info.from_filename(
                   ^^^^^^^^^^^^^^^^^^^^^^^^^^^^^^^^^^^^
  File "/home/airflow/.local/lib/python3.11/site-packages/google/auth/_service_account_info.py", line 78, in from_filename
    with io.open(filename, "r", encoding="utf-8") as json_file:
         ^^^^^^^^^^^^^^^^^^^^^^^^^^^^^^^^^^^^^^^^
FileNotFoundError: [Errno 2] No such file or directory: '/.gc/my-creds.json'
[2024-06-27T23:58:07.433+0000] {processor.py:842} WARNING - No viable dags retrieved from /opt/airflow/dags/ingestion_dag.py
[2024-06-27T23:58:07.472+0000] {processor.py:183} INFO - Processing /opt/airflow/dags/ingestion_dag.py took 0.070 seconds
[2024-06-27T23:58:38.069+0000] {processor.py:161} INFO - Started process (PID=9739) to work on /opt/airflow/dags/ingestion_dag.py
[2024-06-27T23:58:38.071+0000] {processor.py:830} INFO - Processing file /opt/airflow/dags/ingestion_dag.py for tasks to queue
[2024-06-27T23:58:38.075+0000] {logging_mixin.py:188} INFO - [2024-06-27T23:58:38.075+0000] {dagbag.py:545} INFO - Filling up the DagBag from /opt/airflow/dags/ingestion_dag.py
[2024-06-27T23:58:38.084+0000] {logging_mixin.py:188} INFO - [2024-06-27T23:58:38.082+0000] {dagbag.py:355} ERROR - Failed to import: /opt/airflow/dags/ingestion_dag.py
Traceback (most recent call last):
  File "/home/airflow/.local/lib/python3.11/site-packages/airflow/models/dagbag.py", line 351, in parse
    loader.exec_module(new_module)
  File "<frozen importlib._bootstrap_external>", line 940, in exec_module
  File "<frozen importlib._bootstrap>", line 241, in _call_with_frames_removed
  File "/opt/airflow/dags/ingestion_dag.py", line 20, in <module>
    SERVICE_ACCOUNT_CREDENTIALS = service_account.Credentials.from_service_account_file(
                                  ^^^^^^^^^^^^^^^^^^^^^^^^^^^^^^^^^^^^^^^^^^^^^^^^^^^^^^
  File "/home/airflow/.local/lib/python3.11/site-packages/google/oauth2/service_account.py", line 258, in from_service_account_file
    info, signer = _service_account_info.from_filename(
                   ^^^^^^^^^^^^^^^^^^^^^^^^^^^^^^^^^^^^
  File "/home/airflow/.local/lib/python3.11/site-packages/google/auth/_service_account_info.py", line 78, in from_filename
    with io.open(filename, "r", encoding="utf-8") as json_file:
         ^^^^^^^^^^^^^^^^^^^^^^^^^^^^^^^^^^^^^^^^
FileNotFoundError: [Errno 2] No such file or directory: '/.gc/my-creds.json'
[2024-06-27T23:58:38.085+0000] {processor.py:842} WARNING - No viable dags retrieved from /opt/airflow/dags/ingestion_dag.py
[2024-06-27T23:58:38.120+0000] {processor.py:183} INFO - Processing /opt/airflow/dags/ingestion_dag.py took 0.064 seconds
[2024-06-27T23:59:08.551+0000] {processor.py:161} INFO - Started process (PID=9801) to work on /opt/airflow/dags/ingestion_dag.py
[2024-06-27T23:59:08.553+0000] {processor.py:830} INFO - Processing file /opt/airflow/dags/ingestion_dag.py for tasks to queue
[2024-06-27T23:59:08.557+0000] {logging_mixin.py:188} INFO - [2024-06-27T23:59:08.556+0000] {dagbag.py:545} INFO - Filling up the DagBag from /opt/airflow/dags/ingestion_dag.py
[2024-06-27T23:59:08.566+0000] {logging_mixin.py:188} INFO - [2024-06-27T23:59:08.563+0000] {dagbag.py:355} ERROR - Failed to import: /opt/airflow/dags/ingestion_dag.py
Traceback (most recent call last):
  File "/home/airflow/.local/lib/python3.11/site-packages/airflow/models/dagbag.py", line 351, in parse
    loader.exec_module(new_module)
  File "<frozen importlib._bootstrap_external>", line 940, in exec_module
  File "<frozen importlib._bootstrap>", line 241, in _call_with_frames_removed
  File "/opt/airflow/dags/ingestion_dag.py", line 20, in <module>
    SERVICE_ACCOUNT_CREDENTIALS = service_account.Credentials.from_service_account_file(
                                  ^^^^^^^^^^^^^^^^^^^^^^^^^^^^^^^^^^^^^^^^^^^^^^^^^^^^^^
  File "/home/airflow/.local/lib/python3.11/site-packages/google/oauth2/service_account.py", line 258, in from_service_account_file
    info, signer = _service_account_info.from_filename(
                   ^^^^^^^^^^^^^^^^^^^^^^^^^^^^^^^^^^^^
  File "/home/airflow/.local/lib/python3.11/site-packages/google/auth/_service_account_info.py", line 78, in from_filename
    with io.open(filename, "r", encoding="utf-8") as json_file:
         ^^^^^^^^^^^^^^^^^^^^^^^^^^^^^^^^^^^^^^^^
FileNotFoundError: [Errno 2] No such file or directory: '/.gc/my-creds.json'
[2024-06-27T23:59:08.567+0000] {processor.py:842} WARNING - No viable dags retrieved from /opt/airflow/dags/ingestion_dag.py
[2024-06-27T23:59:08.607+0000] {processor.py:183} INFO - Processing /opt/airflow/dags/ingestion_dag.py took 0.070 seconds
[2024-06-27T23:59:39.303+0000] {processor.py:161} INFO - Started process (PID=9863) to work on /opt/airflow/dags/ingestion_dag.py
[2024-06-27T23:59:39.305+0000] {processor.py:830} INFO - Processing file /opt/airflow/dags/ingestion_dag.py for tasks to queue
[2024-06-27T23:59:39.309+0000] {logging_mixin.py:188} INFO - [2024-06-27T23:59:39.309+0000] {dagbag.py:545} INFO - Filling up the DagBag from /opt/airflow/dags/ingestion_dag.py
[2024-06-27T23:59:39.318+0000] {logging_mixin.py:188} INFO - [2024-06-27T23:59:39.315+0000] {dagbag.py:355} ERROR - Failed to import: /opt/airflow/dags/ingestion_dag.py
Traceback (most recent call last):
  File "/home/airflow/.local/lib/python3.11/site-packages/airflow/models/dagbag.py", line 351, in parse
    loader.exec_module(new_module)
  File "<frozen importlib._bootstrap_external>", line 940, in exec_module
  File "<frozen importlib._bootstrap>", line 241, in _call_with_frames_removed
  File "/opt/airflow/dags/ingestion_dag.py", line 20, in <module>
    SERVICE_ACCOUNT_CREDENTIALS = service_account.Credentials.from_service_account_file(
                                  ^^^^^^^^^^^^^^^^^^^^^^^^^^^^^^^^^^^^^^^^^^^^^^^^^^^^^^
  File "/home/airflow/.local/lib/python3.11/site-packages/google/oauth2/service_account.py", line 258, in from_service_account_file
    info, signer = _service_account_info.from_filename(
                   ^^^^^^^^^^^^^^^^^^^^^^^^^^^^^^^^^^^^
  File "/home/airflow/.local/lib/python3.11/site-packages/google/auth/_service_account_info.py", line 78, in from_filename
    with io.open(filename, "r", encoding="utf-8") as json_file:
         ^^^^^^^^^^^^^^^^^^^^^^^^^^^^^^^^^^^^^^^^
FileNotFoundError: [Errno 2] No such file or directory: '/.gc/my-creds.json'
[2024-06-27T23:59:39.319+0000] {processor.py:842} WARNING - No viable dags retrieved from /opt/airflow/dags/ingestion_dag.py
[2024-06-27T23:59:39.354+0000] {processor.py:183} INFO - Processing /opt/airflow/dags/ingestion_dag.py took 0.063 seconds
