[2024-07-03T20:55:07.877+0000] {processor.py:161} INFO - Started process (PID=32) to work on /opt/airflow/dags/ingestion_dag.py
[2024-07-03T20:55:07.879+0000] {processor.py:830} INFO - Processing file /opt/airflow/dags/ingestion_dag.py for tasks to queue
[2024-07-03T20:55:07.892+0000] {logging_mixin.py:188} INFO - [2024-07-03T20:55:07.884+0000] {dagbag.py:545} INFO - Filling up the DagBag from /opt/airflow/dags/ingestion_dag.py
[2024-07-03T20:55:07.905+0000] {logging_mixin.py:188} INFO - [2024-07-03T20:55:07.896+0000] {dagbag.py:355} ERROR - Failed to import: /opt/airflow/dags/ingestion_dag.py
Traceback (most recent call last):
  File "/home/airflow/.local/lib/python3.11/site-packages/airflow/models/dagbag.py", line 351, in parse
    loader.exec_module(new_module)
  File "<frozen importlib._bootstrap_external>", line 940, in exec_module
  File "<frozen importlib._bootstrap>", line 241, in _call_with_frames_removed
  File "/opt/airflow/dags/ingestion_dag.py", line 20, in <module>
    SERVICE_ACCOUNT_CREDENTIALS = service_account.Credentials.from_service_account_file(
                                  ^^^^^^^^^^^^^^^^^^^^^^^^^^^^^^^^^^^^^^^^^^^^^^^^^^^^^^
  File "/home/airflow/.local/lib/python3.11/site-packages/google/oauth2/service_account.py", line 258, in from_service_account_file
    info, signer = _service_account_info.from_filename(
                   ^^^^^^^^^^^^^^^^^^^^^^^^^^^^^^^^^^^^
  File "/home/airflow/.local/lib/python3.11/site-packages/google/auth/_service_account_info.py", line 78, in from_filename
    with io.open(filename, "r", encoding="utf-8") as json_file:
         ^^^^^^^^^^^^^^^^^^^^^^^^^^^^^^^^^^^^^^^^
FileNotFoundError: [Errno 2] No such file or directory: '/.gc/my-creds.json'
[2024-07-03T20:55:07.907+0000] {processor.py:842} WARNING - No viable dags retrieved from /opt/airflow/dags/ingestion_dag.py
[2024-07-03T20:55:07.964+0000] {processor.py:183} INFO - Processing /opt/airflow/dags/ingestion_dag.py took 0.118 seconds
[2024-07-03T20:55:38.279+0000] {processor.py:161} INFO - Started process (PID=94) to work on /opt/airflow/dags/ingestion_dag.py
[2024-07-03T20:55:38.281+0000] {processor.py:830} INFO - Processing file /opt/airflow/dags/ingestion_dag.py for tasks to queue
[2024-07-03T20:55:38.285+0000] {logging_mixin.py:188} INFO - [2024-07-03T20:55:38.284+0000] {dagbag.py:545} INFO - Filling up the DagBag from /opt/airflow/dags/ingestion_dag.py
[2024-07-03T20:55:38.291+0000] {logging_mixin.py:188} INFO - [2024-07-03T20:55:38.288+0000] {dagbag.py:355} ERROR - Failed to import: /opt/airflow/dags/ingestion_dag.py
Traceback (most recent call last):
  File "/home/airflow/.local/lib/python3.11/site-packages/airflow/models/dagbag.py", line 351, in parse
    loader.exec_module(new_module)
  File "<frozen importlib._bootstrap_external>", line 940, in exec_module
  File "<frozen importlib._bootstrap>", line 241, in _call_with_frames_removed
  File "/opt/airflow/dags/ingestion_dag.py", line 20, in <module>
    SERVICE_ACCOUNT_CREDENTIALS = service_account.Credentials.from_service_account_file(
                                  ^^^^^^^^^^^^^^^^^^^^^^^^^^^^^^^^^^^^^^^^^^^^^^^^^^^^^^
  File "/home/airflow/.local/lib/python3.11/site-packages/google/oauth2/service_account.py", line 258, in from_service_account_file
    info, signer = _service_account_info.from_filename(
                   ^^^^^^^^^^^^^^^^^^^^^^^^^^^^^^^^^^^^
  File "/home/airflow/.local/lib/python3.11/site-packages/google/auth/_service_account_info.py", line 78, in from_filename
    with io.open(filename, "r", encoding="utf-8") as json_file:
         ^^^^^^^^^^^^^^^^^^^^^^^^^^^^^^^^^^^^^^^^
FileNotFoundError: [Errno 2] No such file or directory: '/.gc/my-creds.json'
[2024-07-03T20:55:38.292+0000] {processor.py:842} WARNING - No viable dags retrieved from /opt/airflow/dags/ingestion_dag.py
[2024-07-03T20:55:38.328+0000] {processor.py:183} INFO - Processing /opt/airflow/dags/ingestion_dag.py took 0.062 seconds
[2024-07-03T20:56:08.369+0000] {processor.py:161} INFO - Started process (PID=157) to work on /opt/airflow/dags/ingestion_dag.py
[2024-07-03T20:56:08.372+0000] {processor.py:830} INFO - Processing file /opt/airflow/dags/ingestion_dag.py for tasks to queue
[2024-07-03T20:56:08.375+0000] {logging_mixin.py:188} INFO - [2024-07-03T20:56:08.374+0000] {dagbag.py:545} INFO - Filling up the DagBag from /opt/airflow/dags/ingestion_dag.py
[2024-07-03T20:56:08.380+0000] {logging_mixin.py:188} INFO - [2024-07-03T20:56:08.378+0000] {dagbag.py:355} ERROR - Failed to import: /opt/airflow/dags/ingestion_dag.py
Traceback (most recent call last):
  File "/home/airflow/.local/lib/python3.11/site-packages/airflow/models/dagbag.py", line 351, in parse
    loader.exec_module(new_module)
  File "<frozen importlib._bootstrap_external>", line 940, in exec_module
  File "<frozen importlib._bootstrap>", line 241, in _call_with_frames_removed
  File "/opt/airflow/dags/ingestion_dag.py", line 20, in <module>
    SERVICE_ACCOUNT_CREDENTIALS = service_account.Credentials.from_service_account_file(
                                  ^^^^^^^^^^^^^^^^^^^^^^^^^^^^^^^^^^^^^^^^^^^^^^^^^^^^^^
  File "/home/airflow/.local/lib/python3.11/site-packages/google/oauth2/service_account.py", line 258, in from_service_account_file
    info, signer = _service_account_info.from_filename(
                   ^^^^^^^^^^^^^^^^^^^^^^^^^^^^^^^^^^^^
  File "/home/airflow/.local/lib/python3.11/site-packages/google/auth/_service_account_info.py", line 78, in from_filename
    with io.open(filename, "r", encoding="utf-8") as json_file:
         ^^^^^^^^^^^^^^^^^^^^^^^^^^^^^^^^^^^^^^^^
FileNotFoundError: [Errno 2] No such file or directory: '/.gc/my-creds.json'
[2024-07-03T20:56:08.381+0000] {processor.py:842} WARNING - No viable dags retrieved from /opt/airflow/dags/ingestion_dag.py
[2024-07-03T20:56:08.414+0000] {processor.py:183} INFO - Processing /opt/airflow/dags/ingestion_dag.py took 0.056 seconds
[2024-07-03T20:56:38.943+0000] {processor.py:161} INFO - Started process (PID=218) to work on /opt/airflow/dags/ingestion_dag.py
[2024-07-03T20:56:38.945+0000] {processor.py:830} INFO - Processing file /opt/airflow/dags/ingestion_dag.py for tasks to queue
[2024-07-03T20:56:38.949+0000] {logging_mixin.py:188} INFO - [2024-07-03T20:56:38.949+0000] {dagbag.py:545} INFO - Filling up the DagBag from /opt/airflow/dags/ingestion_dag.py
[2024-07-03T20:56:38.955+0000] {logging_mixin.py:188} INFO - [2024-07-03T20:56:38.953+0000] {dagbag.py:355} ERROR - Failed to import: /opt/airflow/dags/ingestion_dag.py
Traceback (most recent call last):
  File "/home/airflow/.local/lib/python3.11/site-packages/airflow/models/dagbag.py", line 351, in parse
    loader.exec_module(new_module)
  File "<frozen importlib._bootstrap_external>", line 940, in exec_module
  File "<frozen importlib._bootstrap>", line 241, in _call_with_frames_removed
  File "/opt/airflow/dags/ingestion_dag.py", line 20, in <module>
    SERVICE_ACCOUNT_CREDENTIALS = service_account.Credentials.from_service_account_file(
                                  ^^^^^^^^^^^^^^^^^^^^^^^^^^^^^^^^^^^^^^^^^^^^^^^^^^^^^^
  File "/home/airflow/.local/lib/python3.11/site-packages/google/oauth2/service_account.py", line 258, in from_service_account_file
    info, signer = _service_account_info.from_filename(
                   ^^^^^^^^^^^^^^^^^^^^^^^^^^^^^^^^^^^^
  File "/home/airflow/.local/lib/python3.11/site-packages/google/auth/_service_account_info.py", line 78, in from_filename
    with io.open(filename, "r", encoding="utf-8") as json_file:
         ^^^^^^^^^^^^^^^^^^^^^^^^^^^^^^^^^^^^^^^^
FileNotFoundError: [Errno 2] No such file or directory: '/.gc/my-creds.json'
[2024-07-03T20:56:38.955+0000] {processor.py:842} WARNING - No viable dags retrieved from /opt/airflow/dags/ingestion_dag.py
[2024-07-03T20:56:38.987+0000] {processor.py:183} INFO - Processing /opt/airflow/dags/ingestion_dag.py took 0.055 seconds
[2024-07-03T20:57:09.205+0000] {processor.py:161} INFO - Started process (PID=279) to work on /opt/airflow/dags/ingestion_dag.py
[2024-07-03T20:57:09.215+0000] {processor.py:830} INFO - Processing file /opt/airflow/dags/ingestion_dag.py for tasks to queue
[2024-07-03T20:57:09.219+0000] {logging_mixin.py:188} INFO - [2024-07-03T20:57:09.219+0000] {dagbag.py:545} INFO - Filling up the DagBag from /opt/airflow/dags/ingestion_dag.py
[2024-07-03T20:57:09.225+0000] {logging_mixin.py:188} INFO - [2024-07-03T20:57:09.223+0000] {dagbag.py:355} ERROR - Failed to import: /opt/airflow/dags/ingestion_dag.py
Traceback (most recent call last):
  File "/home/airflow/.local/lib/python3.11/site-packages/airflow/models/dagbag.py", line 351, in parse
    loader.exec_module(new_module)
  File "<frozen importlib._bootstrap_external>", line 940, in exec_module
  File "<frozen importlib._bootstrap>", line 241, in _call_with_frames_removed
  File "/opt/airflow/dags/ingestion_dag.py", line 20, in <module>
    SERVICE_ACCOUNT_CREDENTIALS = service_account.Credentials.from_service_account_file(
                                  ^^^^^^^^^^^^^^^^^^^^^^^^^^^^^^^^^^^^^^^^^^^^^^^^^^^^^^
  File "/home/airflow/.local/lib/python3.11/site-packages/google/oauth2/service_account.py", line 258, in from_service_account_file
    info, signer = _service_account_info.from_filename(
                   ^^^^^^^^^^^^^^^^^^^^^^^^^^^^^^^^^^^^
  File "/home/airflow/.local/lib/python3.11/site-packages/google/auth/_service_account_info.py", line 78, in from_filename
    with io.open(filename, "r", encoding="utf-8") as json_file:
         ^^^^^^^^^^^^^^^^^^^^^^^^^^^^^^^^^^^^^^^^
FileNotFoundError: [Errno 2] No such file or directory: '/.gc/my-creds.json'
[2024-07-03T20:57:09.225+0000] {processor.py:842} WARNING - No viable dags retrieved from /opt/airflow/dags/ingestion_dag.py
[2024-07-03T20:57:09.256+0000] {processor.py:183} INFO - Processing /opt/airflow/dags/ingestion_dag.py took 0.061 seconds
[2024-07-03T20:57:39.459+0000] {processor.py:161} INFO - Started process (PID=341) to work on /opt/airflow/dags/ingestion_dag.py
[2024-07-03T20:57:39.460+0000] {processor.py:830} INFO - Processing file /opt/airflow/dags/ingestion_dag.py for tasks to queue
[2024-07-03T20:57:39.463+0000] {logging_mixin.py:188} INFO - [2024-07-03T20:57:39.463+0000] {dagbag.py:545} INFO - Filling up the DagBag from /opt/airflow/dags/ingestion_dag.py
[2024-07-03T20:57:39.469+0000] {logging_mixin.py:188} INFO - [2024-07-03T20:57:39.467+0000] {dagbag.py:355} ERROR - Failed to import: /opt/airflow/dags/ingestion_dag.py
Traceback (most recent call last):
  File "/home/airflow/.local/lib/python3.11/site-packages/airflow/models/dagbag.py", line 351, in parse
    loader.exec_module(new_module)
  File "<frozen importlib._bootstrap_external>", line 940, in exec_module
  File "<frozen importlib._bootstrap>", line 241, in _call_with_frames_removed
  File "/opt/airflow/dags/ingestion_dag.py", line 20, in <module>
    SERVICE_ACCOUNT_CREDENTIALS = service_account.Credentials.from_service_account_file(
                                  ^^^^^^^^^^^^^^^^^^^^^^^^^^^^^^^^^^^^^^^^^^^^^^^^^^^^^^
  File "/home/airflow/.local/lib/python3.11/site-packages/google/oauth2/service_account.py", line 258, in from_service_account_file
    info, signer = _service_account_info.from_filename(
                   ^^^^^^^^^^^^^^^^^^^^^^^^^^^^^^^^^^^^
  File "/home/airflow/.local/lib/python3.11/site-packages/google/auth/_service_account_info.py", line 78, in from_filename
    with io.open(filename, "r", encoding="utf-8") as json_file:
         ^^^^^^^^^^^^^^^^^^^^^^^^^^^^^^^^^^^^^^^^
FileNotFoundError: [Errno 2] No such file or directory: '/.gc/my-creds.json'
[2024-07-03T20:57:39.470+0000] {processor.py:842} WARNING - No viable dags retrieved from /opt/airflow/dags/ingestion_dag.py
[2024-07-03T20:57:39.500+0000] {processor.py:183} INFO - Processing /opt/airflow/dags/ingestion_dag.py took 0.050 seconds
[2024-07-03T20:58:09.629+0000] {processor.py:161} INFO - Started process (PID=403) to work on /opt/airflow/dags/ingestion_dag.py
[2024-07-03T20:58:09.632+0000] {processor.py:830} INFO - Processing file /opt/airflow/dags/ingestion_dag.py for tasks to queue
[2024-07-03T20:58:09.636+0000] {logging_mixin.py:188} INFO - [2024-07-03T20:58:09.635+0000] {dagbag.py:545} INFO - Filling up the DagBag from /opt/airflow/dags/ingestion_dag.py
[2024-07-03T20:58:09.642+0000] {logging_mixin.py:188} INFO - [2024-07-03T20:58:09.640+0000] {dagbag.py:355} ERROR - Failed to import: /opt/airflow/dags/ingestion_dag.py
Traceback (most recent call last):
  File "/home/airflow/.local/lib/python3.11/site-packages/airflow/models/dagbag.py", line 351, in parse
    loader.exec_module(new_module)
  File "<frozen importlib._bootstrap_external>", line 940, in exec_module
  File "<frozen importlib._bootstrap>", line 241, in _call_with_frames_removed
  File "/opt/airflow/dags/ingestion_dag.py", line 20, in <module>
    SERVICE_ACCOUNT_CREDENTIALS = service_account.Credentials.from_service_account_file(
                                  ^^^^^^^^^^^^^^^^^^^^^^^^^^^^^^^^^^^^^^^^^^^^^^^^^^^^^^
  File "/home/airflow/.local/lib/python3.11/site-packages/google/oauth2/service_account.py", line 258, in from_service_account_file
    info, signer = _service_account_info.from_filename(
                   ^^^^^^^^^^^^^^^^^^^^^^^^^^^^^^^^^^^^
  File "/home/airflow/.local/lib/python3.11/site-packages/google/auth/_service_account_info.py", line 78, in from_filename
    with io.open(filename, "r", encoding="utf-8") as json_file:
         ^^^^^^^^^^^^^^^^^^^^^^^^^^^^^^^^^^^^^^^^
FileNotFoundError: [Errno 2] No such file or directory: '/.gc/my-creds.json'
[2024-07-03T20:58:09.643+0000] {processor.py:842} WARNING - No viable dags retrieved from /opt/airflow/dags/ingestion_dag.py
[2024-07-03T20:58:09.679+0000] {processor.py:183} INFO - Processing /opt/airflow/dags/ingestion_dag.py took 0.062 seconds
[2024-07-03T20:58:39.848+0000] {processor.py:161} INFO - Started process (PID=464) to work on /opt/airflow/dags/ingestion_dag.py
[2024-07-03T20:58:39.850+0000] {processor.py:830} INFO - Processing file /opt/airflow/dags/ingestion_dag.py for tasks to queue
[2024-07-03T20:58:39.854+0000] {logging_mixin.py:188} INFO - [2024-07-03T20:58:39.853+0000] {dagbag.py:545} INFO - Filling up the DagBag from /opt/airflow/dags/ingestion_dag.py
[2024-07-03T20:58:39.859+0000] {logging_mixin.py:188} INFO - [2024-07-03T20:58:39.857+0000] {dagbag.py:355} ERROR - Failed to import: /opt/airflow/dags/ingestion_dag.py
Traceback (most recent call last):
  File "/home/airflow/.local/lib/python3.11/site-packages/airflow/models/dagbag.py", line 351, in parse
    loader.exec_module(new_module)
  File "<frozen importlib._bootstrap_external>", line 940, in exec_module
  File "<frozen importlib._bootstrap>", line 241, in _call_with_frames_removed
  File "/opt/airflow/dags/ingestion_dag.py", line 20, in <module>
    SERVICE_ACCOUNT_CREDENTIALS = service_account.Credentials.from_service_account_file(
                                  ^^^^^^^^^^^^^^^^^^^^^^^^^^^^^^^^^^^^^^^^^^^^^^^^^^^^^^
  File "/home/airflow/.local/lib/python3.11/site-packages/google/oauth2/service_account.py", line 258, in from_service_account_file
    info, signer = _service_account_info.from_filename(
                   ^^^^^^^^^^^^^^^^^^^^^^^^^^^^^^^^^^^^
  File "/home/airflow/.local/lib/python3.11/site-packages/google/auth/_service_account_info.py", line 78, in from_filename
    with io.open(filename, "r", encoding="utf-8") as json_file:
         ^^^^^^^^^^^^^^^^^^^^^^^^^^^^^^^^^^^^^^^^
FileNotFoundError: [Errno 2] No such file or directory: '/.gc/my-creds.json'
[2024-07-03T20:58:39.860+0000] {processor.py:842} WARNING - No viable dags retrieved from /opt/airflow/dags/ingestion_dag.py
[2024-07-03T20:58:39.890+0000] {processor.py:183} INFO - Processing /opt/airflow/dags/ingestion_dag.py took 0.053 seconds
[2024-07-03T20:59:10.523+0000] {processor.py:161} INFO - Started process (PID=526) to work on /opt/airflow/dags/ingestion_dag.py
[2024-07-03T20:59:10.524+0000] {processor.py:830} INFO - Processing file /opt/airflow/dags/ingestion_dag.py for tasks to queue
[2024-07-03T20:59:10.529+0000] {logging_mixin.py:188} INFO - [2024-07-03T20:59:10.528+0000] {dagbag.py:545} INFO - Filling up the DagBag from /opt/airflow/dags/ingestion_dag.py
[2024-07-03T20:59:10.534+0000] {logging_mixin.py:188} INFO - [2024-07-03T20:59:10.532+0000] {dagbag.py:355} ERROR - Failed to import: /opt/airflow/dags/ingestion_dag.py
Traceback (most recent call last):
  File "/home/airflow/.local/lib/python3.11/site-packages/airflow/models/dagbag.py", line 351, in parse
    loader.exec_module(new_module)
  File "<frozen importlib._bootstrap_external>", line 940, in exec_module
  File "<frozen importlib._bootstrap>", line 241, in _call_with_frames_removed
  File "/opt/airflow/dags/ingestion_dag.py", line 20, in <module>
    SERVICE_ACCOUNT_CREDENTIALS = service_account.Credentials.from_service_account_file(
                                  ^^^^^^^^^^^^^^^^^^^^^^^^^^^^^^^^^^^^^^^^^^^^^^^^^^^^^^
  File "/home/airflow/.local/lib/python3.11/site-packages/google/oauth2/service_account.py", line 258, in from_service_account_file
    info, signer = _service_account_info.from_filename(
                   ^^^^^^^^^^^^^^^^^^^^^^^^^^^^^^^^^^^^
  File "/home/airflow/.local/lib/python3.11/site-packages/google/auth/_service_account_info.py", line 78, in from_filename
    with io.open(filename, "r", encoding="utf-8") as json_file:
         ^^^^^^^^^^^^^^^^^^^^^^^^^^^^^^^^^^^^^^^^
FileNotFoundError: [Errno 2] No such file or directory: '/.gc/my-creds.json'
[2024-07-03T20:59:10.535+0000] {processor.py:842} WARNING - No viable dags retrieved from /opt/airflow/dags/ingestion_dag.py
[2024-07-03T20:59:10.568+0000] {processor.py:183} INFO - Processing /opt/airflow/dags/ingestion_dag.py took 0.055 seconds
[2024-07-03T20:59:41.147+0000] {processor.py:161} INFO - Started process (PID=588) to work on /opt/airflow/dags/ingestion_dag.py
[2024-07-03T20:59:41.165+0000] {processor.py:830} INFO - Processing file /opt/airflow/dags/ingestion_dag.py for tasks to queue
[2024-07-03T20:59:41.177+0000] {logging_mixin.py:188} INFO - [2024-07-03T20:59:41.168+0000] {dagbag.py:545} INFO - Filling up the DagBag from /opt/airflow/dags/ingestion_dag.py
[2024-07-03T20:59:41.193+0000] {logging_mixin.py:188} INFO - [2024-07-03T20:59:41.190+0000] {dagbag.py:355} ERROR - Failed to import: /opt/airflow/dags/ingestion_dag.py
Traceback (most recent call last):
  File "/home/airflow/.local/lib/python3.11/site-packages/airflow/models/dagbag.py", line 351, in parse
    loader.exec_module(new_module)
  File "<frozen importlib._bootstrap_external>", line 940, in exec_module
  File "<frozen importlib._bootstrap>", line 241, in _call_with_frames_removed
  File "/opt/airflow/dags/ingestion_dag.py", line 20, in <module>
    SERVICE_ACCOUNT_CREDENTIALS = service_account.Credentials.from_service_account_file(
                                  ^^^^^^^^^^^^^^^^^^^^^^^^^^^^^^^^^^^^^^^^^^^^^^^^^^^^^^
  File "/home/airflow/.local/lib/python3.11/site-packages/google/oauth2/service_account.py", line 258, in from_service_account_file
    info, signer = _service_account_info.from_filename(
                   ^^^^^^^^^^^^^^^^^^^^^^^^^^^^^^^^^^^^
  File "/home/airflow/.local/lib/python3.11/site-packages/google/auth/_service_account_info.py", line 78, in from_filename
    with io.open(filename, "r", encoding="utf-8") as json_file:
         ^^^^^^^^^^^^^^^^^^^^^^^^^^^^^^^^^^^^^^^^
FileNotFoundError: [Errno 2] No such file or directory: '/.gc/my-creds.json'
[2024-07-03T20:59:41.194+0000] {processor.py:842} WARNING - No viable dags retrieved from /opt/airflow/dags/ingestion_dag.py
[2024-07-03T20:59:41.327+0000] {processor.py:183} INFO - Processing /opt/airflow/dags/ingestion_dag.py took 0.207 seconds
