[2024-07-18T20:52:50.776+0000] {local_task_job_runner.py:120} INFO - ::group::Pre task execution logs
[2024-07-18T20:52:50.809+0000] {taskinstance.py:2076} INFO - Dependencies all met for dep_context=non-requeueable deps ti=<TaskInstance: rec_data_dag.upload_zip_task_rec manual__2024-07-18T20:52:43.569922+00:00 [queued]>
[2024-07-18T20:52:50.820+0000] {taskinstance.py:2076} INFO - Dependencies all met for dep_context=requeueable deps ti=<TaskInstance: rec_data_dag.upload_zip_task_rec manual__2024-07-18T20:52:43.569922+00:00 [queued]>
[2024-07-18T20:52:50.821+0000] {taskinstance.py:2306} INFO - Starting attempt 1 of 2
[2024-07-18T20:52:50.839+0000] {taskinstance.py:2330} INFO - Executing <Task(PythonOperator): upload_zip_task_rec> on 2024-07-18 20:52:43.569922+00:00
[2024-07-18T20:52:50.849+0000] {standard_task_runner.py:63} INFO - Started process 321 to run task
[2024-07-18T20:52:50.854+0000] {standard_task_runner.py:90} INFO - Running: ['***', 'tasks', 'run', 'rec_data_dag', 'upload_zip_task_rec', 'manual__2024-07-18T20:52:43.569922+00:00', '--job-id', '730', '--raw', '--subdir', 'DAGS_FOLDER/rec_data_dag.py', '--cfg-path', '/tmp/tmp_t_g7fkm']
[2024-07-18T20:52:50.856+0000] {standard_task_runner.py:91} INFO - Job 730: Subtask upload_zip_task_rec
[2024-07-18T20:52:50.927+0000] {task_command.py:426} INFO - Running <TaskInstance: rec_data_dag.upload_zip_task_rec manual__2024-07-18T20:52:43.569922+00:00 [running]> on host e1216aff0b18
[2024-07-18T20:52:51.047+0000] {taskinstance.py:2648} INFO - Exporting env vars: AIRFLOW_CTX_DAG_OWNER='***' AIRFLOW_CTX_DAG_ID='rec_data_dag' AIRFLOW_CTX_TASK_ID='upload_zip_task_rec' AIRFLOW_CTX_EXECUTION_DATE='2024-07-18T20:52:43.569922+00:00' AIRFLOW_CTX_TRY_NUMBER='1' AIRFLOW_CTX_DAG_RUN_ID='manual__2024-07-18T20:52:43.569922+00:00'
[2024-07-18T20:52:51.048+0000] {taskinstance.py:430} INFO - ::endgroup::
[2024-07-18T20:52:51.177+0000] {logging_mixin.py:188} INFO - Uploading to storage bucket as <Blob: de-zoomcamp-cchow-bucket, recreation_lines.zip, None> from /opt/***/recreation_lines.zip...
[2024-07-18T20:52:51.185+0000] {logging_mixin.py:188} INFO - Error uploading file /opt/***/recreation_lines.zip to <Blob: de-zoomcamp-cchow-bucket, recreation_lines.zip, None>: [Errno 2] No such file or directory: '/opt/***/recreation_lines.zip'
[2024-07-18T20:52:51.185+0000] {taskinstance.py:441} INFO - ::group::Post task execution logs
[2024-07-18T20:52:51.199+0000] {taskinstance.py:2905} ERROR - Task failed with exception
Traceback (most recent call last):
  File "/opt/airflow/dags/rec_data_dag.py", line 51, in upload_to_gcs
    blob.upload_from_filename(source_path)
  File "/home/airflow/.local/lib/python3.11/site-packages/google/cloud/storage/blob.py", line 2947, in upload_from_filename
    self._handle_filename_and_upload(
  File "/home/airflow/.local/lib/python3.11/site-packages/google/cloud/storage/blob.py", line 2824, in _handle_filename_and_upload
    with open(filename, "rb") as file_obj:
         ^^^^^^^^^^^^^^^^^^^^
FileNotFoundError: [Errno 2] No such file or directory: '/opt/airflow/recreation_lines.zip'

During handling of the above exception, another exception occurred:

Traceback (most recent call last):
  File "/home/airflow/.local/lib/python3.11/site-packages/airflow/models/taskinstance.py", line 465, in _execute_task
    result = _execute_callable(context=context, **execute_callable_kwargs)
             ^^^^^^^^^^^^^^^^^^^^^^^^^^^^^^^^^^^^^^^^^^^^^^^^^^^^^^^^^^^^^
  File "/home/airflow/.local/lib/python3.11/site-packages/airflow/models/taskinstance.py", line 432, in _execute_callable
    return execute_callable(context=context, **execute_callable_kwargs)
           ^^^^^^^^^^^^^^^^^^^^^^^^^^^^^^^^^^^^^^^^^^^^^^^^^^^^^^^^^^^^
  File "/home/airflow/.local/lib/python3.11/site-packages/airflow/models/baseoperator.py", line 401, in wrapper
    return func(self, *args, **kwargs)
           ^^^^^^^^^^^^^^^^^^^^^^^^^^^
  File "/home/airflow/.local/lib/python3.11/site-packages/airflow/operators/python.py", line 235, in execute
    return_value = self.execute_callable()
                   ^^^^^^^^^^^^^^^^^^^^^^^
  File "/home/airflow/.local/lib/python3.11/site-packages/airflow/operators/python.py", line 252, in execute_callable
    return self.python_callable(*self.op_args, **self.op_kwargs)
           ^^^^^^^^^^^^^^^^^^^^^^^^^^^^^^^^^^^^^^^^^^^^^^^^^^^^^
  File "/opt/airflow/dags/rec_data_dag.py", line 55, in upload_to_gcs
    raise AirflowException("Task failed due to an exception")
airflow.exceptions.AirflowException: Task failed due to an exception
[2024-07-18T20:52:51.206+0000] {taskinstance.py:1206} INFO - Marking task as UP_FOR_RETRY. dag_id=rec_data_dag, task_id=upload_zip_task_rec, run_id=manual__2024-07-18T20:52:43.569922+00:00, execution_date=20240718T205243, start_date=20240718T205250, end_date=20240718T205251
[2024-07-18T20:52:51.226+0000] {standard_task_runner.py:110} ERROR - Failed to execute job 730 for task upload_zip_task_rec (Task failed due to an exception; 321)
[2024-07-18T20:52:51.267+0000] {local_task_job_runner.py:240} INFO - Task exited with return code 1
[2024-07-18T20:52:51.307+0000] {taskinstance.py:3503} INFO - 0 downstream tasks scheduled from follow-on schedule check
[2024-07-18T20:52:51.309+0000] {local_task_job_runner.py:222} INFO - ::endgroup::
